Workbook

Sheet OVERALL
A1: ATTENDANCE RECORD JULY-NOVEMEBER 2024 (B.Tech CSE 3B)
A2: Date | D2: DSA | G2: M-III | J2: OOPS | M2: DE | P2: DOS | S2: OOPS LAB | V2: DE LAB | Y2: DSA LAB | AB2: IT WORKSHOP | AE2: OVERALL
A3: S.No. | B3: Reg No. | C3: Name of Student | D3: ATT. | E3: TOTAL | F3: % | G3: ATT. | H3: TOTAL | I3: % | J3: ATT. | K3: TOTAL | L3: % | M3: ATT. | N3: TOTAL | O3: % | P3: ATT. | Q3: TOTAL | R3: % | S3: ATT. | T3: TOTAL | U3: % | V3: ATT. | W3: TOTAL | X3: % | Y3: ATT. | Z3: TOTAL | AA3: % | AB3: ATT. | AC3: TOTAL | AD3: % | AE3: ATT. | AF3: G.TOTAL | AG3: %
A4: 1 | B4: 2301236 | C4: Manmohan Singh | D4: =DSA!BF5 -> 19 | E4: =DSA!BG5 -> 41 | F4: =(D4/E4)*100 -> 46.341463 | G4: ='M-III'!BF5 -> 19 | H4: ='M-III'!BG5 -> 65 | I4: =(G4/H4)*100 -> 29.230769 | J4: =OOPS!BG5 -> 19 | K4: =OOPS!BH5 -> 48 | L4: =(J4/K4)*100 -> 39.583333 | M4: =DE!BF5 -> 10 | N4: =DE!BG5 -> 46 | O4: =(M4/N4)*100 -> 21.73913 | P4: =DOS!BF5 -> 14 | Q4: =DOS!BG5 -> 48 | R4: =(P4/Q4)*100 -> 29.166667 | S4: ='OOPS LAB'!AE5 -> 20 | T4: ='OOPS LAB'!AF5 -> 48 | U4: =(S4/T4)*100 -> 41.666667 | V4: ='DE LAB'!AE5 -> 10 | W4: ='DE LAB'!AF5 -> 30 | X4: =(V4/W4)*100 -> 33.333333 | Y4: ='DSA LAB'!AE5 -> 28 | Z4: ='DSA LAB'!AF5 -> 41 | AA4: =(Y4/Z4)*100 -> 68.292683 | AB4: ='IT WORKSHOP'!AM5 -> 13 | AC4: ='IT WORKSHOP'!AN5 -> 33 | AD4: =(AB4/AC4)*100 -> 39.393939 | AE4: =D4+G4+J4+M4+P4+S4+V4+Y4+AB4 -> 152 | AF4: =E4+H4+K4+N4+T4+W4+Z4+Q4+AC4 -> 400 | AG4: =AE4/AF4 -> 0.38
A5: 2 | B5: 2301237 | C5: Manpreet Kaur | D5: =DSA!BF6 -> 33 | E5: =DSA!BG6 -> 41 | F5: =(D5/E5)*100 -> 80.487805 | G5: ='M-III'!BF6 -> 45 | H5: ='M-III'!BG6 -> 65 | I5: =(G5/H5)*100 -> 69.230769 | J5: =OOPS!BG6 -> 36 | K5: =OOPS!BH6 -> 48 | L5: =(J5/K5)*100 -> 75 | M5: =DE!BF6 -> 37 | N5: =DE!BG6 -> 46 | O5: =(M5/N5)*100 -> 80.434783 | P5: =DOS!BF6 -> 39 | Q5: =DOS!BG6 -> 48 | R5: =(P5/Q5)*100 -> 81.25 | S5: ='OOPS LAB'!AE6 -> 40 | T5: ='OOPS LAB'!AF6 -> 48 | U5: =(S5/T5)*100 -> 83.333333 | V5: ='DE LAB'!AE6 -> 22 | W5: ='DE LAB'!AF6 -> 30 | X5: =(V5/W5)*100 -> 73.333333 | Y5: ='DSA LAB'!AE6 -> 29 | Z5: ='DSA LAB'!AF6 -> 41 | AA5: =(Y5/Z5)*100 -> 70.731707 | AB5: ='IT WORKSHOP'!AM6 -> 25 | AC5: ='IT WORKSHOP'!AN6 -> 33 | AD5: =(AB5/AC5)*100 -> 75.757576 | AE5: =D5+G5+J5+M5+P5+S5+V5+Y5+AB5 -> 306 | AF5: =E5+H5+K5+N5+T5+W5+Z5+Q5+AC5 -> 400 | AG5: =AE5/AF5 -> 0.765
A6: 3 | B6: 2301238 | C6: Md Warish Chesam | D6: =DSA!BF7 -> 33 | E6: =DSA!BG7 -> 41 | F6: =(D6/E6)*100 -> 80.487805 | G6: ='M-III'!BF7 -> 56 | H6: ='M-III'!BG7 -> 65 | I6: =(G6/H6)*100 -> 86.153846 | J6: =OOPS!BG7 -> 30 | K6: =OOPS!BH7 -> 48 | L6: =(J6/K6)*100 -> 62.5 | M6: =DE!BF7 -> 36 | N6: =DE!BG7 -> 46 | O6: =(M6/N6)*100 -> 78.26087 | P6: =DOS!BF7 -> 37 | Q6: =DOS!BG7 -> 48 | R6: =(P6/Q6)*100 -> 77.083333 | S6: ='OOPS LAB'!AE7 -> 31 | T6: ='OOPS LAB'!AF7 -> 48 | U6: =(S6/T6)*100 -> 64.583333 | V6: ='DE LAB'!AE7 -> 26 | W6: ='DE LAB'!AF7 -> 30 | X6: =(V6/W6)*100 -> 86.666667 | Y6: ='DSA LAB'!AE7 -> 34 | Z6: ='DSA LAB'!AF7 -> 41 | AA6: =(Y6/Z6)*100 -> 82.926829 | AB6: ='IT WORKSHOP'!AM7 -> 20 | AC6: ='IT WORKSHOP'!AN7 -> 33 | AD6: =(AB6/AC6)*100 -> 60.606061 | AE6: =D6+G6+J6+M6+P6+S6+V6+Y6+AB6 -> 303 | AF6: =E6+H6+K6+N6+T6+W6+Z6+Q6+AC6 -> 400 | AG6: =AE6/AF6 -> 0.7575
A7: 4 | B7: 2301239 | C7: Mohd Shahid Afridi | D7: =DSA!BF8 -> 0 | E7: =DSA!BG8 -> 41 | F7: =(D7/E7)*100 -> 0 | G7: ='M-III'!BF8 -> 0 | H7: ='M-III'!BG8 -> 65 | I7: =(G7/H7)*100 -> 0 | J7: =OOPS!BG8 -> 0 | K7: =OOPS!BH8 -> 48 | L7: =(J7/K7)*100 -> 0 | M7: =DE!BF8 -> 0 | N7: =DE!BG8 -> 46 | O7: =(M7/N7)*100 -> 0 | P7: =DOS!BF8 -> 0 | Q7: =DOS!BG8 -> 48 | R7: =(P7/Q7)*100 -> 0 | S7: ='OOPS LAB'!AE8 -> 0 | T7: ='OOPS LAB'!AF8 -> 48 | U7: =(S7/T7)*100 -> 0 | V7: ='DE LAB'!AE8 -> 4 | W7: ='DE LAB'!AF8 -> 30 | X7: =(V7/W7)*100 -> 13.333333 | Y7: ='DSA LAB'!AE8 -> 0 | Z7: ='DSA LAB'!AF8 -> 41 | AA7: =(Y7/Z7)*100 -> 0 | AB7: ='IT WORKSHOP'!AM8 -> 0 | AC7: ='IT WORKSHOP'!AN8 -> 33 | AD7: =(AB7/AC7)*100 -> 0 | AE7: =D7+G7+J7+M7+P7+S7+V7+Y7+AB7 -> 4 | AF7: =E7+H7+K7+N7+T7+W7+Z7+Q7+AC7 -> 400 | AG7: =AE7/AF7 -> 0.01
A8: 5 | B8: 2301240 | C8: Munisha | D8: =DSA!BF9 -> 39 | E8: =DSA!BG9 -> 41 | F8: =(D8/E8)*100 -> 95.121951 | G8: ='M-III'!BF9 -> 53 | H8: ='M-III'!BG9 -> 65 | I8: =(G8/H8)*100 -> 81.538462 | J8: =OOPS!BG9 -> 33 | K8: =OOPS!BH9 -> 48 | L8: =(J8/K8)*100 -> 68.75 | M8: =DE!BF9 -> 37 | N8: =DE!BG9 -> 46 | O8: =(M8/N8)*100 -> 80.434783 | P8: =DOS!BF9 -> 37 | Q8: =DOS!BG9 -> 48 | R8: =(P8/Q8)*100 -> 77.083333 | S8: ='OOPS LAB'!AE9 -> 42 | T8: ='OOPS LAB'!AF9 -> 48 | U8: =(S8/T8)*100 -> 87.5 | V8: ='DE LAB'!AE9 -> 20 | W8: ='DE LAB'!AF9 -> 30 | X8: =(V8/W8)*100 -> 66.666667 | Y8: ='DSA LAB'!AE9 -> 35 | Z8: ='DSA LAB'!AF9 -> 41 | AA8: =(Y8/Z8)*100 -> 85.365854 | AB8: ='IT WORKSHOP'!AM9 -> 31 | AC8: ='IT WORKSHOP'!AN9 -> 33 | AD8: =(AB8/AC8)*100 -> 93.939394 | AE8: =D8+G8+J8+M8+P8+S8+V8+Y8+AB8 -> 327 | AF8: =E8+H8+K8+N8+T8+W8+Z8+Q8+AC8 -> 400 | AG8: =AE8/AF8 -> 0.8175
A9: 6 | B9: 2301241 | C9: Nikhil Kumar Thakur | D9: =DSA!BF10 -> 38 | E9: =DSA!BG10 -> 41 | F9: =(D9/E9)*100 -> 92.682927 | G9: ='M-III'!BF10 -> 59 | H9: ='M-III'!BG10 -> 65 | I9: =(G9/H9)*100 -> 90.769231 | J9: =OOPS!BG10 -> 42 | K9: =OOPS!BH10 -> 48 | L9: =(J9/K9)*100 -> 87.5 | M9: =DE!BF10 -> 41 | N9: =DE!BG10 -> 46 | O9: =(M9/N9)*100 -> 89.130435 | P9: =DOS!BF10 -> 44 | Q9: =DOS!BG10 -> 48 | R9: =(P9/Q9)*100 -> 91.666667 | S9: ='OOPS LAB'!AE10 -> 43 | T9: ='OOPS LAB'!AF10 -> 48 | U9: =(S9/T9)*100 -> 89.583333 | V9: ='DE LAB'!AE10 -> 26 | W9: ='DE LAB'!AF10 -> 30 | X9: =(V9/W9)*100 -> 86.666667 | Y9: ='DSA LAB'!AE10 -> 40 | Z9: ='DSA LAB'!AF10 -> 41 | AA9: =(Y9/Z9)*100 -> 97.560976 | AB9: ='IT WORKSHOP'!AM10 -> 31 | AC9: ='IT WORKSHOP'!AN10 -> 33 | AD9: =(AB9/AC9)*100 -> 93.939394 | AE9: =D9+G9+J9+M9+P9+S9+V9+Y9+AB9 -> 364 | AF9: =E9+H9+K9+N9+T9+W9+Z9+Q9+AC9 -> 400 | AG9: =AE9/AF9 -> 0.91
A10: 7 | B10: 2301242 | C10: Palak Pathania | D10: =DSA!BF11 -> 35 | E10: =DSA!BG11 -> 41 | F10: =(D10/E10)*100 -> 85.365854 | G10: ='M-III'!BF11 -> 45 | H10: ='M-III'!BG11 -> 65 | I10: =(G10/H10)*100 -> 69.230769 | J10: =OOPS!BG11 -> 36 | K10: =OOPS!BH11 -> 48 | L10: =(J10/K10)*100 -> 75 | M10: =DE!BF11 -> 34 | N10: =DE!BG11 -> 46 | O10: =(M10/N10)*100 -> 73.913043 | P10: =DOS!BF11 -> 32 | Q10: =DOS!BG11 -> 48 | R10: =(P10/Q10)*100 -> 66.666667 | S10: ='OOPS LAB'!AE11 -> 44 | T10: ='OOPS LAB'!AF11 -> 48 | U10: =(S10/T10)*100 -> 91.666667 | V10: ='DE LAB'!AE11 -> 24 | W10: ='DE LAB'!AF11 -> 30 | X10: =(V10/W10)*100 -> 80 | Y10: ='DSA LAB'!AE11 -> 40 | Z10: ='DSA LAB'!AF11 -> 41 | AA10: =(Y10/Z10)*100 -> 97.560976 | AB10: ='IT WORKSHOP'!AM11 -> 19 | AC10: ='IT WORKSHOP'!AN11 -> 33 | AD10: =(AB10/AC10)*100 -> 57.575758 | AE10: =D10+G10+J10+M10+P10+S10+V10+Y10+AB10 -> 309 | AF10: =E10+H10+K10+N10+T10+W10+Z10+Q10+AC10 -> 400 | AG10: =AE10/AF10 -> 0.7725
A11: 8 | B11: 2301243 | C11: Pardeep Singh | D11: =DSA!BF12 -> 29 | E11: =DSA!BG12 -> 41 | F11: =(D11/E11)*100 -> 70.731707 | G11: ='M-III'!BF12 -> 46 | H11: ='M-III'!BG12 -> 65 | I11: =(G11/H11)*100 -> 70.769231 | J11: =OOPS!BG12 -> 30 | K11: =OOPS!BH12 -> 48 | L11: =(J11/K11)*100 -> 62.5 | M11: =DE!BF12 -> 38 | N11: =DE!BG12 -> 46 | O11: =(M11/N11)*100 -> 82.608696 | P11: =DOS!BF12 -> 27 | Q11: =DOS!BG12 -> 48 | R11: =(P11/Q11)*100 -> 56.25 | S11: ='OOPS LAB'!AE12 -> 38 | T11: ='OOPS LAB'!AF12 -> 48 | U11: =(S11/T11)*100 -> 79.166667 | V11: ='DE LAB'!AE12 -> 22 | W11: ='DE LAB'!AF12 -> 30 | X11: =(V11/W11)*100 -> 73.333333 | Y11: ='DSA LAB'!AE12 -> 31 | Z11: ='DSA LAB'!AF12 -> 41 | AA11: =(Y11/Z11)*100 -> 75.609756 | AB11: ='IT WORKSHOP'!AM12 -> 21 | AC11: ='IT WORKSHOP'!AN12 -> 33 | AD11: =(AB11/AC11)*100 -> 63.636364 | AE11: =D11+G11+J11+M11+P11+S11+V11+Y11+AB11 -> 282 | AF11: =E11+H11+K11+N11+T11+W11+Z11+Q11+AC11 -> 400 | AG11: =AE11/AF11 -> 0.705
A12: 9 | B12: 2301244 | C12: Parveen Mandal | D12: =DSA!BF13 -> 0 | E12: =DSA!BG13 -> 41 | F12: =(D12/E12)*100 -> 0 | G12: ='M-III'!BF13 -> 0 | H12: ='M-III'!BG13 -> 65 | I12: =(G12/H12)*100 -> 0 | J12: =OOPS!BG13 -> 0 | K12: =OOPS!BH13 -> 48 | L12: =(J12/K12)*100 -> 0 | M12: =DE!BF13 -> 0 | N12: =DE!BG13 -> 46 | O12: =(M12/N12)*100 -> 0 | P12: =DOS!BF13 -> 0 | Q12: =DOS!BG13 -> 48 | R12: =(P12/Q12)*100 -> 0 | S12: ='OOPS LAB'!AE13 -> 0 | T12: ='OOPS LAB'!AF13 -> 48 | U12: =(S12/T12)*100 -> 0 | V12: ='DE LAB'!AE13 -> 0 | W12: ='DE LAB'!AF13 -> 30 | X12: =(V12/W12)*100 -> 0 | Y12: ='DSA LAB'!AE13 -> 0 | Z12: ='DSA LAB'!AF13 -> 41 | AA12: =(Y12/Z12)*100 -> 0 | AB12: ='IT WORKSHOP'!AM13 -> 0 | AC12: ='IT WORKSHOP'!AN13 -> 33 | AD12: =(AB12/AC12)*100 -> 0 | AE12: =D12+G12+J12+M12+P12+S12+V12+Y12+AB12 -> 0 | AF12: =E12+H12+K12+N12+T12+W12+Z12+Q12+AC12 -> 400 | AG12: =AE12/AF12 -> 0
A13: 10 | B13: 2301245 | C13: Payal | D13: =DSA!BF14 -> 41 | E13: =DSA!BG14 -> 41 | F13: =(D13/E13)*100 -> 100 | G13: ='M-III'!BF14 -> 62 | H13: ='M-III'!BG14 -> 65 | I13: =(G13/H13)*100 -> 95.384615 | J13: =OOPS!BG14 -> 43 | K13: =OOPS!BH14 -> 48 | L13: =(J13/K13)*100 -> 89.583333 | M13: =DE!BF14 -> 41 | N13: =DE!BG14 -> 46 | O13: =(M13/N13)*100 -> 89.130435 | P13: =DOS!BF14 -> 46 | Q13: =DOS!BG14 -> 48 | R13: =(P13/Q13)*100 -> 95.833333 | S13: ='OOPS LAB'!AE14 -> 42 | T13: ='OOPS LAB'!AF14 -> 48 | U13: =(S13/T13)*100 -> 87.5 | V13: ='DE LAB'!AE14 -> 28 | W13: ='DE LAB'!AF14 -> 30 | X13: =(V13/W13)*100 -> 93.333333 | Y13: ='DSA LAB'!AE14 -> 41 | Z13: ='DSA LAB'!AF14 -> 41 | AA13: =(Y13/Z13)*100 -> 100 | AB13: ='IT WORKSHOP'!AM14 -> 32 | AC13: ='IT WORKSHOP'!AN14 -> 33 | AD13: =(AB13/AC13)*100 -> 96.969697 | AE13: =D13+G13+J13+M13+P13+S13+V13+Y13+AB13 -> 376 | AF13: =E13+H13+K13+N13+T13+W13+Z13+Q13+AC13 -> 400 | AG13: =AE13/AF13 -> 0.94
A14: 11 | B14: 2301247 | C14: Priya | D14: =DSA!BF15 -> 33 | E14: =DSA!BG15 -> 41 | F14: =(D14/E14)*100 -> 80.487805 | G14: ='M-III'!BF15 -> 36 | H14: ='M-III'!BG15 -> 65 | I14: =(G14/H14)*100 -> 55.384615 | J14: =OOPS!BG15 -> 34 | K14: =OOPS!BH15 -> 48 | L14: =(J14/K14)*100 -> 70.833333 | M14: =DE!BF15 -> 36 | N14: =DE!BG15 -> 46 | O14: =(M14/N14)*100 -> 78.26087 | P14: =DOS!BF15 -> 25 | Q14: =DOS!BG15 -> 48 | R14: =(P14/Q14)*100 -> 52.083333 | S14: ='OOPS LAB'!AE15 -> 26 | T14: ='OOPS LAB'!AF15 -> 48 | U14: =(S14/T14)*100 -> 54.166667 | V14: ='DE LAB'!AE15 -> 18 | W14: ='DE LAB'!AF15 -> 30 | X14: =(V14/W14)*100 -> 60 | Y14: ='DSA LAB'!AE15 -> 31 | Z14: ='DSA LAB'!AF15 -> 41 | AA14: =(Y14/Z14)*100 -> 75.609756 | AB14: ='IT WORKSHOP'!AM15 -> 26 | AC14: ='IT WORKSHOP'!AN15 -> 33 | AD14: =(AB14/AC14)*100 -> 78.787879 | AE14: =D14+G14+J14+M14+P14+S14+V14+Y14+AB14 -> 265 | AF14: =E14+H14+K14+N14+T14+W14+Z14+Q14+AC14 -> 400 | AG14: =AE14/AF14 -> 0.6625
A15: 12 | B15: 2301248 | C15: Priyam Puri | D15: =DSA!BF16 -> 0 | E15: =DSA!BG16 -> 41 | F15: =(D15/E15)*100 -> 0 | G15: ='M-III'!BF16 -> 0 | H15: ='M-III'!BG16 -> 65 | I15: =(G15/H15)*100 -> 0 | J15: =OOPS!BG16 -> 0 | K15: =OOPS!BH16 -> 48 | L15: =(J15/K15)*100 -> 0 | M15: =DE!BF16 -> 0 | N15: =DE!BG16 -> 46 | O15: =(M15/N15)*100 -> 0 | P15: =DOS!BF16 -> 0 | Q15: =DOS!BG16 -> 48 | R15: =(P15/Q15)*100 -> 0 | S15: ='OOPS LAB'!AE16 -> 0 | T15: ='OOPS LAB'!AF16 -> 48 | U15: =(S15/T15)*100 -> 0 | V15: ='DE LAB'!AE16 -> 0 | W15: ='DE LAB'!AF16 -> 30 | X15: =(V15/W15)*100 -> 0 | Y15: ='DSA LAB'!AE16 -> 0 | Z15: ='DSA LAB'!AF16 -> 41 | AA15: =(Y15/Z15)*100 -> 0 | AB15: ='IT WORKSHOP'!AM16 -> 0 | AC15: ='IT WORKSHOP'!AN16 -> 33 | AD15: =(AB15/AC15)*100 -> 0 | AE15: =D15+G15+J15+M15+P15+S15+V15+Y15+AB15 -> 0 | AF15: =E15+H15+K15+N15+T15+W15+Z15+Q15+AC15 -> 400 | AG15: =AE15/AF15 -> 0
... A25: 22 | B25: 2301258 | C25: Ritesh Thakur | D25: =DSA!BF26 -> 21 | E25: =DSA!BG26 -> 41 | F25: =(D25/E25)*100 -> 51.219512 | G25: ='M-III'!BF26 -> 21 | H25: ='M-III'!BG26 -> 65 | I25: =(G25/H25)*100 -> 32.307692 | J25: =OOPS!BG26 -> 13 | K25: =OOPS!BH26 -> 48 | L25: =(J25/K25)*100 -> 27.083333 | M25: =DE!BF26 -> 16 | N25: =DE!BG26 -> 46 | O25: =(M25/N25)*100 -> 34.782609 | P25: =DOS!BF26 -> 9 | Q25: =DOS!BG26 -> 48 | R25: =(P25/Q25)*100 -> 18.75 | S25: ='OOPS LAB'!AE26 -> 12 | T25: ='OOPS LAB'!AF26 -> 48 | U25: =(S25/T25)*100 -> 25 | V25: ='DE LAB'!AE26 -> 10 | W25: ='DE LAB'!AF26 -> 30 | X25: =(V25/W25)*100 -> 33.333333 | Y25: ='DSA LAB'!AE26 -> 18 | Z25: ='DSA LAB'!AF26 -> 41 | AA25: =(Y25/Z25)*100 -> 43.902439 | AB25: ='IT WORKSHOP'!AM26 -> 10 | AC25: ='IT WORKSHOP'!AN26 -> 33 | AD25: =(AB25/AC25)*100 -> 30.30303 | AE25: =D25+G25+J25+M25+P25+S25+V25+Y25+AB25 -> 130 | AF25: =E25+H25+K25+N25+T25+W25+Z25+Q25+AC25 -> 400 | AG25: =AE25/AF25 -> 0.325
A26: 23 | B26: 2301259 | C26: Riya Thakur | D26: =DSA!BF27 -> 27 | E26: =DSA!BG27 -> 41 | F26: =(D26/E26)*100 -> 65.853659 | G26: ='M-III'!BF27 -> 43 | H26: ='M-III'!BG26 -> 65 | I26: =(G26/H26)*100 -> 66.153846 | J26: =OOPS!BG27 -> 31 | K26: =OOPS!BH27 -> 48 | L26: =(J26/K26)*100 -> 64.583333 | M26: =DE!BF27 -> 34 | N26: =DE!BG27 -> 46 | O26: =(M26/N26)*100 -> 73.913043 | P26: =DOS!BF27 -> 29 | Q26: =DOS!BG27 -> 48 | R26: =(P26/Q26)*100 -> 60.416667 | S26: ='OOPS LAB'!AE27 -> 31 | T26: ='OOPS LAB'!AF27 -> 48 | U26: =(S26/T26)*100 -> 64.583333 | V26: ='DE LAB'!AE27 -> 20 | W26: ='DE LAB'!AF27 -> 30 | X26: =(V26/W26)*100 -> 66.666667 | Y26: ='DSA LAB'!AE27 -> 25 | Z26: ='DSA LAB'!AF27 -> 41 | AA26: =(Y26/Z26)*100 -> 60.97561 | AB26: ='IT WORKSHOP'!AM27 -> 23 | AC26: ='IT WORKSHOP'!AN27 -> 33 | AD26: =(AB26/AC26)*100 -> 69.69697 | AE26: =D26+G26+J26+M26+P26+S26+V26+Y26+AB26 -> 263 | AF26: =E26+H26+K26+N26+T26+W26+Z26+Q26+AC26 -> 400 | AG26: =AE26/AF26 -> 0.6575
A27: 24 | B27: 2301260 | C27: Rounit Dhiman | D27: =DSA!BF28 -> 35 | E27: =DSA!BG28 -> 41 | F27: =(D27/E27)*100 -> 85.365854 | G27: ='M-III'!BF28 -> 52 | H27: ='M-III'!BG27 -> 65 | I27: =(G27/H27)*100 -> 80 | J27: =OOPS!BG28 -> 33 | K27: =OOPS!BH28 -> 48 | L27: =(J27/K27)*100 -> 68.75 | M27: =DE!BF28 -> 29 | N27: =DE!BG28 -> 46 | O27: =(M27/N27)*100 -> 63.043478 | P27: =DOS!BF28 -> 32 | Q27: =DOS!BG28 -> 48 | R27: =(P27/Q27)*100 -> 66.666667 | S27: ='OOPS LAB'!AE28 -> 29 | T27: ='OOPS LAB'!AF28 -> 48 | U27: =(S27/T27)*100 -> 60.416667 | V27: ='DE LAB'!AE28 -> 22 | W27: ='DE LAB'!AF28 -> 30 | X27: =(V27/W27)*100 -> 73.333333 | Y27: ='DSA LAB'!AE28 -> 31 | Z27: ='DSA LAB'!AF28 -> 41 | AA27: =(Y27/Z27)*100 -> 75.609756 | AB27: ='IT WORKSHOP'!AM28 -> 26 | AC27: ='IT WORKSHOP'!AN28 -> 33 | AD27: =(AB27/AC27)*100 -> 78.787879 | AE27: =D27+G27+J27+M27+P27+S27+V27+Y27+AB27 -> 289 | AF27: =E27+H27+K27+N27+T27+W27+Z27+Q27+AC27 -> 400 | AG27: =AE27/AF27 -> 0.7225
A28: 25 | B28: 2301261 | C28: Rubby Kumari | D28: =DSA!BF29 -> 27 | E28: =DSA!BG29 -> 41 | F28: =(D28/E28)*100 -> 65.853659 | G28: ='M-III'!BF29 -> 33 | H28: ='M-III'!BG28 -> 65 | I28: =(G28/H28)*100 -> 50.769231 | J28: =OOPS!BG29 -> 8 | K28: =OOPS!BH29 -> 48 | L28: =(J28/K28)*100 -> 16.666667 | M28: =DE!BF29 -> 16 | N28: =DE!BG29 -> 46 | O28: =(M28/N28)*100 -> 34.782609 | P28: =DOS!BF29 -> 20 | Q28: =DOS!BG29 -> 48 | R28: =(P28/Q28)*100 -> 41.666667 | S28: ='OOPS LAB'!AE29 -> 24 | T28: ='OOPS LAB'!AF29 -> 48 | U28: =(S28/T28)*100 -> 50 | V28: ='DE LAB'!AE29 -> 14 | W28: ='DE LAB'!AF29 -> 30 | X28: =(V28/W28)*100 -> 46.666667 | Y28: ='DSA LAB'!AE29 -> 38 | Z28: ='DSA LAB'!AF29 -> 41 | AA28: =(Y28/Z28)*100 -> 92.682927 | AB28: ='IT WORKSHOP'!AM29 -> 20 | AC28: ='IT WORKSHOP'!AN29 -> 33 | AD28: =(AB28/AC28)*100 -> 60.606061 | AE28: =D28+G28+J28+M28+P28+S28+V28+Y28+AB28 -> 200 | AF28: =E28+H28+K28+N28+T28+W28+Z28+Q28+AC28 -> 400 | AG28: =AE28/AF28 -> 0.5
A29: 26 | B29: 2301262 | C29: Sakshi Devi | D29: =DSA!BF30 -> 33 | E29: =DSA!BG30 -> 41 | F29: =(D29/E29)*100 -> 80.487805 | G29: ='M-III'!BF30 -> 46 | H29: ='M-III'!BG29 -> 65 | I29: =(G29/H29)*100 -> 70.769231 | J29: =OOPS!BG30 -> 30 | K29: =OOPS!BH30 -> 48 | L29: =(J29/K29)*100 -> 62.5 | M29: =DE!BF30 -> 35 | N29: =DE!BG30 -> 46 | O29: =(M29/N29)*100 -> 76.086957 | P29: =DOS!BF30 -> 30 | Q29: =DOS!BG30 -> 48 | R29: =(P29/Q29)*100 -> 62.5 | S29: ='OOPS LAB'!AE30 -> 28 | T29: ='OOPS LAB'!AF30 -> 48 | U29: =(S29/T29)*100 -> 58.333333 | V29: ='DE LAB'!AE30 -> 22 | W29: ='DE LAB'!AF30 -> 30 | X29: =(V29/W29)*100 -> 73.333333 | Y29: ='DSA LAB'!AE30 -> 31 | Z29: ='DSA LAB'!AF30 -> 41 | AA29: =(Y29/Z29)*100 -> 75.609756 | AB29: ='IT WORKSHOP'!AM30 -> 25 | AC29: ='IT WORKSHOP'!AN30 -> 33 | AD29: =(AB29/AC29)*100 -> 75.757576 | AE29: =D29+G29+J29+M29+P29+S29+V29+Y29+AB29 -> 280 | AF29: =E29+H29+K29+N29+T29+W29+Z29+Q29+AC29 -> 400 | AG29: =AE29/AF29 -> 0.7
A30: 27 | B30: 2301263 | C30: Sanchi Sharma | D30: =DSA!BF31 -> 38 | E30: =DSA!BG31 -> 41 | F30: =(D30/E30)*100 -> 92.682927 | G30: ='M-III'!BF31 -> 57 | H30: ='M-III'!BG30 -> 65 | I30: =(G30/H30)*100 -> 87.692308 | J30: =OOPS!BG31 -> 43 | K30: =OOPS!BH31 -> 48 | L30: =(J30/K30)*100 -> 89.583333 | M30: =DE!BF31 -> 40 | N30: =DE!BG31 -> 46 | O30: =(M30/N30)*100 -> 86.956522 | P30: =DOS!BF31 -> 47 | Q30: =DOS!BG31 -> 48 | R30: =(P30/Q30)*100 -> 97.916667 | S30: ='OOPS LAB'!AE31 -> 48 | T30: ='OOPS LAB'!AF31 -> 48 | U30: =(S30/T30)*100 -> 100 | V30: ='DE LAB'!AE31 -> 28 | W30: ='DE LAB'!AF31 -> 30 | X30: =(V30/W30)*100 -> 93.333333 | Y30: ='DSA LAB'!AE31 -> 37 | Z30: ='DSA LAB'!AF31 -> 41 | AA30: =(Y30/Z30)*100 -> 90.243902 | AB30: ='IT WORKSHOP'!AM31 -> 31 | AC30: ='IT WORKSHOP'!AN31 -> 33 | AD30: =(AB30/AC30)*100 -> 93.939394 | AE30: =D30+G30+J30+M30+P30+S30+V30+Y30+AB30 -> 369 | AF30: =E30+H30+K30+N30+T30+W30+Z30+Q30+AC30 -> 400 | AG30: =AE30/AF30 -> 0.9225
A31: 28 | B31: 2301264 | C31: Sarbjit Singh | D31: =DSA!BF32 -> 20 | E31: =DSA!BG32 -> 41 | F31: =(D31/E31)*100 -> 48.780488 | G31: ='M-III'!BF32 -> 13 | H31: ='M-III'!BG31 -> 65 | I31: =(G31/H31)*100 -> 20 | J31: =OOPS!BG32 -> 14 | K31: =OOPS!BH32 -> 48 | L31: =(J31/K31)*100 -> 29.166667 | M31: =DE!BF32 -> 22 | N31: =DE!BG32 -> 46 | O31: =(M31/N31)*100 -> 47.826087 | P31: =DOS!BF32 -> 8 | Q31: =DOS!BG32 -> 48 | R31: =(P31/Q31)*100 -> 16.666667 | S31: ='OOPS LAB'!AE32 -> 13 | T31: ='OOPS LAB'!AF32 -> 48 | U31: =(S31/T31)*100 -> 27.083333 | V31: ='DE LAB'!AE32 -> 10 | W31: ='DE LAB'!AF32 -> 30 | X31: =(V31/W31)*100 -> 33.333333 | Y31: ='DSA LAB'!AE32 -> 26 | Z31: ='DSA LAB'!AF32 -> 41 | AA31: =(Y31/Z31)*100 -> 63.414634 | AB31: ='IT WORKSHOP'!AM32 -> 10 | AC31: ='IT WORKSHOP'!AN32 -> 33 | AD31: =(AB31/AC31)*100 -> 30.30303 | AE31: =D31+G31+J31+M31+P31+S31+V31+Y31+AB31 -> 136 | AF31: =E31+H31+K31+N31+T31+W31+Z31+Q31+AC31 -> 400 | AG31: =AE31/AF31 -> 0.34
A32: 29 | B32: 2301265 | C32: Sarif Mayangmayum | D32: =DSA!BF33 -> 38 | E32: =DSA!BG33 -> 41 | F32: =(D32/E32)*100 -> 92.682927 | G32: ='M-III'!BF33 -> 52 | H32: ='M-III'!BG32 -> 65 | I32: =(G32/H32)*100 -> 80 | J32: =OOPS!BG33 -> 40 | K32: =OOPS!BH33 -> 48 | L32: =(J32/K32)*100 -> 83.333333 | M32: =DE!BF33 -> 35 | N32: =DE!BG33 -> 46 | O32: =(M32/N32)*100 -> 76.086957 | P32: =DOS!BF33 -> 37 | Q32: =DOS!BG33 -> 48 | R32: =(P32/Q32)*100 -> 77.083333 | S32: ='OOPS LAB'!AE33 -> 33 | T32: ='OOPS LAB'!AF33 -> 48 | U32: =(S32/T32)*100 -> 68.75 | V32: ='DE LAB'!AE33 -> 26 | W32: ='DE LAB'!AF33 -> 30 | X32: =(V32/W32)*100 -> 86.666667 | Y32: ='DSA LAB'!AE33 -> 40 | Z32: ='DSA LAB'!AF33 -> 41 | AA32: =(Y32/Z32)*100 -> 97.560976 | AB32: ='IT WORKSHOP'!AM33 -> 15 | AC32: ='IT WORKSHOP'!AN33 -> 33 | AD32: =(AB32/AC32)*100 -> 45.454545 | AE32: =D32+G32+J32+M32+P32+S32+V32+Y32+AB32 -> 316 | AF32: =E32+H32+K32+N32+T32+W32+Z32+Q32+AC32 -> 400 | AG32: =AE32/AF32 -> 0.79
A33: 30 | B33: 2301267 | C33: Shivam Kumar Chaubey | D33: =DSA!BF34 -> 35 | E33: =DSA!BG34 -> 41 | F33: =(D33/E33)*100 -> 85.365854 | G33: ='M-III'!BF34 -> 54 | H33: ='M-III'!BG33 -> 65 | I33: =(G33/H33)*100 -> 83.076923 | J33: =OOPS!BG34 -> 40 | K33: =OOPS!BH34 -> 48 | L33: =(J33/K33)*100 -> 83.333333 | M33: =DE!BF34 -> 38 | N33: =DE!BG34 -> 46 | O33: =(M33/N33)*100 -> 82.608696 | P33: =DOS!BF34 -> 37 | Q33: =DOS!BG34 -> 48 | R33: =(P33/Q33)*100 -> 77.083333 | S33: ='OOPS LAB'!AE34 -> 39 | T33: ='OOPS LAB'!AF34 -> 48 | U33: =(S33/T33)*100 -> 81.25 | V33: ='DE LAB'!AE34 -> 24 | W33: ='DE LAB'!AF34 -> 30 | X33: =(V33/W33)*100 -> 80 | Y33: ='DSA LAB'!AE34 -> 40 | Z33: ='DSA LAB'!AF34 -> 41 | AA33: =(Y33/Z33)*100 -> 97.560976 | AB33: ='IT WORKSHOP'!AM34 -> 26 | AC33: ='IT WORKSHOP'!AN34 -> 33 | AD33: =(AB33/AC33)*100 -> 78.787879 | AE33: =D33+G33+J33+M33+P33+S33+V33+Y33+AB33 -> 333 | AF33: =E33+H33+K33+N33+T33+W33+Z33+Q33+AC33 -> 400 | AG33: =AE33/AF33 -> 0.8325
A34: 31 | B34: 2301268 | C34: Simba Godfrey | D34: =DSA!BF35 -> 26 | E34: =DSA!BG35 -> 41 | F34: =(D34/E34)*100 -> 63.414634 | G34: ='M-III'!BF35 -> 35 | H34: ='M-III'!BG34 -> 65 | I34: =(G34/H34)*100 -> 53.846154 | J34: =OOPS!BG35 -> 24 | K34: =OOPS!BH35 -> 48 | L34: =(J34/K34)*100 -> 50 | M34: =DE!BF35 -> 33 | N34: =DE!BG35 -> 46 | O34: =(M34/N34)*100 -> 71.73913 | P34: =DOS!BF35 -> 29 | Q34: =DOS!BG35 -> 48 | R34: =(P34/Q34)*100 -> 60.416667 | S34: ='OOPS LAB'!AE35 -> 29 | T34: ='OOPS LAB'!AF35 -> 48 | U34: =(S34/T34)*100 -> 60.416667 | V34: ='DE LAB'!AE35 -> 16 | W34: ='DE LAB'!AF35 -> 30 | X34: =(V34/W34)*100 -> 53.333333 | Y34: ='DSA LAB'!AE35 -> 20 | Z34: ='DSA LAB'!AF35 -> 41 | AA34: =(Y34/Z34)*100 -> 48.780488 | AB34: ='IT WORKSHOP'!AM35 -> 20 | AC34: ='IT WORKSHOP'!AN35 -> 33 | AD34: =(AB34/AC34)*100 -> 60.606061 | AE34: =D34+G34+J34+M34+P34+S34+V34+Y34+AB34 -> 232 | AF34: =E34+H34+K34+N34+T34+W34+Z34+Q34+AC34 -> 400 | AG34: =AE34/AF34 -> 0.58
A35: 32 | B35: 2301269 | C35: Simran Kaur | D35: =DSA!BF36 -> 29 | E35: =DSA!BG36 -> 41 | F35: =(D35/E35)*100 -> 70.731707 | G35: ='M-III'!BF36 -> 47 | H35: ='M-III'!BG35 -> 65 | I35: =(G35/H35)*100 -> 72.307692 | J35: =OOPS!BG36 -> 35 | K35: =OOPS!BH36 -> 48 | L35: =(J35/K35)*100 -> 72.916667 | M35: =DE!BF36 -> 35 | N35: =DE!BG36 -> 46 | O35: =(M35/N35)*100 -> 76.086957 | P35: =DOS!BF36 -> 41 | Q35: =DOS!BG36 -> 48 | R35: =(P35/Q35)*100 -> 85.416667 | S35: ='OOPS LAB'!AE36 -> 32 | T35: ='OOPS LAB'!AF36 -> 48 | U35: =(S35/T35)*100 -> 66.666667 | V35: ='DE LAB'!AE36 -> 24 | W35: ='DE LAB'!AF36 -> 30 | X35: =(V35/W35)*100 -> 80 | Y35: ='DSA LAB'!AE36 -> 27 | Z35: ='DSA LAB'!AF36 -> 41 | AA35: =(Y35/Z35)*100 -> 65.853659 | AB35: ='IT WORKSHOP'!AM36 -> 28 | AC35: ='IT WORKSHOP'!AN36 -> 33 | AD35: =(AB35/AC35)*100 -> 84.848485 | AE35: =D35+G35+J35+M35+P35+S35+V35+Y35+AB35 -> 298 | AF35: =E35+H35+K35+N35+T35+W35+Z35+Q35+AC35 -> 400 | AG35: =AE35/AF35 -> 0.745
A36: 33 | B36: 2301270 | C36: Simranjit Singh | D36: =DSA!BF37 -> 34 | E36: =DSA!BG37 -> 41 | F36: =(D36/E36)*100 -> 82.926829 | G36: ='M-III'!BF37 -> 44 | H36: ='M-III'!BG36 -> 65 | I36: =(G36/H36)*100 -> 67.692308 | J36: =OOPS!BG37 -> 32 | K36: =OOPS!BH37 -> 48 | L36: =(J36/K36)*100 -> 66.666667 | M36: =DE!BF37 -> 28 | N36: =DE!BG37 -> 46 | O36: =(M36/N36)*100 -> 60.869565 | P36: =DOS!BF37 -> 25 | Q36: =DOS!BG37 -> 48 | R36: =(P36/Q36)*100 -> 52.083333 | S36: ='OOPS LAB'!AE37 -> 35 | T36: ='OOPS LAB'!AF37 -> 48 | U36: =(S36/T36)*100 -> 72.916667 | V36: ='DE LAB'!AE37 -> 24 | W36: ='DE LAB'!AF37 -> 30 | X36: =(V36/W36)*100 -> 80 | Y36: ='DSA LAB'!AE37 -> 35 | Z36: ='DSA LAB'!AF37 -> 41 | AA36: =(Y36/Z36)*100 -> 85.365854 | AB36: ='IT WORKSHOP'!AM37 -> 23 | AC36: ='IT WORKSHOP'!AN37 -> 33 | AD36: =(AB36/AC36)*100 -> 69.69697 | AE36: =D36+G36+J36+M36+P36+S36+V36+Y36+AB36 -> 280 | AF36: =E36+H36+K36+N36+T36+W36+Z36+Q36+AC36 -> 400 | AG36: =AE36/AF36 -> 0.7
A37: 34 | B37: 2301271 | C37: Sudip Sunar | D37: =DSA!BF38 -> 29 | E37: =DSA!BG38 -> 41 | F37: =(D37/E37)*100 -> 70.731707 | G37: ='M-III'!BF38 -> 53 | H37: ='M-III'!BG37 -> 65 | I37: =(G37/H37)*100 -> 81.538462 | J37: =OOPS!BG38 -> 33 | K37: =OOPS!BH38 -> 48 | L37: =(J37/K37)*100 -> 68.75 | M37: =DE!BF38 -> 31 | N37: =DE!BG38 -> 46 | O37: =(M37/N37)*100 -> 67.391304 | P37: =DOS!BF38 -> 35 | Q37: =DOS!BG38 -> 48 | R37: =(P37/Q37)*100 -> 72.916667 | S37: ='OOPS LAB'!AE38 -> 25 | T37: ='OOPS LAB'!AF38 -> 48 | U37: =(S37/T37)*100 -> 52.083333 | V37: ='DE LAB'!AE38 -> 22 | W37: ='DE LAB'!AF38 -> 30 | X37: =(V37/W37)*100 -> 73.333333 | Y37: ='DSA LAB'!AE38 -> 28 | Z37: ='DSA LAB'!AF38 -> 41 | AA37: =(Y37/Z37)*100 -> 68.292683 | AB37: ='IT WORKSHOP'!AM38 -> 23 | AC37: ='IT WORKSHOP'!AN38 -> 33 | AD37: =(AB37/AC37)*100 -> 69.69697 | AE37: =D37+G37+J37+M37+P37+S37+V37+Y37+AB37 -> 279 | AF37: =E37+H37+K37+N37+T37+W37+Z37+Q37+AC37 -> 400 | AG37: =AE37/AF37 -> 0.6975
... A46: 43 | B46: 2301280 | C46: Taniya | D46: =DSA!BF47 -> 33 | E46: =DSA!BG47 -> 41 | F46: =(D46/E46)*100 -> 80.487805 | G46: ='M-III'!BF47 -> 30 | H46: ='M-III'!BG46 -> 65 | I46: =(G46/H46)*100 -> 46.153846 | J46: =OOPS!BG47 -> 16 | K46: =OOPS!BH47 -> 48 | L46: =(J46/K46)*100 -> 33.333333 | M46: =DE!BF47 -> 21 | N46: =DE!BG47 -> 46 | O46: =(M46/N46)*100 -> 45.652174 | P46: =DOS!BF47 -> 23 | Q46: =DOS!BG47 -> 48 | R46: =(P46/Q46)*100 -> 47.916667 | S46: ='OOPS LAB'!AE47 -> 14 | T46: ='OOPS LAB'!AF47 -> 48 | U46: =(S46/T46)*100 -> 29.166667 | V46: ='DE LAB'!AE47 -> 20 | W46: ='DE LAB'!AF47 -> 30 | X46: =(V46/W46)*100 -> 66.666667 | Y46: ='DSA LAB'!AE47 -> 11 | Z46: ='DSA LAB'!AF47 -> 41 | AA46: =(Y46/Z46)*100 -> 26.829268 | AB46: ='IT WORKSHOP'!AM47 -> 13 | AC46: ='IT WORKSHOP'!AN47 -> 33 | AD46: =(AB46/AC46)*100 -> 39.393939 | AE46: =D46+G46+J46+M46+P46+S46+V46+Y46+AB46 -> 181 | AF46: =E46+H46+K46+N46+T46+W46+Z46+Q46+AC46 -> 400 | AG46: =AE46/AF46 -> 0.4525
A47: 44 | B47: 2301281 | C47: Taziko Trakha | D47: =DSA!BF48 -> 35 | E47: =DSA!BG48 -> 41 | F47: =(D47/E47)*100 -> 85.365854 | G47: ='M-III'!BF48 -> 49 | H47: ='M-III'!BG48 -> 65 | I47: =(G47/H47)*100 -> 75.384615 | J47: =OOPS!BG48 -> 31 | K47: =OOPS!BH48 -> 48 | L47: =(J47/K47)*100 -> 64.583333 | M47: =DE!BF48 -> 25 | N47: =DE!BG48 -> 46 | O47: =(M47/N47)*100 -> 54.347826 | P47: =DOS!BF48 -> 36 | Q47: =DOS!BG48 -> 48 | R47: =(P47/Q47)*100 -> 75 | S47: ='OOPS LAB'!AE48 -> 27 | T47: ='OOPS LAB'!AF48 -> 48 | U47: =(S47/T47)*100 -> 56.25 | V47: ='DE LAB'!AE48 -> 16 | W47: ='DE LAB'!AF48 -> 30 | X47: =(V47/W47)*100 -> 53.333333 | Y47: ='DSA LAB'!AE48 -> 30 | Z47: ='DSA LAB'!AF48 -> 41 | AA47: =(Y47/Z47)*100 -> 73.170732 | AB47: ='IT WORKSHOP'!AM48 -> 22 | AC47: ='IT WORKSHOP'!AN48 -> 33 | AD47: =(AB47/AC47)*100 -> 66.666667 | AE47: =D47+G47+J47+M47+P47+S47+V47+Y47+AB47 -> 271 | AF47: =E47+H47+K47+N47+T47+W47+Z47+Q47+AC47 -> 400 | AG47: =AE47/AF47 -> 0.6775
A48: 45 | B48: 2301282 | C48: Uday Kumar | D48: =DSA!BF49 -> 17 | E48: =DSA!BG49 -> 41 | F48: =(D48/E48)*100 -> 41.463415 | G48: ='M-III'!BF49 -> 20 | H48: ='M-III'!BG49 -> 65 | I48: =(G48/H48)*100 -> 30.769231 | J48: =OOPS!BG49 -> 7 | K48: =OOPS!BH49 -> 48 | L48: =(J48/K48)*100 -> 14.583333 | M48: =DE!BF49 -> 17 | N48: =DE!BG49 -> 46 | O48: =(M48/N48)*100 -> 36.956522 | P48: =DOS!BF49 -> 9 | Q48: =DOS!BG49 -> 48 | R48: =(P48/Q48)*100 -> 18.75 | S48: ='OOPS LAB'!AE49 -> 12 | T48: ='OOPS LAB'!AF49 -> 48 | U48: =(S48/T48)*100 -> 25 | V48: ='DE LAB'!AE49 -> 18 | W48: ='DE LAB'!AF49 -> 30 | X48: =(V48/W48)*100 -> 60 | Y48: ='DSA LAB'!AE49 -> 12 | Z48: ='DSA LAB'!AF49 -> 41 | AA48: =(Y48/Z48)*100 -> 29.268293 | AB48: ='IT WORKSHOP'!AM49 -> 6 | AC48: ='IT WORKSHOP'!AN49 -> 33 | AD48: =(AB48/AC48)*100 -> 18.181818 | AE48: =D48+G48+J48+M48+P48+S48+V48+Y48+AB48 -> 118 | AF48: =E48+H48+K48+N48+T48+W48+Z48+Q48+AC48 -> 400 | AG48: =AE48/AF48 -> 0.295
A49: 46 | B49: 2301283 | C49: Vaibhav Shahi | D49: =DSA!BF50 -> 26 | E49: =DSA!BG50 -> 41 | F49: =(D49/E49)*100 -> 63.414634 | G49: ='M-III'!BF50 -> 30 | H49: ='M-III'!BG50 -> 65 | I49: =(G49/H49)*100 -> 46.153846 | J49: =OOPS!BG50 -> 13 | K49: =OOPS!BH50 -> 48 | L49: =(J49/K49)*100 -> 27.083333 | M49: =DE!BF50 -> 26 | N49: =DE!BG50 -> 46 | O49: =(M49/N49)*100 -> 56.521739 | P49: =DOS!BF50 -> 21 | Q49: =DOS!BG50 -> 48 | R49: =(P49/Q49)*100 -> 43.75 | S49: ='OOPS LAB'!AE50 -> 22 | T49: ='OOPS LAB'!AF50 -> 48 | U49: =(S49/T49)*100 -> 45.833333 | V49: ='DE LAB'!AE50 -> 10 | W49: ='DE LAB'!AF50 -> 30 | X49: =(V49/W49)*100 -> 33.333333 | Y49: ='DSA LAB'!AE50 -> 24 | Z49: ='DSA LAB'!AF50 -> 41 | AA49: =(Y49/Z49)*100 -> 58.536585 | AB49: ='IT WORKSHOP'!AM50 -> 9 | AC49: ='IT WORKSHOP'!AN50 -> 33 | AD49: =(AB49/AC49)*100 -> 27.272727 | AE49: =D49+G49+J49+M49+P49+S49+V49+Y49+AB49 -> 181 | AF49: =E49+H49+K49+N49+T49+W49+Z49+Q49+AC49 -> 400 | AG49: =AE49/AF49 -> 0.4525
A50: 47 | B50: 2301284 | C50: Vansh Kumar | D50: =DSA!BF51 -> 0 | E50: =DSA!BG51 -> 41 | F50: =(D50/E50)*100 -> 0 | G50: ='M-III'!BF51 -> 0 | H50: ='M-III'!BG51 -> 65 | I50: =(G50/H50)*100 -> 0 | J50: =OOPS!BG51 -> 0 | K50: =OOPS!BH51 -> 48 | L50: =(J50/K50)*100 -> 0 | M50: =DE!BF51 -> 3 | N50: =DE!BG51 -> 46 | O50: =(M50/N50)*100 -> 6.5217391 | P50: =DOS!BF51 -> 0 | Q50: =DOS!BG51 -> 48 | R50: =(P50/Q50)*100 -> 0 | S50: ='OOPS LAB'!AE51 -> 0 | T50: ='OOPS LAB'!AF51 -> 48 | U50: =(S50/T50)*100 -> 0 | V50: ='DE LAB'!AE51 -> 0 | W50: ='DE LAB'!AF51 -> 30 | X50: =(V50/W50)*100 -> 0 | Y50: ='DSA LAB'!AE51 -> 1 | Z50: ='DSA LAB'!AF51 -> 41 | AA50: =(Y50/Z50)*100 -> 2.4390244 | AB50: ='IT WORKSHOP'!AM51 -> 0 | AC50: ='IT WORKSHOP'!AN51 -> 33 | AD50: =(AB50/AC50)*100 -> 0 | AE50: =D50+G50+J50+M50+P50+S50+V50+Y50+AB50 -> 4 | AF50: =E50+H50+K50+N50+T50+W50+Z50+Q50+AC50 -> 400 | AG50: =AE50/AF50 -> 0.01
A51: 48 | B51: 2301285 | C51: Vansh Sharma | D51: =DSA!BF52 -> 25 | E51: =DSA!BG52 -> 41 | F51: =(D51/E51)*100 -> 60.97561 | G51: ='M-III'!BF52 -> 33 | H51: ='M-III'!BG52 -> 65 | I51: =(G51/H51)*100 -> 50.769231 | J51: =OOPS!BG52 -> 24 | K51: =OOPS!BH52 -> 48 | L51: =(J51/K51)*100 -> 50 | M51: =DE!BF52 -> 30 | N51: =DE!BG52 -> 46 | O51: =(M51/N51)*100 -> 65.217391 | P51: =DOS!BF52 -> 25 | Q51: =DOS!BG52 -> 48 | R51: =(P51/Q51)*100 -> 52.083333 | S51: ='OOPS LAB'!AE52 -> 29 | T51: ='OOPS LAB'!AF52 -> 48 | U51: =(S51/T51)*100 -> 60.416667 | V51: ='DE LAB'!AE52 -> 20 | W51: ='DE LAB'!AF52 -> 30 | X51: =(V51/W51)*100 -> 66.666667 | Y51: ='DSA LAB'!AE52 -> 27 | Z51: ='DSA LAB'!AF52 -> 41 | AA51: =(Y51/Z51)*100 -> 65.853659 | AB51: ='IT WORKSHOP'!AM52 -> 23 | AC51: ='IT WORKSHOP'!AN52 -> 33 | AD51: =(AB51/AC51)*100 -> 69.69697 | AE51: =D51+G51+J51+M51+P51+S51+V51+Y51+AB51 -> 236 | AF51: =E51+H51+K51+N51+T51+W51+Z51+Q51+AC51 -> 400 | AG51: =AE51/AF51 -> 0.59
A52: 49 | B52: 2301286 | C52: Vikramjit Singh | D52: =DSA!BF53 -> 0 | E52: =DSA!BG53 -> 41 | F52: =(D52/E52)*100 -> 0 | G52: ='M-III'!BF53 -> 1 | H52: ='M-III'!BG53 -> 65 | I52: =(G52/H52)*100 -> 1.5384615 | J52: =OOPS!BG53 -> 3 | K52: =OOPS!BH53 -> 48 | L52: =(J52/K52)*100 -> 6.25 | M52: =DE!BF53 -> 6 | N52: =DE!BG53 -> 46 | O52: =(M52/N52)*100 -> 13.043478 | P52: =DOS!BF53 -> 2 | Q52: =DOS!BG53 -> 48 | R52: =(P52/Q52)*100 -> 4.1666667 | S52: ='OOPS LAB'!AE53 -> 2 | T52: ='OOPS LAB'!AF53 -> 48 | U52: =(S52/T52)*100 -> 4.1666667 | V52: ='DE LAB'!AE53 -> 0 | W52: ='DE LAB'!AF53 -> 30 | X52: =(V52/W52)*100 -> 0 | Y52: ='DSA LAB'!AE53 -> 6 | Z52: ='DSA LAB'!AF53 -> 41 | AA52: =(Y52/Z52)*100 -> 14.634146 | AB52: ='IT WORKSHOP'!AM53 -> 1 | AC52: ='IT WORKSHOP'!AN53 -> 33 | AD52: =(AB52/AC52)*100 -> 3.030303 | AE52: =D52+G52+J52+M52+P52+S52+V52+Y52+AB52 -> 21 | AF52: =E52+H52+K52+N52+T52+W52+Z52+Q52+AC52 -> 400 | AG52: =AE52/AF52 -> 0.0525
A53: 50 | B53: 2301287 | C53: Vishavjit Singh | D53: =DSA!BF54 -> 0 | E53: =DSA!BG54 -> 41 | F53: =(D53/E53)*100 -> 0 | G53: ='M-III'!BF54 -> 1 | H53: ='M-III'!BG54 -> 65 | I53: =(G53/H53)*100 -> 1.5384615 | J53: =OOPS!BG54 -> 4 | K53: =OOPS!BH54 -> 48 | L53: =(J53/K53)*100 -> 8.3333333 | M53: =DE!BF54 -> 4 | N53: =DE!BG54 -> 46 | O53: =(M53/N53)*100 -> 8.6956522 | P53: =DOS!BF54 -> 1 | Q53: =DOS!BG54 -> 48 | R53: =(P53/Q53)*100 -> 2.0833333 | S53: ='OOPS LAB'!AE54 -> 2 | T53: ='OOPS LAB'!AF54 -> 48 | U53: =(S53/T53)*100 -> 4.1666667 | V53: ='DE LAB'!AE54 -> 0 | W53: ='DE LAB'!AF54 -> 30 | X53: =(V53/W53)*100 -> 0 | Y53: ='DSA LAB'!AE54 -> 9 | Z53: ='DSA LAB'!AF54 -> 41 | AA53: =(Y53/Z53)*100 -> 21.95122 | AB53: ='IT WORKSHOP'!AM54 -> 7 | AC53: ='IT WORKSHOP'!AN54 -> 33 | AD53: =(AB53/AC53)*100 -> 21.212121 | AE53: =D53+G53+J53+M53+P53+S53+V53+Y53+AB53 -> 28 | AF53: =E53+H53+K53+N53+T53+W53+Z53+Q53+AC53 -> 400 | AG53: =AE53/AF53 -> 0.07
A54: 51 | B54: 2339508 | C54: TANISHA | D54: =DSA!BF55 -> 32 | E54: =DSA!BG55 -> 41 | F54: =(D54/E54)*100 -> 78.04878 | G54: ='M-III'!BF55 -> 48 | H54: ='M-III'!BG55 -> 65 | I54: =(G54/H54)*100 -> 73.846154 | J54: =OOPS!BG55 -> 38 | K54: =OOPS!BH55 -> 48 | L54: =(J54/K54)*100 -> 79.166667 | M54: =DE!BF55 -> 29 | N54: =DE!BG55 -> 46 | O54: =(M54/N54)*100 -> 63.043478 | P54: =DOS!BF55 -> 33 | Q54: =DOS!BG55 -> 48 | R54: =(P54/Q54)*100 -> 68.75 | S54: ='OOPS LAB'!AE55 -> 40 | T54: ='OOPS LAB'!AF55 -> 48 | U54: =(S54/T54)*100 -> 83.333333 | V54: ='DE LAB'!AE55 -> 22 | W54: ='DE LAB'!AF55 -> 30 | X54: =(V54/W54)*100 -> 73.333333 | Y54: ='DSA LAB'!AE55 -> 31 | Z54: ='DSA LAB'!AF55 -> 41 | AA54: =(Y54/Z54)*100 -> 75.609756 | AB54: ='IT WORKSHOP'!AM55 -> 26 | AC54: ='IT WORKSHOP'!AN55 -> 33 | AD54: =(AB54/AC54)*100 -> 78.787879 | AE54: =D54+G54+J54+M54+P54+S54+V54+Y54+AB54 -> 299 | AF54: =E54+H54+K54+N54+T54+W54+Z54+Q54+AC54 -> 400 | AG54: =AE54/AF54 -> 0.7475
A55: 52 | B55: 2339509 | C55: TOHIED AHMED | D55: =DSA!BF56 -> 0 | E55: =DSA!BG56 -> 41 | F55: =(D55/E55)*100 -> 0 | G55: ='M-III'!BF56 -> 0 | H55: ='M-III'!BG56 -> 65 | I55: =(G55/H55)*100 -> 0 | J55: =OOPS!BG56 -> 0 | K55: =OOPS!BH56 -> 48 | L55: =(J55/K55)*100 -> 0 | M55: =DE!BF56 -> 0 | N55: =DE!BG56 -> 46 | O55: =(M55/N55)*100 -> 0 | P55: =DOS!BF56 -> 0 | Q55: =DOS!BG56 -> 48 | R55: =(P55/Q55)*100 -> 0 | S55: ='OOPS LAB'!AE56 -> 0 | T55: ='OOPS LAB'!AF56 -> 48 | U55: =(S55/T55)*100 -> 0 | V55: ='DE LAB'!AE56 -> 0 | W55: ='DE LAB'!AF56 -> 30 | X55: =(V55/W55)*100 -> 0 | Y55: ='DSA LAB'!AE56 -> 0 | Z55: ='DSA LAB'!AF56 -> 41 | AA55: =(Y55/Z55)*100 -> 0 | AB55: ='IT WORKSHOP'!AM56 -> 0 | AC55: ='IT WORKSHOP'!AN56 -> 33 | AD55: =(AB55/AC55)*100 -> 0 | AE55: =D55+G55+J55+M55+P55+S55+V55+Y55+AB55 -> 0 | AF55: =E55+H55+K55+N55+T55+W55+Z55+Q55+AC55 -> 400 | AG55: =AE55/AF55 -> 0
A56: 53 | B56: 2301207 | C56: Harsh thakur | D56: =DSA!BF57 -> 0 | E56: =DSA!BG57 -> 41 | F56: =(D56/E56)*100 -> 0 | G56: ='M-III'!BF57 -> 0 | H56: ='M-III'!BG57 -> 65 | I56: =(G56/H56)*100 -> 0 | J56: =OOPS!BG57 -> 0 | K56: =OOPS!BH57 -> 48 | L56: =(J56/K56)*100 -> 0 | M56: =DE!BF57 -> 0 | N56: =DE!BG57 -> 46 | O56: =(M56/N56)*100 -> 0 | P56: =DOS!BF57 -> 0 | Q56: =DOS!BG57 -> 48 | R56: =(P56/Q56)*100 -> 0 | S56: ='OOPS LAB'!AE57 -> 0 | T56: ='OOPS LAB'!AF57 -> 48 | U56: =(S56/T56)*100 -> 0 | V56: ='DE LAB'!AE57 -> 0 | W56: ='DE LAB'!AF57 -> 30 | X56: =(V56/W56)*100 -> 0 | Y56: ='DSA LAB'!AE57 -> 0 | Z56: ='DSA LAB'!AF57 -> 41 | AA56: =(Y56/Z56)*100 -> 0 | AB56: ='IT WORKSHOP'!AM57 -> 0 | AC56: ='IT WORKSHOP'!AN57 -> 33 | AD56: =(AB56/AC56)*100 -> 0 | AE56: =D56+G56+J56+M56+P56+S56+V56+Y56+AB56 -> 0 | AF56: =E56+H56+K56+N56+T56+W56+Z56+Q56+AC56 -> 400 | AG56: =AE56/AF56 -> 0
A57: 54 | B57: Leet | C57: Gagan | D57: =DSA!BF58 -> 33 | E57: =DSA!BG58 -> 41 | F57: =(D57/E57)*100 -> 80.487805 | G57: ='M-III'!BF58 -> 47 | H57: ='M-III'!BG58 -> 65 | I57: =(G57/H57)*100 -> 72.307692 | J57: =OOPS!BG58 -> 38 | K57: =OOPS!BH58 -> 48 | L57: =(J57/K57)*100 -> 79.166667 | M57: =DE!BF58 -> 34 | N57: =DE!BG58 -> 46 | O57: =(M57/N57)*100 -> 73.913043 | P57: =DOS!BF58 -> 33 | Q57: =DOS!BG58 -> 48 | R57: =(P57/Q57)*100 -> 68.75 | S57: ='OOPS LAB'!AE58 -> 32 | T57: ='OOPS LAB'!AF58 -> 48 | U57: =(S57/T57)*100 -> 66.666667 | V57: ='DE LAB'!AE58 -> 24 | W57: ='DE LAB'!AF58 -> 30 | X57: =(V57/W57)*100 -> 80 | Y57: ='DSA LAB'!AE58 -> 33 | Z57: ='DSA LAB'!AF58 -> 41 | AA57: =(Y57/Z57)*100 -> 80.487805 | AB57: ='IT WORKSHOP'!AM58 -> 22 | AC57: ='IT WORKSHOP'!AN58 -> 33 | AD57: =(AB57/AC57)*100 -> 66.666667 | AE57: =D57+G57+J57+M57+P57+S57+V57+Y57+AB57 -> 296 | AF57: =E57+H57+K57+N57+T57+W57+Z57+Q57+AC57 -> 400 | AG57: =AE57/AF57 -> 0.74
...

Sheet Internal
A1: INTERNAL RECORD JULY-NOVEMBER 2024 (B.Tech CSE 3B)
A2: Subjects | D2: DSA | E2: M-III | F2: OOPS | G2: DE | H2: DOS | I2: OOPS LAB | J2: DE LAB | K2: DSA LAB | L2: IT WORKSHOP
A3: S.No. | B3: Reg No. | C3: Name of Student | D3: 40 | E3: 40 | F3: 40 | G3: 40 | H3: 40 | I3: 30 | J3: 30 | K3: 30 | L3: 30
A4: =OVERALL!A4 -> 1 | B4: =OVERALL!B4 -> 2301236 | C4: =OVERALL!C4 -> Manmohan Singh | D4: =DSA!BX9 -> 17 | E4: ='M-III'!BZ9 -> 13 | F4: =OOPS!CA9 -> 14 | G4: =DE!BY9 -> 16 | H4: =DOS!BX9 -> 10 | I4: ='OOPS LAB'!AS8 -> 13 | J4: ='DE LAB'!AS8 -> 12 | K4: ='DSA LAB'!AS8 -> 13 | L4: ='IT WORKSHOP'!BA8 -> 10
A5: =OVERALL!A5 -> 2 | B5: =OVERALL!B5 -> 2301237 | C5: =OVERALL!C5 -> Manpreet Kaur | D5: =DSA!BX10 -> 33 | E5: ='M-III'!BZ10 -> 29 | F5: =OOPS!CA10 -> 26 | G5: =DE!BY10 -> 33 | H5: =DOS!BX10 -> 32 | I5: ='OOPS LAB'!AS9 -> 22 | J5: ='DE LAB'!AS9 -> 20 | K5: ='DSA LAB'!AS9 -> 16 | L5: ='IT WORKSHOP'!BA9 -> 22
A6: =OVERALL!A6 -> 3 | B6: =OVERALL!B6 -> 2301238 | C6: =OVERALL!C6 -> Md Warish Chesam | D6: =DSA!BX11 -> 23 | E6: ='M-III'!BZ11 -> 24 | F6: =OOPS!CA11 -> 19 | G6: =DE!BY11 -> 24 | H6: =DOS!BX11 -> 17 | I6: ='OOPS LAB'!AS10 -> 17 | J6: ='DE LAB'!AS10 -> 24 | K6: ='DSA LAB'!AS10 -> 20 | L6: ='IT WORKSHOP'!BA10 -> 16
A7: =OVERALL!A7 -> 4 | B7: =OVERALL!B7 -> 2301239 | C7: =OVERALL!C7 -> Mohd Shahid Afridi | D7: =DSA!BX12 -> 0 | E7: ='M-III'!BZ12 -> 0 | F7: =OOPS!CA12 -> 0 | G7: =DE!BY12 -> 2 | H7: =DOS!BX12 -> 0 | I7: ='OOPS LAB'!AS11 -> 0 | J7: ='DE LAB'!AS11 -> 2 | K7: ='DSA LAB'!AS11 -> 0 | L7: ='IT WORKSHOP'!BA11 -> 0
A8: =OVERALL!A8 -> 5 | B8: =OVERALL!B8 -> 2301240 | C8: =OVERALL!C8 -> Munisha | D8: =DSA!BX13 -> 29 | E8: ='M-III'!BZ13 -> 22 | F8: =OOPS!CA13 -> 18 | G8: =DE!BY13 -> 24 | H8: =DOS!BX13 -> 21 | I8: ='OOPS LAB'!AS12 -> 21 | J8: ='DE LAB'!AS12 -> 20 | K8: ='DSA LAB'!AS12 -> 19 | L8: ='IT WORKSHOP'!BA12 -> 24
A9: =OVERALL!A9 -> 6 | B9: =OVERALL!B9 -> 2301241 | C9: =OVERALL!C9 -> Nikhil Kumar Thakur | D9: =DSA!BX14 -> 33 | E9: ='M-III'!BZ14 -> 28 | F9: =OOPS!CA14 -> 24 | G9: =DE!BY14 -> 28 | H9: =DOS!BX14 -> 27 | I9: ='OOPS LAB'!AS13 -> 24 | J9: ='DE LAB'!AS13 -> 23 | K9: ='DSA LAB'!AS13 -> 25 | L9: ='IT WORKSHOP'!BA13 -> 27
A10: =OVERALL!A10 -> 7 | B10: =OVERALL!B10 -> 2301242 | C10: =OVERALL!C10 -> Palak Pathania | D10: =DSA!BX15 -> 32 | E10: ='M-III'!BZ15 -> 27 | F10: =OOPS!CA15 -> 30 | G10: =DE!BY15 -> 24 | H10: =DOS!BX15 -> 22 | I10: ='OOPS LAB'!AS14 -> 25 | J10: ='DE LAB'!AS14 -> 21 | K10: ='DSA LAB'!AS14 -> 23 | L10: ='IT WORKSHOP'!BA14 -> 16
A11: =OVERALL!A11 -> 8 | B11: =OVERALL!B11 -> 2301243 | C11: =OVERALL!C11 -> Pardeep Singh | D11: =DSA!BX16 -> 16 | E11: ='M-III'!BZ16 -> 19 | F11: =OOPS!CA16 -> 19 | G11: =DE!BY16 -> 21 | H11: =DOS!BX16 -> 17 | I11: ='OOPS LAB'!AS15 -> 19 | J11: ='DE LAB'!AS15 -> 14 | K11: ='DSA LAB'!AS15 -> 20 | L11: ='IT WORKSHOP'!BA15 -> 15
A12: =OVERALL!A12 -> 9 | B12: =OVERALL!B12 -> 2301244 | C12: =OVERALL!C12 -> Parveen Mandal | D12: =DSA!BX17 -> 0 | E12: ='M-III'!BZ17 -> 0 | F12: =OOPS!CA17 -> 0 | G12: =DE!BY17 -> 2 | H12: =DOS!BX17 -> 0 | I12: ='OOPS LAB'!AS16 -> 0 | J12: ='DE LAB'!AS16 -> 2 | K12: ='DSA LAB'!AS16 -> 0 | L12: ='IT WORKSHOP'!BA16 -> 0
A13: =OVERALL!A13 -> 10 | B13: =OVERALL!B13 -> 2301245 | C13: =OVERALL!C13 -> Payal | D13: =DSA!BX18 -> 34 | E13: ='M-III'!BZ18 -> 34 | F13: =OOPS!CA18 -> 36 | G13: =DE!BY18 -> 32 | H13: =DOS!BX18 -> 36 | I13: ='OOPS LAB'!AS17 -> 25 | J13: ='DE LAB'!AS17 -> 26 | K13: ='DSA LAB'!AS17 -> 25 | L13: ='IT WORKSHOP'!BA17 -> 27
A14: =OVERALL!A14 -> 11 | B14: =OVERALL!B14 -> 2301247 | C14: =OVERALL!C14 -> Priya | D14: =DSA!BX19 -> 28 | E14: ='M-III'!BZ19 -> 22 | F14: =OOPS!CA19 -> 17 | G14: =DE!BY19 -> 21 | H14: =DOS!BX19 -> 19 | I14: ='OOPS LAB'!AS18 -> 14 | J14: ='DE LAB'!AS18 -> 18 | K14: ='DSA LAB'!AS18 -> 17 | L14: ='IT WORKSHOP'!BA18 -> 20
A15: =OVERALL!A15 -> 12 | B15: =OVERALL!B15 -> 2301248 | C15: =OVERALL!C15 -> Priyam Puri | D15: =DSA!BX20 -> 0 | E15: ='M-III'!BZ20 -> 0 | F15: =OOPS!CA20 -> 0 | G15: =DE!BY20 -> 2 | H15: =DOS!BX20 -> 0 | I15: ='OOPS LAB'!AS19 -> 0 | J15: ='DE LAB'!AS19 -> 2 | K15: ='DSA LAB'!AS19 -> 0 | L15: ='IT WORKSHOP'!BA19 -> 0
... A61: =OVERALL!A61 -> 58 | B61: =OVERALL!B61 -> leet | C61: =OVERALL!C61 -> Shubham | D61: =DSA!BX66 -> 16 | E61: ='M-III'!BZ66 -> 13 | F61: =OOPS!CA66 -> 17 | G61: =DE!BY66 -> 18 | H61: =DOS!BX66 -> 13 | I61: ='OOPS LAB'!AS65 -> 21 | J61: ='DE LAB'!AS65 -> 19 | K61: ='DSA LAB'!AS65 -> 16 | L61: ='IT WORKSHOP'!BA65 -> 21
A62: HIGHEST MARKS | D62: =MAX(D4:D59) -> 35 | E62: =MAX(E4:E59) -> 34 | F62: =MAX(F4:F59) -> 36 | G62: =MAX(G4:G59) -> 33 | H62: =MAX(H4:H59) -> 36 | I62: =MAX(I4:I59) -> 26 | J62: =MAX(J4:J59) -> 26 | K62: =MAX(K4:K59) -> 26 | L62: =MAX(L4:L59) -> 27
A63: LOWEST MARKS | D63: =MIN(D4:D59) -> 0 | E63: =MIN(E4:E59) -> 0 | F63: =MIN(F4:F59) -> 0 | G63: =MIN(G4:G59) -> 2 | H63: =MIN(H4:H59) -> 0 | I63: =MIN(I4:I59) -> 0 | J63: =MIN(J4:J59) -> 0 | K63: =MIN(K4:K59) -> 0 | L63: =MIN(L4:L59) -> 0
A64: AVG INTERNAL | D64: =AVERAGE(D4:D59) -> 17.375 | E64: =AVERAGE(E4:E59) -> 15.053571 | F64: =AVERAGE(F4:F59) -> 16.160714 | G64: =AVERAGE(G4:G59) -> 17.571429 | H64: =AVERAGE(H4:H59) -> 14.946429 | I64: =AVERAGE(I4:I59) -> 13.75 | J64: =AVERAGE(J4:J59) -> 14.642857 | K64: =AVERAGE(K4:K59) -> 13.321429 | L64: =AVERAGE(L4:L59) -> 14
A65: NAME OF SUBJECT INCHARGE | D65: Mr. Manjot | E65: Ms. Simranjit Kaur | F65: Ms. Preet Kaur | G65: Mr. Gurminder Singh | H65: Ms. Ashmeet | I65: Ms. Preet Kaur | J65: Mr. Gurminder Singh | K65: Mr. Manjot | L65: Mr. Sukhdayal
A67: Signature

Sheet OOPS
A1: =OVERALL!A1 -> ATTENDANCE RECORD JULY-NOVEMEBER 2024 (B.Tech CSE 3B)
A2: Ms. Preet Kaur | BK2: CTIEMT
A3: Date | T3: 30/9/24 | U3: 45392 | BD3: 29/11/24 | BE3: PRESENT | BF3: DL (IF ANY) | BG3: Total Attended | BH3: Total Delievered | BI3: PERCENTAGE | BK3: Evaluation Sheet for Internal Awards (Theory)
A4: S.No. | B4: Reg No. | C4: Name of Student | D4: 1 | E4: 2 | F4: 3 | G4: 4 | H4: 5 | I4: 6 | J4: 7 | K4: 8 | L4: 9 | M4: 10 | N4: 11 | O4: 12 | P4: 13 | Q4: 14 | R4: 15 | S4: 16 | T4: 17 | U4: 18 | V4: 19 | W4: 20 | X4: 21 | Y4: 22 | Z4: 23 | AA4: 24 | AB4: 25 | AC4: 26 | AD4: 27 | AE4: 28 | AF4: 29 | AG4: 30 | AH4: 31 | AI4: 32 | AJ4: 33 | AK4: 34 | AL4: 35 | AM4: 36 | AN4: 37 | AO4: 38 | AP4: 39 | AQ4: 40 | AR4: 41 | AS4: 42 | AT4: 43 | AU4: 44 | AV4: 45 | AW4: 46 | AX4: 47 | AY4: 48 | AZ4: 49 | BA4: 50 | BB4: 51 | BC4: 52 | BD4: 17 | BK4: Session: July-November2024
A5: =OVERALL!A4 -> 1 | B5: =OVERALL!B4 -> 2301236 | C5: =OVERALL!C4 -> Manmohan Singh | T5: 15 | U5: 16 | BD5: 19 | BE5: =COUNTIF(D5:BC5,"P")+BD5 -> 19 | BG5: =BE5+BF5 -> 19 | BH5: 48 | BI5: =BG5/BH5 -> 0.39583333 | BK5: Department: CSE | BU5: Semester: 3rd B
A6: =OVERALL!A5 -> 2 | B6: =OVERALL!B5 -> 2301237 | C6: =OVERALL!C5 -> Manpreet Kaur | T6: 24 | U6: 31 | BD6: 36 | BE6: =COUNTIF(D6:BC6,"P")+BD6 -> 36 | BG6: =BE6+BF6 -> 36 | BH6: 48 | BI6: =BG6/BH6 -> 0.75 | BK6: Subject Name:OOPS | BU6: Subject Code: BTCS 302-18
A7: =OVERALL!A6 -> 3 | B7: =OVERALL!B6 -> 2301238 | C7: =OVERALL!C6 -> Md Warish Chesam | T7: 22 | U7: 29 | BD7: 30 | BE7: =COUNTIF(D7:BC7,"P")+BD7 -> 30 | BG7: =BE7+BF7 -> 30 | BH7: 48 | BI7: =BG7/BH7 -> 0.625 | BK7: S.No. | BL7: Reg No. | BM7: Name of Student | BN7: Total Lec Del | BO7: Total Lec Att | BP7: Att %age | BQ7: Att Marks (6) | BR7: MST I | BS7: MST II(Converted) | BT7: MST II(Original) | BU7: MST marks | BV7: Assignment | BY7: Weighted marks in Assignments (10) | BZ7: Grace | CA7: Grand Total (40)
A8: =OVERALL!A7 -> 4 | B8: =OVERALL!B7 -> 2301239 | C8: =OVERALL!C7 -> Mohd Shahid Afridi | T8: 0 | BD8: 0 | BE8: =COUNTIF(D8:BC8,"P")+BD8 -> 0 | BG8: =BE8+BF8 -> 0 | BH8: 48 | BI8: =BG8/BH8 -> 0 | BU8: Average MST I & II (24) | BV8: 1 | BW8: 2 | BX8: 3
A9: =OVERALL!A8 -> 5 | B9: =OVERALL!B8 -> 2301240 | C9: =OVERALL!C8 -> Munisha | T9: 23 | BD9: 33 | BE9: =COUNTIF(D9:BC9,"P")+BD9 -> 33 | BG9: =BE9+BF9 -> 33 | BH9: 48 | BI9: =BG9/BH9 -> 0.6875 | BK9: =OVERALL!A4 -> 1 | BL9: =OVERALL!B4 -> 2301236 | BM9: =OVERALL!C4 -> Manmohan Singh | BN9: =BH5 -> 48 | BO9: =BG5 -> 19 | BP9: =BO9/BN9% -> 39.583333 | BQ9: =IF(BP9>=95.5,"6",IF(BP9>=90.5,"5", IF(BP9>=85.5,"4",IF(BP9>=80.5,"3",IF(BP9>=75.5,"2","0"))))) -> 0 | BR9: 12 | BS9: 10 | BT9: 10 | BU9: =(BR9+BT9)/2 -> 11 | BV9: 0 | BW9: 8 | BX9: 0 | BY9: =AVERAGE(BV9:BX9) -> 2.6666667 | CA9: =ROUND(BQ9+BU9+BY9+BZ9,0) -> 14
A10: =OVERALL!A9 -> 6 | B10: =OVERALL!B9 -> 2301241 | C10: =OVERALL!C9 -> Nikhil Kumar Thakur | T10: 25 | BD10: 42 | BE10: =COUNTIF(D10:BC10,"P")+BD10 -> 42 | BG10: =BE10+BF10 -> 42 | BH10: 48 | BI10: =BG10/BH10 -> 0.875 | BK10: =OVERALL!A5 -> 2 | BL10: =OVERALL!B5 -> 2301237 | BM10: =OVERALL!C5 -> Manpreet Kaur | BN10: =BH6 -> 48 | BO10: =BG6 -> 36 | BP10: =BO10/BN10% -> 75 | BQ10: =IF(BP10>=95.5,"6",IF(BP10>=90.5,"5", IF(BP10>=85.5,"4",IF(BP10>=80.5,"3",IF(BP10>=75.5,"2","0"))))) -> 0 | BR10: 18 | BS10: 17 | BT10: 17 | BU10: =(BR10+BT10)/2 -> 17.5 | BV10: 8 | BW10: 9 | BX10: 8 | BY10: =AVERAGE(BV10:BX10) -> 8.3333333 | CA10: =ROUND(BQ10+BU10+BY10+BZ10,0) -> 26
A11: =OVERALL!A10 -> 7 | B11: =OVERALL!B10 -> 2301242 | C11: =OVERALL!C10 -> Palak Pathania | T11: 25 | BD11: 36 | BE11: =COUNTIF(D11:BC11,"P")+BD11 -> 36 | BG11: =BE11+BF11 -> 36 | BH11: 48 | BI11: =BG11/BH11 -> 0.75 | BK11: =OVERALL!A6 -> 3 | BL11: =OVERALL!B6 -> 2301238 | BM11: =OVERALL!C6 -> Md Warish Chesam | BN11: =BH7 -> 48 | BO11: =BG7 -> 30 | BP11: =BO11/BN11% -> 62.5 | BQ11: =IF(BP11>=95.5,"6",IF(BP11>=90.5,"5", IF(BP11>=85.5,"4",IF(BP11>=80.5,"3",IF(BP11>=75.5,"2","0"))))) -> 0 | BR11: 10 | BS11: 12 | BT11: 12 | BU11: =(BR11+BT11)/2 -> 11 | BV11: 8 | BW11: 9 | BX11: 8 | BY11: =AVERAGE(BV11:BX11) -> 8.3333333 | CA11: =ROUND(BQ11+BU11+BY11+BZ11,0) -> 19
A12: =OVERALL!A11 -> 8 | B12: =OVERALL!B11 -> 2301243 | C12: =OVERALL!C11 -> Pardeep Singh | T12: 20 | BD12: 30 | BE12: =COUNTIF(D12:BC12,"P")+BD12 -> 30 | BG12: =BE12+BF12 -> 30 | BH12: 48 | BI12: =BG12/BH12 -> 0.625 | BK12: =OVERALL!A7 -> 4 | BL12: =OVERALL!B7 -> 2301239 | BM12: =OVERALL!C7 -> Mohd Shahid Afridi | BN12: =BH8 -> 48 | BO12: =BG8 -> 0 | BP12: =BO12/BN12% -> 0 | BQ12: =IF(BP12>=95.5,"6",IF(BP12>=90.5,"5", IF(BP12>=85.5,"4",IF(BP12>=80.5,"3",IF(BP12>=75.5,"2","0"))))) -> 0 | BR12: 0 | BS12: 0 | BT12: 0 | BU12: =(BR12+BT12)/2 -> 0 | BV12: 0 | BW12: 0 | BX12: 0 | BY12: =AVERAGE(BV12:BX12) -> 0 | CA12: =ROUND(BQ12+BU12+BY12+BZ12,0) -> 0
A13: =OVERALL!A12 -> 9 | B13: =OVERALL!B12 -> 2301244 | C13: =OVERALL!C12 -> Parveen Mandal | T13: 0 | BD13: 0 | BE13: 0 | BG13: 0 | BH13: 48 | BI13: =BG13/BH13 -> 0 | BK13: =OVERALL!A8 -> 5 | BL13: =OVERALL!B8 -> 2301240 | BM13: =OVERALL!C8 -> Munisha | BN13: =BH9 -> 48 | BO13: =BG9 -> 33 | BP13: =BO13/BN13% -> 68.75 | BQ13: =IF(BP13>=95.5,"6",IF(BP13>=90.5,"5", IF(BP13>=85.5,"4",IF(BP13>=80.5,"3",IF(BP13>=75.5,"2","0"))))) -> 0 | BR13: 10 | BS13: 9 | BT13: 9 | BU13: =(BR13+BT13)/2 -> 9.5 | BV13: 7 | BW13: 9 | BX13: 8 | BY13: =AVERAGE(BV13:BX13) -> 8 | CA13: =ROUND(BQ13+BU13+BY13+BZ13,0) -> 18
A14: =OVERALL!A13 -> 10 | B14: =OVERALL!B13 -> 2301245 | C14: =OVERALL!C13 -> Payal | T14: 26 | BD14: 40 | BE14: =COUNTIF(D14:BC14,"P")+BD14 -> 40 | BF14: 3 | BG14: =BE14+BF14 -> 43 | BH14: 48 | BI14: =BG14/BH14 -> 0.89583333 | BK14: =OVERALL!A9 -> 6 | BL14: =OVERALL!B9 -> 2301241 | BM14: =OVERALL!C9 -> Nikhil Kumar Thakur | BN14: =BH10 -> 48 | BO14: =BG10 -> 42 | BP14: =BO14/BN14% -> 87.5 | BQ14: =IF(BP14>=95.5,"6",IF(BP14>=90.5,"5", IF(BP14>=85.5,"4",IF(BP14>=80.5,"3",IF(BP14>=75.5,"2","0"))))) -> 4 | BR14: 12 | BS14: =BT21/2.5 -> 3.2 | BT14: 10 | BU14: =(BR14+BT14)/2 -> 11 | BV14: 9 | BW14: 9 | BX14: 8 | BY14: =AVERAGE(BV14:BX14) -> 8.6666667 | CA14: =ROUND(BQ14+BU14+BY14+BZ14,0) -> 24
A15: =OVERALL!A14 -> 11 | B15: =OVERALL!B14 -> 2301247 | C15: =OVERALL!C14 -> Priya | T15: 26 | BD15: 34 | BE15: =COUNTIF(D15:BC15,"P")+BD15 -> 34 | BG15: =BE15+BF15 -> 34 | BH15: 48 | BI15: =BG15/BH15 -> 0.70833333 | BK15: =OVERALL!A10 -> 7 | BL15: =OVERALL!B10 -> 2301242 | BM15: =OVERALL!C10 -> Palak Pathania | BN15: =BH11 -> 48 | BO15: =BG11 -> 36 | BP15: =BO15/BN15% -> 75 | BQ15: =IF(BP15>=95.5,"6",IF(BP15>=90.5,"5", IF(BP15>=85.5,"4",IF(BP15>=80.5,"3",IF(BP15>=75.5,"2","0"))))) -> 0 | BR15: 22 | BS15: =BT22/2.5 -> 4 | BT15: 20 | BU15: =(BR15+BT15)/2 -> 21 | BV15: 9 | BW15: 10 | BX15: 9 | BY15: =AVERAGE(BV15:BX15) -> 9.3333333 | CA15: =ROUND(BQ15+BU15+BY15+BZ15,0) -> 30
A16: =OVERALL!A15 -> 12 | B16: =OVERALL!B15 -> 2301248 | C16: =OVERALL!C15 -> Priyam Puri | T16: 0 | BD16: 0 | BE16: =COUNTIF(D16:BC16,"P")+BD16 -> 0 | BG16: =BE16+BF16 -> 0 | BH16: 48 | BI16: =BG16/BH16 -> 0 | BK16: =OVERALL!A11 -> 8 | BL16: =OVERALL!B11 -> 2301243 | BM16: =OVERALL!C11 -> Pardeep Singh | BN16: =BH12 -> 48 | BO16: =BG12 -> 30 | BP16: =BO16/BN16% -> 62.5 | BQ16: =IF(BP16>=95.5,"6",IF(BP16>=90.5,"5", IF(BP16>=85.5,"4",IF(BP16>=80.5,"3",IF(BP16>=75.5,"2","0"))))) -> 0 | BR16: 16 | BS16: =BT23/2.5 -> 2 | BT16: 7 | BU16: =(BR16+BT16)/2 -> 11.5 | BV16: 8 | BW16: 8 | BX16: 7 | BY16: =AVERAGE(BV16:BX16) -> 7.6666667 | CA16: =ROUND(BQ16+BU16+BY16+BZ16,0) -> 19
A17: =OVERALL!A16 -> 13 | B17: =OVERALL!B16 -> 2301249 | C17: =OVERALL!C16 -> Rahul Sharma | T17: 16 | BD17: 25 | BE17: =COUNTIF(D17:BC17,"P")+BD17 -> 25 | BF17: 5 | BG17: =BE17+BF17 -> 30 | BH17: 48 | BI17: =BG17/BH17 -> 0.625 | BK17: =OVERALL!A12 -> 9 | BL17: =OVERALL!B12 -> 2301244 | BM17: =OVERALL!C12 -> Parveen Mandal | BN17: =BH13 -> 48 | BO17: =BG13 -> 0 | BP17: =BO17/BN17% -> 0 | BQ17: =IF(BP17>=95.5,"6",IF(BP17>=90.5,"5", IF(BP17>=85.5,"4",IF(BP17>=80.5,"3",IF(BP17>=75.5,"2","0"))))) -> 0 | BR17: 0 | BS17: =BT17/2.5 -> 0 | BT17: 0 | BU17: =(BR17+BT17)/2 -> 0 | BV17: 0 | BW17: 0 | BX17: 0 | BY17: =AVERAGE(BV17:BX17) -> 0 | CA17: =ROUND(BQ17+BU17+BY17+BZ17,0) -> 0
A18: =OVERALL!A17 -> 14 | B18: =OVERALL!B17 -> 2301250 | C18: =OVERALL!C17 -> Rahulpreet Singh Khinda | T18: 15 | BD18: 26 | BE18: =COUNTIF(D18:BC18,"P")+BD18 -> 26 | BG18: =BE18+BF18 -> 26 | BH18: 48 | BI18: =BG18/BH18 -> 0.54166667 | BK18: =OVERALL!A13 -> 10 | BL18: =OVERALL!B13 -> 2301245 | BM18: =OVERALL!C13 -> Payal | BN18: =BH14 -> 48 | BO18: =BG14 -> 43 | BP18: =BO18/BN18% -> 89.583333 | BQ18: =IF(BP18>=95.5,"6",IF(BP18>=90.5,"5", IF(BP18>=85.5,"4",IF(BP18>=80.5,"3",IF(BP18>=75.5,"2","0"))))) -> 4 | BR18: 24 | BS18: =BT18/2.5 -> 8.4 | BT18: 21 | BU18: =(BR18+BT18)/2 -> 22.5 | BV18: 9 | BW18: 10 | BX18: 9 | BY18: =AVERAGE(BV18:BX18) -> 9.3333333 | CA18: =ROUND(BQ18+BU18+BY18+BZ18,0) -> 36
A19: =OVERALL!A18 -> 15 | B19: =OVERALL!B18 -> 2301251 | C19: =OVERALL!C18 -> Raj Kumar | T19: 10 | BD19: 20 | BE19: =COUNTIF(D19:BC19,"P")+BD19 -> 20 | BG19: =BE19+BF19 -> 20 | BH19: 48 | BI19: =BG19/BH19 -> 0.41666667 | BK19: =OVERALL!A14 -> 11 | BL19: =OVERALL!B14 -> 2301247 | BM19: =OVERALL!C14 -> Priya | BN19: =BH15 -> 48 | BO19: =BG15 -> 34 | BP19: =BO19/BN19% -> 70.833333 | BQ19: =IF(BP19>=95.5,"6",IF(BP19>=90.5,"5", IF(BP19>=85.5,"4",IF(BP19>=80.5,"3",IF(BP19>=75.5,"2","0"))))) -> 0 | BR19: 18 | BS19: =BT19/2.5 -> 1.6 | BT19: 4 | BU19: =(BR19+BT19)/2 -> 11 | BV19: 9 | BW19: 9 | BX19: 0 | BY19: =AVERAGE(BV19:BX19) -> 6 | CA19: =ROUND(BQ19+BU19+BY19+BZ19,0) -> 17
A20: =OVERALL!A19 -> 16 | B20: =OVERALL!B19 -> 2301252 | C20: =OVERALL!C19 -> Rajan Sharma | T20: 24 | BD20: 40 | BE20: =COUNTIF(D20:BC20,"P")+BD20 -> 40 | BG20: =BE20+BF20 -> 40 | BH20: 48 | BI20: =BG20/BH20 -> 0.83333333 | BK20: =OVERALL!A15 -> 12 | BL20: =OVERALL!B15 -> 2301248 | BM20: =OVERALL!C15 -> Priyam Puri | BN20: =BH16 -> 48 | BO20: =BG16 -> 0 | BP20: =BO20/BN20% -> 0 | BQ20: =IF(BP20>=95.5,"6",IF(BP20>=90.5,"5", IF(BP20>=85.5,"4",IF(BP20>=80.5,"3",IF(BP20>=75.5,"2","0"))))) -> 0 | BR20: 0 | BS20: =BT20/2.5 -> 0 | BT20: 0 | BU20: =(BR20+BT20)/2 -> 0 | BV20: 0 | BW20: 0 | BX20: 0 | BY20: =AVERAGE(BV20:BX20) -> 0 | CA20: =ROUND(BQ20+BU20+BY20+BZ20,0) -> 0
A21: =OVERALL!A20 -> 17 | B21: =OVERALL!B20 -> 2301253 | C21: =OVERALL!C20 -> Rajwinder Kaur | T21: 15 | BD21: 25 | BE21: =COUNTIF(D21:BC21,"P")+BD21 -> 25 | BG21: =BE21+BF21 -> 25 | BH21: 48 | BI21: =BG21/BH21 -> 0.52083333 | BK21: =OVERALL!A16 -> 13 | BL21: =OVERALL!B16 -> 2301249 | BM21: =OVERALL!C16 -> Rahul Sharma | BN21: =BH17 -> 48 | BO21: =BG17 -> 30 | BP21: =BO21/BN21% -> 62.5 | BQ21: =IF(BP21>=95.5,"6",IF(BP21>=90.5,"5", IF(BP21>=85.5,"4",IF(BP21>=80.5,"3",IF(BP21>=75.5,"2","0"))))) -> 0 | BR21: 13 | BS21: =BT21/2.5 -> 3.2 | BT21: 8 | BU21: =(BR21+BT21)/2 -> 10.5 | BV21: 7 | BW21: 0 | BX21: 0 | BY21: =AVERAGE(BV21:BX21) -> 2.3333333 | CA21: =ROUND(BQ21+BU21+BY21+BZ21,0) -> 13
A22: =OVERALL!A21 -> 18 | B22: =OVERALL!B21 -> 2301254 | C22: =OVERALL!C21 -> RANJIT SHAH KANU | T22: 0 | BD22: 0 | BE22: =COUNTIF(D22:BC22,"P")+BD22 -> 0 | BG22: =BE22+BF22 -> 0 | BH22: 48 | BI22: =BG22/BH22 -> 0 | BK22: =OVERALL!A17 -> 14 | BL22: =OVERALL!B17 -> 2301250 | BM22: =OVERALL!C17 -> Rahulpreet Singh Khinda | BN22: =BH18 -> 48 | BO22: =BG18 -> 26 | BP22: =BO22/BN22% -> 54.166667 | BQ22: =IF(BP22>=95.5,"6",IF(BP22>=90.5,"5", IF(BP22>=85.5,"4",IF(BP22>=80.5,"3",IF(BP22>=75.5,"2","0"))))) -> 0 | BR22: 11 | BS22: =BT22/2.5 -> 4 | BT22: 10 | BU22: =(BR22+BT22)/2 -> 10.5 | BV22: 7 | BW22: 9 | BX22: 8 | BY22: =AVERAGE(BV22:BX22) -> 8 | CA22: =ROUND(BQ22+BU22+BY22+BZ22,0) -> 19
A23: =OVERALL!A22 -> 19 | B23: =OVERALL!B22 -> 2301255 | C23: =OVERALL!C22 -> Ravi Bhushan Kumar | T23: 23 | BD23: 38 | BE23: =COUNTIF(D23:BC23,"P")+BD23 -> 38 | BG23: =BE23+BF23 -> 38 | BH23: 48 | BI23: =BG23/BH23 -> 0.79166667 | BK23: =OVERALL!A18 -> 15 | BL23: =OVERALL!B18 -> 2301251 | BM23: =OVERALL!C18 -> Raj Kumar | BN23: =BH19 -> 48 | BO23: =BG19 -> 20 | BP23: =BO23/BN23% -> 41.666667 | BQ23: =IF(BP23>=95.5,"6",IF(BP23>=90.5,"5", IF(BP23>=85.5,"4",IF(BP23>=80.5,"3",IF(BP23>=75.5,"2","0"))))) -> 0 | BR23: 10 | BS23: =BT23/2.5 -> 2 | BT23: 5 | BU23: =(BR23+BT23)/2 -> 7.5 | BV23: 8 | BW23: 8 | BX23: 7 | BY23: =AVERAGE(BV23:BX23) -> 7.6666667 | CA23: =ROUND(BQ23+BU23+BY23+BZ23,0) -> 15
A24: =OVERALL!A23 -> 20 | B24: =OVERALL!B23 -> 2301256 | C24: =OVERALL!C23 -> Reshma | T24: 22 | BD24: 32 | BE24: =COUNTIF(D24:BC24,"P")+BD24 -> 32 | BG24: =BE24+BF24 -> 32 | BH24: 48 | BI24: =BG24/BH24 -> 0.66666667 | BK24: =OVERALL!A19 -> 16 | BL24: =OVERALL!B19 -> 2301252 | BM24: =OVERALL!C19 -> Rajan Sharma | BN24: =BH20 -> 48 | BO24: =BG20 -> 40 | BP24: =BO24/BN24% -> 83.333333 | BQ24: =IF(BP24>=95.5,"6",IF(BP24>=90.5,"5", IF(BP24>=85.5,"4",IF(BP24>=80.5,"3",IF(BP24>=75.5,"2","0"))))) -> 3 | BR24: 15 | BS24: =BT24/2.5 -> 4 | BT24: 10 | BU24: =(BR24+BT24)/2 -> 12.5 | BV24: 9 | BW24: 10 | BX24: 9 | BY24: =AVERAGE(BV24:BX24) -> 9.3333333 | CA24: =ROUND(BQ24+BU24+BY24+BZ24,0) -> 25
A25: =OVERALL!A24 -> 21 | B25: =OVERALL!B24 -> 2301257 | C25: =OVERALL!C24 -> Ritesh Kumar Choudhary | T25: 12 | BD25: 14 | BE25: =COUNTIF(D25:BC25,"P")+BD25 -> 14 | BF25: 13 | BG25: =BE25+BF25 -> 27 | BH25: 48 | BI25: =BG25/BH25 -> 0.5625 | BK25: =OVERALL!A20 -> 17 | BL25: =OVERALL!B20 -> 2301253 | BM25: =OVERALL!C20 -> Rajwinder Kaur | BN25: =BH21 -> 48 | BO25: =BG21 -> 25 | BP25: =BO25/BN25% -> 52.083333 | BQ25: =IF(BP25>=95.5,"6",IF(BP25>=90.5,"5", IF(BP25>=85.5,"4",IF(BP25>=80.5,"3",IF(BP25>=75.5,"2","0"))))) -> 0 | BR25: 20 | BS25: =BT25/2.5 -> 7.2 | BT25: 18 | BU25: =(BR25+BT25)/2 -> 19 | BV25: 8 | BW25: 10 | BX25: 9 | BY25: =AVERAGE(BV25:BX25) -> 9 | CA25: =ROUND(BQ25+BU25+BY25+BZ25,0) -> 28
A26: =OVERALL!A25 -> 22 | B26: =OVERALL!B25 -> 2301258 | C26: =OVERALL!C25 -> Ritesh Thakur | T26: 11 | BD26: 13 | BE26: =COUNTIF(D26:BC26,"P")+BD26 -> 13 | BG26: =BE26+BF26 -> 13 | BH26: 48 | BI26: =BG26/BH26 -> 0.27083333 | BK26: =OVERALL!A21 -> 18 | BL26: =OVERALL!B21 -> 2301254 | BM26: =OVERALL!C21 -> RANJIT SHAH KANU | BN26: =BH22 -> 48 | BO26: =BG22 -> 0 | BP26: =BO26/BN26% -> 0 | BQ26: =IF(BP26>=95.5,"6",IF(BP26>=90.5,"5", IF(BP26>=85.5,"4",IF(BP26>=80.5,"3",IF(BP26>=75.5,"2","0"))))) -> 0 | BR26: 0 | BS26: =BT26/2.5 -> 0 | BT26: 0 | BU26: =(BR26+BT26)/2 -> 0 | BV26: 0 | BW26: 0 | BX26: 0 | BY26: =AVERAGE(BV26:BX26) -> 0 | CA26: =ROUND(BQ26+BU26+BY26+BZ26,0) -> 0
A27: =OVERALL!A26 -> 23 | B27: =OVERALL!B26 -> 2301259 | C27: =OVERALL!C26 -> Riya Thakur | T27: 24 | BD27: 31 | BE27: =COUNTIF(D27:BC27,"P")+BD27 -> 31 | BG27: =BE27+BF27 -> 31 | BH27: 48 | BI27: =BG27/BH27 -> 0.64583333 | BK27: =OVERALL!A22 -> 19 | BL27: =OVERALL!B22 -> 2301255 | BM27: =OVERALL!C22 -> Ravi Bhushan Kumar | BN27: =BH23 -> 48 | BO27: =BG23 -> 38 | BP27: =BO27/BN27% -> 79.166667 | BQ27: =IF(BP27>=95.5,"6",IF(BP27>=90.5,"5", IF(BP27>=85.5,"4",IF(BP27>=80.5,"3",IF(BP27>=75.5,"2","0"))))) -> 2 | BR27: 24 | BS27: =BT27/2.5 -> 6.8 | BT27: 17 | BU27: =(BR27+BT27)/2 -> 20.5 | BV27: 9 | BW27: 10 | BX27: 10 | BY27: =AVERAGE(BV27:BX27) -> 9.6666667 | CA27: =ROUND(BQ27+BU27+BY27+BZ27,0) -> 32
A28: =OVERALL!A27 -> 24 | B28: =OVERALL!B27 -> 2301260 | C28: =OVERALL!C27 -> Rounit Dhiman | T28: 19 | BD28: 32 | BE28: =COUNTIF(D28:BC28,"P")+BD28 -> 32 | BF28: 1 | BG28: =BE28+BF28 -> 33 | BH28: 48 | BI28: =BG28/BH28 -> 0.6875 | BK28: =OVERALL!A23 -> 20 | BL28: =OVERALL!B23 -> 2301256 | BM28: =OVERALL!C23 -> Reshma | BN28: =BH24 -> 48 | BO28: =BG24 -> 32 | BP28: =BO28/BN28% -> 66.666667 | BQ28: =IF(BP28>=95.5,"6",IF(BP28>=90.5,"5", IF(BP28>=85.5,"4",IF(BP28>=80.5,"3",IF(BP28>=75.5,"2","0"))))) -> 0 | BR28: 7 | BS28: =BT28/2.5 -> 4 | BT28: 10 | BU28: =(BR28+BT28)/2 -> 8.5 | BV28: 7 | BW28: 8 | BX28: 9 | BY28: =AVERAGE(BV28:BX28) -> 8 | CA28: =ROUND(BQ28+BU28+BY28+BZ28,0) -> 17
A29: =OVERALL!A28 -> 25 | B29: =OVERALL!B28 -> 2301261 | C29: =OVERALL!C28 -> Rubby Kumari | T29: 7 | BD29: 8 | BE29: =COUNTIF(D29:BC29,"P")+BD29 -> 8 | BG29: =BE29+BF29 -> 8 | BH29: 48 | BI29: =BG29/BH29 -> 0.16666667 | BK29: =OVERALL!A24 -> 21 | BL29: =OVERALL!B24 -> 2301257 | BM29: =OVERALL!C24 -> Ritesh Kumar Choudhary | BN29: =BH25 -> 48 | BO29: =BG25 -> 27 | BP29: =BO29/BN29% -> 56.25 | BQ29: =IF(BP29>=95.5,"6",IF(BP29>=90.5,"5", IF(BP29>=85.5,"4",IF(BP29>=80.5,"3",IF(BP29>=75.5,"2","0"))))) -> 0 | BR29: 10 | BS29: =BT29/2.5 -> 4 | BT29: 10 | BU29: =(BR29+BT29)/2 -> 10 | BV29: 7 | BW29: 8 | BX29: 8 | BY29: =AVERAGE(BV29:BX29) -> 7.6666667 | CA29: =ROUND(BQ29+BU29+BY29+BZ29,0) -> 18
A30: =OVERALL!A29 -> 26 | B30: =OVERALL!B29 -> 2301262 | C30: =OVERALL!C29 -> Sakshi Devi | T30: 23 | BD30: 30 | BE30: =COUNTIF(D30:BC30,"P")+BD30 -> 30 | BG30: =BE30+BF30 -> 30 | BH30: 48 | BI30: =BG30/BH30 -> 0.625 | BK30: =OVERALL!A25 -> 22 | BL30: =OVERALL!B25 -> 2301258 | BM30: =OVERALL!C25 -> Ritesh Thakur | BN30: =BH26 -> 48 | BO30: =BG26 -> 13 | BP30: =BO30/BN30% -> 27.083333 | BQ30: =IF(BP30>=95.5,"6",IF(BP30>=90.5,"5", IF(BP30>=85.5,"4",IF(BP30>=80.5,"3",IF(BP30>=75.5,"2","0"))))) -> 0 | BR30: 0 | BS30: =BT30/2.5 -> 3.2 | BT30: 8 | BU30: =(BR30+BT30)/2 -> 4 | BV30: 0 | BW30: 0 | BX30: 0 | BY30: =AVERAGE(BV30:BX30) -> 0 | CA30: =ROUND(BQ30+BU30+BY30+BZ30,0) -> 4
A31: =OVERALL!A30 -> 27 | B31: =OVERALL!B30 -> 2301263 | C31: =OVERALL!C30 -> Sanchi Sharma | T31: 26 | BD31: 43 | BE31: =COUNTIF(D31:BC31,"P")+BD31 -> 43 | BG31: =BE31+BF31 -> 43 | BH31: 48 | BI31: =BG31/BH31 -> 0.89583333 | BK31: =OVERALL!A26 -> 23 | BL31: =OVERALL!B26 -> 2301259 | BM31: =OVERALL!C26 -> Riya Thakur | BN31: =BH27 -> 48 | BO31: =BG27 -> 31 | BP31: =BO31/BN31% -> 64.583333 | BQ31: =IF(BP31>=95.5,"6",IF(BP31>=90.5,"5", IF(BP31>=85.5,"4",IF(BP31>=80.5,"3",IF(BP31>=75.5,"2","0"))))) -> 0 | BR31: 11 | BS31: =BT31/2.5 -> 5.6 | BT31: 14 | BU31: =(BR31+BT31)/2 -> 12.5 | BV31: 7 | BW31: 9 | BX31: 8 | BY31: =AVERAGE(BV31:BX31) -> 8 | CA31: =ROUND(BQ31+BU31+BY31+BZ31,0) -> 21
A32: =OVERALL!A31 -> 28 | B32: =OVERALL!B31 -> 2301264 | C32: =OVERALL!C31 -> Sarbjit Singh | T32: 10 | BD32: 14 | BE32: =COUNTIF(D32:BC32,"P")+BD32 -> 14 | BG32: =BE32+BF32 -> 14 | BH32: 48 | BI32: =BG32/BH32 -> 0.29166667 | BK32: =OVERALL!A27 -> 24 | BL32: =OVERALL!B27 -> 2301260 | BM32: =OVERALL!C27 -> Rounit Dhiman | BN32: =BH28 -> 48 | BO32: =BG28 -> 33 | BP32: =BO32/BN32% -> 68.75 | BQ32: =IF(BP32>=95.5,"6",IF(BP32>=90.5,"5", IF(BP32>=85.5,"4",IF(BP32>=80.5,"3",IF(BP32>=75.5,"2","0"))))) -> 0 | BR32: 11 | BS32: =BT32/2.5 -> 5.2 | BT32: 13 | BU32: =(BR32+BT32)/2 -> 12 | BV32: 7 | BW32: 9 | BX32: 8 | BY32: =AVERAGE(BV32:BX32) -> 8 | CA32: =ROUND(BQ32+BU32+BY32+BZ32,0) -> 20
