Workbook

Sheet OVERALL
A1: ATTENDANCE RECORD JAN-JUNE 2025 (B.Tech CSE 4B)
A2: S.No. | B2: Reg No. | C2: Name of Student | D2: DM | G2: COA | J2: OS | M2: DAA | P2: UHV2 | S2: EVS | V2: COA LAB | Y2: OS LAB | AB2: DAA LAB | AE2: OVERALL
D3: TA | E3: TD | F3: Att %age | G3: TA | H3: TD | I3: Att %age | J3: TA | K3: TD | L3: Att %age | M3: TA | N3: TD | O3: Att %age | P3: TA | Q3: TD | R3: Att %age | S3: TA | T3: TD | U3: Att %age | V3: TA | W3: TD | X3: Att %age | Y3: TA | Z3: TD | AA3: Att %age | AB3: TA | AC3: TD | AD3: Att %age | AE3: TA | AF3: TD | AG3: Att %age
A4: 1 | B4: 2301249 | C4: Rahul Sharma | D4: =DM!BK7 -> 19 | E4: =DM!BL7 -> 45 | F4: =(D4/E4)*100 -> 42.222222 | G4: =COA!BK7 -> 15 | H4: =COA!BL7 -> 30 | I4: =(G4/H4)*100 -> 50 | J4: =OS!BK7 -> 17 | K4: =OS!BL7 -> 33 | L4: =(J4/K4)*100 -> 51.515152 | M4: =DAA!BK7 -> 30 | N4: =DAA!BL7 -> 33 | O4: =(M4/N4)*100 -> 90.909091 | P4: ='UHV2'!BK7 -> 14 | Q4: ='UHV2'!BL7 -> 29 | R4: =(P4/Q4)*100 -> 48.275862 | S4: =EVS!BK7 -> 18 | T4: =EVS!BL7 -> 29 | U4: =(S4/T4)*100 -> 62.068966 | V4: =COAlab!BK7 -> 10 | W4: =COAlab!BL7 -> 22 | X4: =(V4/W4)*100 -> 45.454545 | Y4: =OSlab!BK7 -> 21 | Z4: =OSlab!BL7 -> 43 | AA4: =(Y4/Z4)*100 -> 48.837209 | AB4: =DAAlab!BK7 -> 34 | AC4: =DAAlab!BL7 -> 44 | AD4: =(AB4/AC4)*100 -> 77.272727 | AE4: =AB4+Y4+V4+S4+P4+M4+J4+G4+D4 -> 178 | AF4: =AC4+Z4+W4+T4+Q4+N4+K4+H4+E4 -> 308 | AG4: =(AE4/AF4)*100 -> 57.792208
A5: 2 | B5: 2301251 | C5: Raj Kumar | D5: =DM!BK8 -> 29 | E5: =DM!BL8 -> 45 | F5: =(D5/E5)*100 -> 64.444444 | G5: =COA!BK8 -> 18 | H5: =COA!BL8 -> 30 | I5: =(G5/H5)*100 -> 60 | J5: =OS!BK8 -> 21 | K5: =OS!BL8 -> 33 | L5: =(J5/K5)*100 -> 63.636364 | M5: =DAA!BK8 -> 21 | N5: =DAA!BL8 -> 33 | O5: =(M5/N5)*100 -> 63.636364 | P5: ='UHV2'!BK8 -> 21 | Q5: ='UHV2'!BL8 -> 29 | R5: =(P5/Q5)*100 -> 72.413793 | S5: =EVS!BK8 -> 20 | T5: =EVS!BL8 -> 29 | U5: =(S5/T5)*100 -> 68.965517 | V5: =COAlab!BK8 -> 6 | W5: =COAlab!BL8 -> 22 | X5: =(V5/W5)*100 -> 27.272727 | Y5: =OSlab!BK8 -> 36 | Z5: =OSlab!BL8 -> 43 | AA5: =(Y5/Z5)*100 -> 83.72093 | AB5: =DAAlab!BK8 -> 34 | AC5: =DAAlab!BL8 -> 44 | AD5: =(AB5/AC5)*100 -> 77.272727 | AE5: =AB5+Y5+V5+S5+P5+M5+J5+G5+D5 -> 206 | AF5: =AC5+Z5+W5+T5+Q5+N5+K5+H5+E5 -> 308 | AG5: =(AE5/AF5)*100 -> 66.883117
A6: 3 | B6: 2301252 | C6: Rajan Sharma | D6: =DM!BK9 -> 34 | E6: =DM!BL9 -> 45 | F6: =(D6/E6)*100 -> 75.555556 | G6: =COA!BK9 -> 20 | H6: =COA!BL9 -> 30 | I6: =(G6/H6)*100 -> 66.666667 | J6: =OS!BK9 -> 27 | K6: =OS!BL9 -> 33 | L6: =(J6/K6)*100 -> 81.818182 | M6: =DAA!BK9 -> 22 | N6: =DAA!BL9 -> 33 | O6: =(M6/N6)*100 -> 66.666667 | P6: ='UHV2'!BK9 -> 24 | Q6: ='UHV2'!BL9 -> 29 | R6: =(P6/Q6)*100 -> 82.758621 | S6: =EVS!BK9 -> 22 | T6: =EVS!BL9 -> 29 | U6: =(S6/T6)*100 -> 75.862069 | V6: =COAlab!BK9 -> 18 | W6: =COAlab!BL9 -> 22 | X6: =(V6/W6)*100 -> 81.818182 | Y6: =OSlab!BK9 -> 36 | Z6: =OSlab!BL9 -> 43 | AA6: =(Y6/Z6)*100 -> 83.72093 | AB6: =DAAlab!BK9 -> 30 | AC6: =DAAlab!BL9 -> 44 | AD6: =(AB6/AC6)*100 -> 68.181818 | AE6: =AB6+Y6+V6+S6+P6+M6+J6+G6+D6 -> 233 | AF6: =AC6+Z6+W6+T6+Q6+N6+K6+H6+E6 -> 308 | AG6: =(AE6/AF6)*100 -> 75.649351
A7: 4 | B7: 2301253 | C7: Rajwinder Kaur | D7: =DM!BK10 -> 30 | E7: =DM!BL10 -> 45 | F7: =(D7/E7)*100 -> 66.666667 | G7: =COA!BK10 -> 24 | H7: =COA!BL10 -> 30 | I7: =(G7/H7)*100 -> 80 | J7: =OS!BK10 -> 28 | K7: =OS!BL10 -> 33 | L7: =(J7/K7)*100 -> 84.848485 | M7: =DAA!BK10 -> 26 | N7: =DAA!BL10 -> 33 | O7: =(M7/N7)*100 -> 78.787879 | P7: ='UHV2'!BK10 -> 21 | Q7: ='UHV2'!BL10 -> 29 | R7: =(P7/Q7)*100 -> 72.413793 | S7: =EVS!BK10 -> 26 | T7: =EVS!BL10 -> 29 | U7: =(S7/T7)*100 -> 89.655172 | V7: =COAlab!BK10 -> 17 | W7: =COAlab!BL10 -> 22 | X7: =(V7/W7)*100 -> 77.272727 | Y7: =OSlab!BK10 -> 22 | Z7: =OSlab!BL10 -> 43 | AA7: =(Y7/Z7)*100 -> 51.162791 | AB7: =DAAlab!BK10 -> 39 | AC7: =DAAlab!BL10 -> 44 | AD7: =(AB7/AC7)*100 -> 88.636364 | AE7: =AB7+Y7+V7+S7+P7+M7+J7+G7+D7 -> 233 | AF7: =AC7+Z7+W7+T7+Q7+N7+K7+H7+E7 -> 308 | AG7: =(AE7/AF7)*100 -> 75.649351
A8: 5 | B8: 2301255 | C8: Ravi Bhushan Kumar | D8: =DM!BK11 -> 36 | E8: =DM!BL11 -> 45 | F8: =(D8/E8)*100 -> 80 | G8: =COA!BK11 -> 26 | H8: =COA!BL11 -> 30 | I8: =(G8/H8)*100 -> 86.666667 | J8: =OS!BK11 -> 25 | K8: =OS!BL11 -> 33 | L8: =(J8/K8)*100 -> 75.757576 | M8: =DAA!BK11 -> 27 | N8: =DAA!BL11 -> 33 | O8: =(M8/N8)*100 -> 81.818182 | P8: ='UHV2'!BK11 -> 23 | Q8: ='UHV2'!BL11 -> 29 | R8: =(P8/Q8)*100 -> 79.310345 | S8: =EVS!BK11 -> 22 | T8: =EVS!BL11 -> 29 | U8: =(S8/T8)*100 -> 75.862069 | V8: =COAlab!BK11 -> 20 | W8: =COAlab!BL11 -> 22 | X8: =(V8/W8)*100 -> 90.909091 | Y8: =OSlab!BK11 -> 39 | Z8: =OSlab!BL11 -> 43 | AA8: =(Y8/Z8)*100 -> 90.697674 | AB8: =DAAlab!BK11 -> 38 | AC8: =DAAlab!BL11 -> 44 | AD8: =(AB8/AC8)*100 -> 86.363636 | AE8: =AB8+Y8+V8+S8+P8+M8+J8+G8+D8 -> 256 | AF8: =AC8+Z8+W8+T8+Q8+N8+K8+H8+E8 -> 308 | AG8: =(AE8/AF8)*100 -> 83.116883
A9: 6 | B9: 2301256 | C9: Reshma | D9: =DM!BK12 -> 37 | E9: =DM!BL12 -> 45 | F9: =(D9/E9)*100 -> 82.222222 | G9: =COA!BK12 -> 30 | H9: =COA!BL12 -> 30 | I9: =(G9/H9)*100 -> 100 | J9: =OS!BK12 -> 31 | K9: =OS!BL12 -> 33 | L9: =(J9/K9)*100 -> 93.939394 | M9: =DAA!BK12 -> 31 | N9: =DAA!BL12 -> 33 | O9: =(M9/N9)*100 -> 93.939394 | P9: ='UHV2'!BK12 -> 22 | Q9: ='UHV2'!BL12 -> 29 | R9: =(P9/Q9)*100 -> 75.862069 | S9: =EVS!BK12 -> 25 | T9: =EVS!BL12 -> 29 | U9: =(S9/T9)*100 -> 86.206897 | V9: =COAlab!BK12 -> 22 | W9: =COAlab!BL12 -> 22 | X9: =(V9/W9)*100 -> 100 | Y9: =OSlab!BK12 -> 36 | Z9: =OSlab!BL12 -> 43 | AA9: =(Y9/Z9)*100 -> 83.72093 | AB9: =DAAlab!BK12 -> 34 | AC9: =DAAlab!BL12 -> 44 | AD9: =(AB9/AC9)*100 -> 77.272727 | AE9: =AB9+Y9+V9+S9+P9+M9+J9+G9+D9 -> 268 | AF9: =AC9+Z9+W9+T9+Q9+N9+K9+H9+E9 -> 308 | AG9: =(AE9/AF9)*100 -> 87.012987
A10: 7 | B10: 2301257 | C10: Ritesh Kumar Choudhary | D10: =DM!BK13 -> 30 | E10: =DM!BL13 -> 45 | F10: =(D10/E10)*100 -> 66.666667 | G10: =COA!BK13 -> 16 | H10: =COA!BL13 -> 30 | I10: =(G10/H10)*100 -> 53.333333 | J10: =OS!BK13 -> 22 | K10: =OS!BL13 -> 33 | L10: =(J10/K10)*100 -> 66.666667 | M10: =DAA!BK13 -> 30 | N10: =DAA!BL13 -> 33 | O10: =(M10/N10)*100 -> 90.909091 | P10: ='UHV2'!BK13 -> 20 | Q10: ='UHV2'!BL13 -> 29 | R10: =(P10/Q10)*100 -> 68.965517 | S10: =EVS!BK13 -> 22 | T10: =EVS!BL13 -> 29 | U10: =(S10/T10)*100 -> 75.862069 | V10: =COAlab!BK13 -> 10 | W10: =COAlab!BL13 -> 22 | X10: =(V10/W10)*100 -> 45.454545 | Y10: =OSlab!BK13 -> 32 | Z10: =OSlab!BL13 -> 43 | AA10: =(Y10/Z10)*100 -> 74.418605 | AB10: =DAAlab!BK13 -> 28 | AC10: =DAAlab!BL13 -> 44 | AD10: =(AB10/AC10)*100 -> 63.636364 | AE10: =AB10+Y10+V10+S10+P10+M10+J10+G10+D10 -> 210 | AF10: =AC10+Z10+W10+T10+Q10+N10+K10+H10+E10 -> 308 | AG10: =(AE10/AF10)*100 -> 68.181818
A11: 8 | B11: 2301258 | C11: Ritesh Thakur | D11: =DM!BK14 -> 8 | E11: =DM!BL14 -> 45 | F11: =(D11/E11)*100 -> 17.777778 | G11: =COA!BK14 -> 1 | H11: =COA!BL14 -> 30 | I11: =(G11/H11)*100 -> 3.3333333 | J11: =OS!BK14 -> 4 | K11: =OS!BL14 -> 33 | L11: =(J11/K11)*100 -> 12.121212 | M11: =DAA!BK14 -> 4 | N11: =DAA!BL14 -> 33 | O11: =(M11/N11)*100 -> 12.121212 | P11: ='UHV2'!BK14 -> 14 | Q11: ='UHV2'!BL14 -> 29 | R11: =(P11/Q11)*100 -> 48.275862 | S11: =EVS!BK14 -> 13 | T11: =EVS!BL14 -> 29 | U11: =(S11/T11)*100 -> 44.827586 | V11: =COAlab!BK14 -> 4 | W11: =COAlab!BL14 -> 22 | X11: =(V11/W11)*100 -> 18.181818 | Y11: =OSlab!BK14 -> 6 | Z11: =OSlab!BL14 -> 43 | AA11: =(Y11/Z11)*100 -> 13.953488 | AB11: =DAAlab!BK14 -> 12 | AC11: =DAAlab!BL14 -> 44 | AD11: =(AB11/AC11)*100 -> 27.272727 | AE11: =AB11+Y11+V11+S11+P11+M11+J11+G11+D11 -> 66 | AF11: =AC11+Z11+W11+T11+Q11+N11+K11+H11+E11 -> 308 | AG11: =(AE11/AF11)*100 -> 21.428571
A12: 9 | B12: 2301259 | C12: Riya Thakur | D12: =DM!BK15 -> 29 | E12: =DM!BL15 -> 45 | F12: =(D12/E12)*100 -> 64.444444 | G12: =COA!BK15 -> 26 | H12: =COA!BL15 -> 30 | I12: =(G12/H12)*100 -> 86.666667 | J12: =OS!BK15 -> 26 | K12: =OS!BL15 -> 33 | L12: =(J12/K12)*100 -> 78.787879 | M12: =DAA!BK15 -> 26 | N12: =DAA!BL15 -> 33 | O12: =(M12/N12)*100 -> 78.787879 | P12: ='UHV2'!BK15 -> 19 | Q12: ='UHV2'!BL15 -> 29 | R12: =(P12/Q12)*100 -> 65.517241 | S12: =EVS!BK15 -> 23 | T12: =EVS!BL15 -> 29 | U12: =(S12/T12)*100 -> 79.310345 | V12: =COAlab!BK15 -> 20 | W12: =COAlab!BL15 -> 22 | X12: =(V12/W12)*100 -> 90.909091 | Y12: =OSlab!BK15 -> 26 | Z12: =OSlab!BL15 -> 43 | AA12: =(Y12/Z12)*100 -> 60.465116 | AB12: =DAAlab!BK15 -> 34 | AC12: =DAAlab!BL15 -> 44 | AD12: =(AB12/AC12)*100 -> 77.272727 | AE12: =AB12+Y12+V12+S12+P12+M12+J12+G12+D12 -> 229 | AF12: =AC12+Z12+W12+T12+Q12+N12+K12+H12+E12 -> 308 | AG12: =(AE12/AF12)*100 -> 74.350649
A13: 10 | B13: 2301260 | C13: Rounit Dhiman | D13: =DM!BK16 -> 34 | E13: =DM!BL16 -> 45 | F13: =(D13/E13)*100 -> 75.555556 | G13: =COA!BK16 -> 26 | H13: =COA!BL16 -> 30 | I13: =(G13/H13)*100 -> 86.666667 | J13: =OS!BK16 -> 28 | K13: =OS!BL16 -> 33 | L13: =(J13/K13)*100 -> 84.848485 | M13: =DAA!BK16 -> 25 | N13: =DAA!BL16 -> 33 | O13: =(M13/N13)*100 -> 75.757576 | P13: ='UHV2'!BK16 -> 22 | Q13: ='UHV2'!BL16 -> 29 | R13: =(P13/Q13)*100 -> 75.862069 | S13: =EVS!BK16 -> 24 | T13: =EVS!BL16 -> 29 | U13: =(S13/T13)*100 -> 82.758621 | V13: =COAlab!BK16 -> 20 | W13: =COAlab!BL16 -> 22 | X13: =(V13/W13)*100 -> 90.909091 | Y13: =OSlab!BK16 -> 38 | Z13: =OSlab!BL16 -> 43 | AA13: =(Y13/Z13)*100 -> 88.372093 | AB13: =DAAlab!BK16 -> 36 | AC13: =DAAlab!BL16 -> 44 | AD13: =(AB13/AC13)*100 -> 81.818182 | AE13: =AB13+Y13+V13+S13+P13+M13+J13+G13+D13 -> 253 | AF13: =AC13+Z13+W13+T13+Q13+N13+K13+H13+E13 -> 308 | AG13: =(AE13/AF13)*100 -> 82.142857
A14: 11 | B14: 2301261 | C14: Rubby Kumari | D14: =DM!BK17 -> 15 | E14: =DM!BL17 -> 45 | F14: =(D14/E14)*100 -> 33.333333 | G14: =COA!BK17 -> 14 | H14: =COA!BL17 -> 30 | I14: =(G14/H14)*100 -> 46.666667 | J14: =OS!BK17 -> 17 | K14: =OS!BL17 -> 33 | L14: =(J14/K14)*100 -> 51.515152 | M14: =DAA!BK17 -> 18 | N14: =DAA!BL17 -> 33 | O14: =(M14/N14)*100 -> 54.545455 | P14: ='UHV2'!BK17 -> 11 | Q14: ='UHV2'!BL17 -> 29 | R14: =(P14/Q14)*100 -> 37.931034 | S14: =EVS!BK17 -> 14 | T14: =EVS!BL17 -> 29 | U14: =(S14/T14)*100 -> 48.275862 | V14: =COAlab!BK17 -> 8 | W14: =COAlab!BL17 -> 22 | X14: =(V14/W14)*100 -> 36.363636 | Y14: =OSlab!BK17 -> 14 | Z14: =OSlab!BL17 -> 43 | AA14: =(Y14/Z14)*100 -> 32.55814 | AB14: =DAAlab!BK17 -> 26 | AC14: =DAAlab!BL17 -> 44 | AD14: =(AB14/AC14)*100 -> 59.090909 | AE14: =AB14+Y14+V14+S14+P14+M14+J14+G14+D14 -> 137 | AF14: =AC14+Z14+W14+T14+Q14+N14+K14+H14+E14 -> 308 | AG14: =(AE14/AF14)*100 -> 44.480519
A15: 12 | B15: 2301262 | C15: Sakshi Devi | D15: =DM!BK18 -> 33 | E15: =DM!BL18 -> 45 | F15: =(D15/E15)*100 -> 73.333333 | G15: =COA!BK18 -> 25 | H15: =COA!BL18 -> 30 | I15: =(G15/H15)*100 -> 83.333333 | J15: =OS!BK18 -> 28 | K15: =OS!BL18 -> 33 | L15: =(J15/K15)*100 -> 84.848485 | M15: =DAA!BK18 -> 25 | N15: =DAA!BL18 -> 33 | O15: =(M15/N15)*100 -> 75.757576 | P15: ='UHV2'!BK18 -> 21 | Q15: ='UHV2'!BL18 -> 29 | R15: =(P15/Q15)*100 -> 72.413793 | S15: =EVS!BK18 -> 25 | T15: =EVS!BL18 -> 29 | U15: =(S15/T15)*100 -> 86.206897 | V15: =COAlab!BK18 -> 20 | W15: =COAlab!BL18 -> 22 | X15: =(V15/W15)*100 -> 90.909091 | Y15: =OSlab!BK18 -> 32 | Z15: =OSlab!BL18 -> 43 | AA15: =(Y15/Z15)*100 -> 74.418605 | AB15: =DAAlab!BK18 -> 32 | AC15: =DAAlab!BL18 -> 44 | AD15: =(AB15/AC15)*100 -> 72.727273 | AE15: =AB15+Y15+V15+S15+P15+M15+J15+G15+D15 -> 241 | AF15: =AC15+Z15+W15+T15+Q15+N15+K15+H15+E15 -> 308 | AG15: =(AE15/AF15)*100 -> 78.246753
... A37: 34 | B37: 2339509 | C37: TOHIED AHMED | D37: =DM!BK40 -> 5 | E37: =DM!BL40 -> 45 | F37: =(D37/E37)*100 -> 11.111111 | G37: =COA!BK40 -> 0 | H37: =COA!BL40 -> 30 | I37: =(G37/H37)*100 -> 0 | J37: =OS!BK40 -> 6 | K37: =OS!BL40 -> 33 | L37: =(J37/K37)*100 -> 18.181818 | M37: =DAA!BK40 -> 3 | N37: =DAA!BL40 -> 33 | O37: =(M37/N37)*100 -> 9.0909091 | P37: ='UHV2'!BK40 -> 1 | Q37: ='UHV2'!BL40 -> 29 | R37: =(P37/Q37)*100 -> 3.4482759 | S37: =EVS!BK40 -> 2 | T37: =EVS!BL40 -> 29 | U37: =(S37/T37)*100 -> 6.8965517 | V37: =COAlab!BK40 -> 0 | W37: =COAlab!BL40 -> 22 | X37: =(V37/W37)*100 -> 0 | Y37: =OSlab!BK40 -> 0 | Z37: =OSlab!BL40 -> 43 | AA37: =(Y37/Z37)*100 -> 0 | AB37: =DAAlab!BK40 -> 2 | AC37: =DAAlab!BL40 -> 44 | AD37: =(AB37/AC37)*100 -> 4.5454545 | AE37: =AB37+Y37+V37+S37+P37+M37+J37+G37+D37 -> 19 | AF37: =AC37+Z37+W37+T37+Q37+N37+K37+H37+E37 -> 308 | AG37: =(AE37/AF37)*100 -> 6.1688312
A38: 35 | B38: Leet | C38: Gagan | D38: =DM!BK41 -> 32 | E38: =DM!BL41 -> 45 | F38: =(D38/E38)*100 -> 71.111111 | G38: =COA!BK41 -> 26 | H38: =COA!BL41 -> 30 | I38: =(G38/H38)*100 -> 86.666667 | J38: =OS!BK41 -> 28 | K38: =OS!BL41 -> 33 | L38: =(J38/K38)*100 -> 84.848485 | M38: =DAA!BK41 -> 29 | N38: =DAA!BL41 -> 33 | O38: =(M38/N38)*100 -> 87.878788 | P38: ='UHV2'!BK41 -> 16 | Q38: ='UHV2'!BL41 -> 29 | R38: =(P38/Q38)*100 -> 55.172414 | S38: =EVS!BK41 -> 26 | T38: =EVS!BL41 -> 29 | U38: =(S38/T38)*100 -> 89.655172 | V38: =COAlab!BK41 -> 22 | W38: =COAlab!BL41 -> 22 | X38: =(V38/W38)*100 -> 100 | Y38: =OSlab!BK41 -> 35 | Z38: =OSlab!BL41 -> 43 | AA38: =(Y38/Z38)*100 -> 81.395349 | AB38: =DAAlab!BK41 -> 34 | AC38: =DAAlab!BL41 -> 44 | AD38: =(AB38/AC38)*100 -> 77.272727 | AE38: =AB38+Y38+V38+S38+P38+M38+J38+G38+D38 -> 248 | AF38: =AC38+Z38+W38+T38+Q38+N38+K38+H38+E38 -> 308 | AG38: =(AE38/AF38)*100 -> 80.519481
A39: 36 | B39: Leet | C39: Manisha | D39: =DM!BK42 -> 39 | E39: =DM!BL42 -> 45 | F39: =(D39/E39)*100 -> 86.666667 | G39: =COA!BK42 -> 28 | H39: =COA!BL42 -> 30 | I39: =(G39/H39)*100 -> 93.333333 | J39: =OS!BK42 -> 29 | K39: =OS!BL42 -> 33 | L39: =(J39/K39)*100 -> 87.878788 | M39: =DAA!BK42 -> 32 | N39: =DAA!BL42 -> 33 | O39: =(M39/N39)*100 -> 96.969697 | P39: ='UHV2'!BK42 -> 22 | Q39: ='UHV2'!BL42 -> 29 | R39: =(P39/Q39)*100 -> 75.862069 | S39: =EVS!BK42 -> 27 | T39: =EVS!BL42 -> 29 | U39: =(S39/T39)*100 -> 93.103448 | V39: =COAlab!BK42 -> 22 | W39: =COAlab!BL42 -> 22 | X39: =(V39/W39)*100 -> 100 | Y39: =OSlab!BK42 -> 37 | Z39: =OSlab!BL42 -> 43 | AA39: =(Y39/Z39)*100 -> 86.046512 | AB39: =DAAlab!BK42 -> 40 | AC39: =DAAlab!BL42 -> 44 | AD39: =(AB39/AC39)*100 -> 90.909091 | AE39: =AB39+Y39+V39+S39+P39+M39+J39+G39+D39 -> 276 | AF39: =AC39+Z39+W39+T39+Q39+N39+K39+H39+E39 -> 308 | AG39: =(AE39/AF39)*100 -> 89.61039
A40: 37 | B40: Leet | C40: Richa | D40: =DM!BK43 -> 31 | E40: =DM!BL43 -> 45 | F40: =(D40/E40)*100 -> 68.888889 | G40: =COA!BK43 -> 27 | H40: =COA!BL43 -> 30 | I40: =(G40/H40)*100 -> 90 | J40: =OS!BK43 -> 29 | K40: =OS!BL43 -> 33 | L40: =(J40/K40)*100 -> 87.878788 | M40: =DAA!BK43 -> 28 | N40: =DAA!BL43 -> 33 | O40: =(M40/N40)*100 -> 84.848485 | P40: ='UHV2'!BK44 -> 20 | Q40: ='UHV2'!BL43 -> 29 | R40: =(P40/Q40)*100 -> 68.965517 | S40: =EVS!BK43 -> 23 | T40: =EVS!BL43 -> 29 | U40: =(S40/T40)*100 -> 79.310345 | V40: =COAlab!BK43 -> 22 | W40: =COAlab!BL43 -> 22 | X40: =(V40/W40)*100 -> 100 | Y40: =OSlab!BK43 -> 27 | Z40: =OSlab!BL43 -> 43 | AA40: =(Y40/Z40)*100 -> 62.790698 | AB40: =DAAlab!BK43 -> 40 | AC40: =DAAlab!BL43 -> 44 | AD40: =(AB40/AC40)*100 -> 90.909091 | AE40: =AB40+Y40+V40+S40+P40+M40+J40+G40+D40 -> 247 | AF40: =AC40+Z40+W40+T40+Q40+N40+K40+H40+E40 -> 308 | AG40: =(AE40/AF40)*100 -> 80.194805
A41: 38 | B41: Leet | C41: Prakriti | D41: =DM!BK44 -> 35 | E41: =DM!BL44 -> 45 | F41: =(D41/E41)*100 -> 77.777778 | G41: =COA!BK44 -> 27 | H41: =COA!BL44 -> 30 | I41: =(G41/H41)*100 -> 90 | J41: =OS!BK44 -> 31 | K41: =OS!BL44 -> 33 | L41: =(J41/K41)*100 -> 93.939394 | M41: =DAA!BK44 -> 31 | N41: =DAA!BL44 -> 33 | O41: =(M41/N41)*100 -> 93.939394 | P41: ='UHV2'!BK44 -> 20 | Q41: ='UHV2'!BL44 -> 29 | R41: =(P41/Q41)*100 -> 68.965517 | S41: =EVS!BK44 -> 24 | T41: =EVS!BL44 -> 29 | U41: =(S41/T41)*100 -> 82.758621 | V41: =COAlab!BK44 -> 18 | W41: =COAlab!BL44 -> 22 | X41: =(V41/W41)*100 -> 81.818182 | Y41: =OSlab!BK44 -> 37 | Z41: =OSlab!BL44 -> 43 | AA41: =(Y41/Z41)*100 -> 86.046512 | AB41: =DAAlab!BK44 -> 38 | AC41: =DAAlab!BL44 -> 44 | AD41: =(AB41/AC41)*100 -> 86.363636 | AE41: =AB41+Y41+V41+S41+P41+M41+J41+G41+D41 -> 261 | AF41: =AC41+Z41+W41+T41+Q41+N41+K41+H41+E41 -> 308 | AG41: =(AE41/AF41)*100 -> 84.74026
A42: 39 | B42: leet | C42: Shubham | D42: =DM!BK45 -> 29 | E42: =DM!BL45 -> 45 | F42: =(D42/E42)*100 -> 64.444444 | G42: =COA!BK45 -> 22 | H42: =COA!BL45 -> 30 | I42: =(G42/H42)*100 -> 73.333333 | J42: =OS!BK45 -> 73 | K42: =OS!BL45 -> 33 | L42: =(J42/K42)*100 -> 221.21212 | M42: =DAA!BK45 -> 25 | N42: =DAA!BL45 -> 33 | O42: =(M42/N42)*100 -> 75.757576 | P42: ='UHV2'!BK45 -> 20 | Q42: ='UHV2'!BL45 -> 29 | R42: =(P42/Q42)*100 -> 68.965517 | S42: =EVS!BK45 -> 24 | T42: =EVS!BL45 -> 29 | U42: =(S42/T42)*100 -> 82.758621 | V42: =COAlab!BK45 -> 16 | W42: =COAlab!BL45 -> 22 | X42: =(V42/W42)*100 -> 72.727273 | Y42: =OSlab!BK45 -> 34 | Z42: =OSlab!BL45 -> 43 | AA42: =(Y42/Z42)*100 -> 79.069767 | AB42: =DAAlab!BK45 -> 32 | AC42: =DAAlab!BL45 -> 44 | AD42: =(AB42/AC42)*100 -> 72.727273 | AE42: =AB42+Y42+V42+S42+P42+M42+J42+G42+D42 -> 275 | AF42: =AC42+Z42+W42+T42+Q42+N42+K42+H42+E42 -> 308 | AG42: =(AE42/AF42)*100 -> 89.285714
A43: 40 | B43: 2301381 | C43: ADITYA | D43: =DM!BK46 -> 35 | E43: =DM!BL46 -> 45 | F43: =(D43/E43)*100 -> 77.777778 | G43: =COA!BK46 -> 29 | H43: =COA!BL46 -> 30 | I43: =(G43/H43)*100 -> 96.666667 | J43: =OS!BK46 -> 33 | K43: =OS!BL46 -> 33 | L43: =(J43/K43)*100 -> 100 | M43: =DAA!BK46 -> 28 | N43: =DAA!BL46 -> 33 | O43: =(M43/N43)*100 -> 84.848485 | P43: ='UHV2'!BK46 -> 26 | Q43: ='UHV2'!BL46 -> 29 | R43: =(P43/Q43)*100 -> 89.655172 | S43: =EVS!BK46 -> 27 | T43: =EVS!BL46 -> 29 | U43: =(S43/T43)*100 -> 93.103448 | V43: =COAlab!BK46 -> 28 | W43: =COAlab!BL46 -> 28 | X43: =(V43/W43)*100 -> 100 | Y43: =OSlab!BK46 -> 36 | Z43: =OSlab!BL46 -> 40 | AA43: =(Y43/Z43)*100 -> 90 | AB43: =DAAlab!BK46 -> 40 | AC43: =DAAlab!BL46 -> 42 | AD43: =(AB43/AC43)*100 -> 95.238095 | AE43: =AB43+Y43+V43+S43+P43+M43+J43+G43+D43 -> 282 | AF43: =AC43+Z43+W43+T43+Q43+N43+K43+H43+E43 -> 309 | AG43: =(AE43/AF43)*100 -> 91.262136
A44: 41 | B44: 2301382 | C44: ANMOL | D44: =DM!BK47 -> 20 | E44: =DM!BL47 -> 45 | F44: =(D44/E44)*100 -> 44.444444 | G44: =COA!BK47 -> 21 | H44: =COA!BL47 -> 30 | I44: =(G44/H44)*100 -> 70 | J44: =OS!BK47 -> 22 | K44: =OS!BL47 -> 33 | L44: =(J44/K44)*100 -> 66.666667 | M44: =DAA!BK47 -> 25 | N44: =DAA!BL47 -> 33 | O44: =(M44/N44)*100 -> 75.757576 | P44: ='UHV2'!BK47 -> 18 | Q44: ='UHV2'!BL47 -> 29 | R44: =(P44/Q44)*100 -> 62.068966 | S44: =EVS!BK47 -> 20 | T44: =EVS!BL47 -> 29 | U44: =(S44/T44)*100 -> 68.965517 | V44: =COAlab!BK47 -> 18 | W44: =COAlab!BL47 -> 28 | X44: =(V44/W44)*100 -> 64.285714 | Y44: =OSlab!BK47 -> 26 | Z44: =OSlab!BL47 -> 40 | AA44: =(Y44/Z44)*100 -> 65 | AB44: =DAAlab!BK47 -> 34 | AC44: =DAAlab!BL47 -> 42 | AD44: =(AB44/AC44)*100 -> 80.952381 | AE44: =AB44+Y44+V44+S44+P44+M44+J44+G44+D44 -> 204 | AF44: =AC44+Z44+W44+T44+Q44+N44+K44+H44+E44 -> 309 | AG44: =(AE44/AF44)*100 -> 66.019417
A45: 42 | B45: 2301383 | C45: AURSH SHARMA | D45: =DM!BK48 -> 34 | E45: =DM!BL48 -> 45 | F45: =(D45/E45)*100 -> 75.555556 | G45: =COA!BK48 -> 23 | H45: =COA!BL48 -> 30 | I45: =(G45/H45)*100 -> 76.666667 | J45: =OS!BK48 -> 25 | K45: =OS!BL48 -> 33 | L45: =(J45/K45)*100 -> 75.757576 | M45: =DAA!BK48 -> 26 | N45: =DAA!BL48 -> 33 | O45: =(M45/N45)*100 -> 78.787879 | P45: ='UHV2'!BK48 -> 21 | Q45: ='UHV2'!BL48 -> 29 | R45: =(P45/Q45)*100 -> 72.413793 | S45: =EVS!BK48 -> 19 | T45: =EVS!BL48 -> 29 | U45: =(S45/T45)*100 -> 65.517241 | V45: =COAlab!BK48 -> 18 | W45: =COAlab!BL48 -> 28 | X45: =(V45/W45)*100 -> 64.285714 | Y45: =OSlab!BK48 -> 26 | Z45: =OSlab!BL48 -> 40 | AA45: =(Y45/Z45)*100 -> 65 | AB45: =DAAlab!BK48 -> 32 | AC45: =DAAlab!BL48 -> 42 | AD45: =(AB45/AC45)*100 -> 76.190476 | AE45: =AB45+Y45+V45+S45+P45+M45+J45+G45+D45 -> 224 | AF45: =AC45+Z45+W45+T45+Q45+N45+K45+H45+E45 -> 309 | AG45: =(AE45/AF45)*100 -> 72.491909
A46: 43 | B46: 2301384 | C46: AVNEET SINGH | D46: =DM!BK49 -> 28 | E46: =DM!BL49 -> 45 | F46: =(D46/E46)*100 -> 62.222222 | G46: =COA!BK49 -> 22 | H46: =COA!BL49 -> 30 | I46: =(G46/H46)*100 -> 73.333333 | J46: =OS!BK49 -> 20 | K46: =OS!BL49 -> 33 | L46: =(J46/K46)*100 -> 60.606061 | M46: =DAA!BK49 -> 23 | N46: =DAA!BL49 -> 33 | O46: =(M46/N46)*100 -> 69.69697 | P46: ='UHV2'!BK49 -> 21 | Q46: ='UHV2'!BL49 -> 29 | R46: =(P46/Q46)*100 -> 72.413793 | S46: =EVS!BK49 -> 18 | T46: =EVS!BL49 -> 29 | U46: =(S46/T46)*100 -> 62.068966 | V46: =COAlab!BK49 -> 16 | W46: =COAlab!BL49 -> 28 | X46: =(V46/W46)*100 -> 57.142857 | Y46: =OSlab!BK49 -> 28 | Z46: =OSlab!BL49 -> 40 | AA46: =(Y46/Z46)*100 -> 70 | AB46: =DAAlab!BK49 -> 30 | AC46: =DAAlab!BL49 -> 42 | AD46: =(AB46/AC46)*100 -> 71.428571 | AE46: =AB46+Y46+V46+S46+P46+M46+J46+G46+D46 -> 206 | AF46: =AC46+Z46+W46+T46+Q46+N46+K46+H46+E46 -> 309 | AG46: =(AE46/AF46)*100 -> 66.666667
A47: 44 | B47: 2301385 | C47: BOBBY | D47: =DM!BK50 -> 26 | E47: =DM!BL50 -> 45 | F47: =(D47/E47)*100 -> 57.777778 | G47: =COA!BK50 -> 23 | H47: =COA!BL50 -> 30 | I47: =(G47/H47)*100 -> 76.666667 | J47: =OS!BK50 -> 25 | K47: =OS!BL50 -> 33 | L47: =(J47/K47)*100 -> 75.757576 | M47: =DAA!BK50 -> 23 | N47: =DAA!BL50 -> 33 | O47: =(M47/N47)*100 -> 69.69697 | P47: ='UHV2'!BK50 -> 25 | Q47: ='UHV2'!BL50 -> 29 | R47: =(P47/Q47)*100 -> 86.206897 | S47: =EVS!BK50 -> 17 | T47: =EVS!BL50 -> 29 | U47: =(S47/T47)*100 -> 58.62069 | V47: =COAlab!BK50 -> 24 | W47: =COAlab!BL50 -> 28 | X47: =(V47/W47)*100 -> 85.714286 | Y47: =OSlab!BK50 -> 30 | Z47: =OSlab!BL50 -> 40 | AA47: =(Y47/Z47)*100 -> 75 | AB47: =DAAlab!BK50 -> 34 | AC47: =DAAlab!BL50 -> 42 | AD47: =(AB47/AC47)*100 -> 80.952381 | AE47: =AB47+Y47+V47+S47+P47+M47+J47+G47+D47 -> 227 | AF47: =AC47+Z47+W47+T47+Q47+N47+K47+H47+E47 -> 309 | AG47: =(AE47/AF47)*100 -> 73.462783
A48: 45 | B48: 2301386 | C48: CHARANJIT SINGH | D48: =DM!BK51 -> 16 | E48: =DM!BL51 -> 45 | F48: =(D48/E48)*100 -> 35.555556 | G48: =COA!BK51 -> 13 | H48: =COA!BL51 -> 30 | I48: =(G48/H48)*100 -> 43.333333 | J48: =OS!BK51 -> 13 | K48: =OS!BL51 -> 33 | L48: =(J48/K48)*100 -> 39.393939 | M48: =DAA!BK51 -> 18 | N48: =DAA!BL51 -> 33 | O48: =(M48/N48)*100 -> 54.545455 | P48: ='UHV2'!BK51 -> 8 | Q48: ='UHV2'!BL51 -> 29 | R48: =(P48/Q48)*100 -> 27.586207 | S48: =EVS!BK51 -> 8 | T48: =EVS!BL51 -> 29 | U48: =(S48/T48)*100 -> 27.586207 | V48: =COAlab!BK51 -> 12 | W48: =COAlab!BL51 -> 28 | X48: =(V48/W48)*100 -> 42.857143 | Y48: =OSlab!BK51 -> 18 | Z48: =OSlab!BL51 -> 40 | AA48: =(Y48/Z48)*100 -> 45 | AB48: =DAAlab!BK51 -> 18 | AC48: =DAAlab!BL51 -> 42 | AD48: =(AB48/AC48)*100 -> 42.857143 | AE48: =AB48+Y48+V48+S48+P48+M48+J48+G48+D48 -> 124 | AF48: =AC48+Z48+W48+T48+Q48+N48+K48+H48+E48 -> 309 | AG48: =(AE48/AF48)*100 -> 40.12945
A49: 46 | B49: 2301387 | C49: INDERBIR SINGH | D49: =DM!BK52 -> 15 | E49: =DM!BL52 -> 45 | F49: =(D49/E49)*100 -> 33.333333 | G49: =COA!BK52 -> 19 | H49: =COA!BL52 -> 30 | I49: =(G49/H49)*100 -> 63.333333 | J49: =OS!BK52 -> 13 | K49: =OS!BL52 -> 33 | L49: =(J49/K49)*100 -> 39.393939 | M49: =DAA!BK52 -> 16 | N49: =DAA!BL52 -> 33 | O49: =(M49/N49)*100 -> 48.484848 | P49: ='UHV2'!BK52 -> 12 | Q49: ='UHV2'!BL52 -> 29 | R49: =(P49/Q49)*100 -> 41.37931 | S49: =EVS!BK52 -> 11 | T49: =EVS!BL52 -> 29 | U49: =(S49/T49)*100 -> 37.931034 | V49: =COAlab!BK52 -> 16 | W49: =COAlab!BL52 -> 28 | X49: =(V49/W49)*100 -> 57.142857 | Y49: =OSlab!BK52 -> 22 | Z49: =OSlab!BL52 -> 40 | AA49: =(Y49/Z49)*100 -> 55 | AB49: =DAAlab!BK52 -> 24 | AC49: =DAAlab!BL52 -> 42 | AD49: =(AB49/AC49)*100 -> 57.142857 | AE49: =AB49+Y49+V49+S49+P49+M49+J49+G49+D49 -> 148 | AF49: =AC49+Z49+W49+T49+Q49+N49+K49+H49+E49 -> 309 | AG49: =(AE49/AF49)*100 -> 47.89644
A50: 47 | B50: 2301389 | C50: JASMEEN | D50: =DM!BK53 -> 27 | E50: =DM!BL53 -> 45 | F50: =(D50/E50)*100 -> 60 | G50: =COA!BK53 -> 14 | H50: =COA!BL53 -> 30 | I50: =(G50/H50)*100 -> 46.666667 | J50: =OS!BK53 -> 19 | K50: =OS!BL53 -> 33 | L50: =(J50/K50)*100 -> 57.575758 | M50: =DAA!BK53 -> 24 | N50: =DAA!BL53 -> 33 | O50: =(M50/N50)*100 -> 72.727273 | P50: ='UHV2'!BK53 -> 12 | Q50: ='UHV2'!BL53 -> 29 | R50: =(P50/Q50)*100 -> 41.37931 | S50: =EVS!BK53 -> 14 | T50: =EVS!BL53 -> 29 | U50: =(S50/T50)*100 -> 48.275862 | V50: =COAlab!BK53 -> 20 | W50: =COAlab!BL53 -> 28 | X50: =(V50/W50)*100 -> 71.428571 | Y50: =OSlab!BK53 -> 20 | Z50: =OSlab!BL53 -> 40 | AA50: =(Y50/Z50)*100 -> 50 | AB50: =DAAlab!BK53 -> 32 | AC50: =DAAlab!BL53 -> 42 | AD50: =(AB50/AC50)*100 -> 76.190476 | AE50: =AB50+Y50+V50+S50+P50+M50+J50+G50+D50 -> 182 | AF50: =AC50+Z50+W50+T50+Q50+N50+K50+H50+E50 -> 309 | AG50: =(AE50/AF50)*100 -> 58.899676
A51: 48 | B51: 2301390 | C51: KUNDAN | D51: =DM!BK54 -> 30 | E51: =DM!BL54 -> 45 | F51: =(D51/E51)*100 -> 66.666667 | G51: =COA!BK54 -> 28 | H51: =COA!BL54 -> 30 | I51: =(G51/H51)*100 -> 93.333333 | J51: =OS!BK54 -> 23 | K51: =OS!BL54 -> 33 | L51: =(J51/K51)*100 -> 69.69697 | M51: =DAA!BK54 -> 23 | N51: =DAA!BL54 -> 33 | O51: =(M51/N51)*100 -> 69.69697 | P51: ='UHV2'!BK54 -> 21 | Q51: ='UHV2'!BL54 -> 29 | R51: =(P51/Q51)*100 -> 72.413793 | S51: =EVS!BK54 -> 26 | T51: =EVS!BL54 -> 29 | U51: =(S51/T51)*100 -> 89.655172 | V51: =COAlab!BK54 -> 20 | W51: =COAlab!BL54 -> 28 | X51: =(V51/W51)*100 -> 71.428571 | Y51: =OSlab!BK54 -> 36 | Z51: =OSlab!BL54 -> 40 | AA51: =(Y51/Z51)*100 -> 90 | AB51: =DAAlab!BK54 -> 30 | AC51: =DAAlab!BL54 -> 42 | AD51: =(AB51/AC51)*100 -> 71.428571 | AE51: =AB51+Y51+V51+S51+P51+M51+J51+G51+D51 -> 237 | AF51: =AC51+Z51+W51+T51+Q51+N51+K51+H51+E51 -> 309 | AG51: =(AE51/AF51)*100 -> 76.699029
A52: 49 | B52: 2301391 | C52: MANVEER SINGH | D52: =DM!BK55 -> 33 | E52: =DM!BL55 -> 45 | F52: =(D52/E52)*100 -> 73.333333 | G52: =COA!BK55 -> 22 | H52: =COA!BL55 -> 30 | I52: =(G52/H52)*100 -> 73.333333 | J52: =OS!BK55 -> 25 | K52: =OS!BL55 -> 33 | L52: =(J52/K52)*100 -> 75.757576 | M52: =DAA!BK55 -> 26 | N52: =DAA!BL55 -> 33 | O52: =(M52/N52)*100 -> 78.787879 | P52: ='UHV2'!BK55 -> 17 | Q52: ='UHV2'!BL55 -> 29 | R52: =(P52/Q52)*100 -> 58.62069 | S52: =EVS!BK55 -> 20 | T52: =EVS!BL55 -> 29 | U52: =(S52/T52)*100 -> 68.965517 | V52: =COAlab!BK55 -> 26 | W52: =COAlab!BL55 -> 28 | X52: =(V52/W52)*100 -> 92.857143 | Y52: =OSlab!BK55 -> 26 | Z52: =OSlab!BL55 -> 40 | AA52: =(Y52/Z52)*100 -> 65 | AB52: =DAAlab!BK55 -> 28 | AC52: =DAAlab!BL55 -> 42 | AD52: =(AB52/AC52)*100 -> 66.666667 | AE52: =AB52+Y52+V52+S52+P52+M52+J52+G52+D52 -> 223 | AF52: =AC52+Z52+W52+T52+Q52+N52+K52+H52+E52 -> 309 | AG52: =(AE52/AF52)*100 -> 72.168285
A53: 50 | B53: 2301392 | C53: MOHIT KUMAR | D53: =DM!BK56 -> 26 | E53: =DM!BL56 -> 45 | F53: =(D53/E53)*100 -> 57.777778 | G53: =COA!BK56 -> 19 | H53: =COA!BL56 -> 30 | I53: =(G53/H53)*100 -> 63.333333 | J53: =OS!BK56 -> 19 | K53: =OS!BL56 -> 33 | L53: =(J53/K53)*100 -> 57.575758 | M53: =DAA!BK56 -> 26 | N53: =DAA!BL56 -> 33 | O53: =(M53/N53)*100 -> 78.787879 | P53: ='UHV2'!BK56 -> 17 | Q53: ='UHV2'!BL56 -> 29 | R53: =(P53/Q53)*100 -> 58.62069 | S53: =EVS!BK56 -> 16 | T53: =EVS!BL56 -> 29 | U53: =(S53/T53)*100 -> 55.172414 | V53: =COAlab!BK56 -> 12 | W53: =COAlab!BL56 -> 28 | X53: =(V53/W53)*100 -> 42.857143 | Y53: =OSlab!BK56 -> 16 | Z53: =OSlab!BL56 -> 40 | AA53: =(Y53/Z53)*100 -> 40 | AB53: =DAAlab!BK56 -> 20 | AC53: =DAAlab!BL56 -> 42 | AD53: =(AB53/AC53)*100 -> 47.619048 | AE53: =AB53+Y53+V53+S53+P53+M53+J53+G53+D53 -> 171 | AF53: =AC53+Z53+W53+T53+Q53+N53+K53+H53+E53 -> 309 | AG53: =(AE53/AF53)*100 -> 55.339806
A54: 51 | B54: 2301393 | C54: NAVNEET | D54: =DM!BK57 -> 16 | E54: =DM!BL57 -> 45 | F54: =(D54/E54)*100 -> 35.555556 | G54: =COA!BK57 -> 13 | H54: =COA!BL57 -> 30 | I54: =(G54/H54)*100 -> 43.333333 | J54: =OS!BK57 -> 11 | K54: =OS!BL57 -> 33 | L54: =(J54/K54)*100 -> 33.333333 | M54: =DAA!BK57 -> 15 | N54: =DAA!BL57 -> 33 | O54: =(M54/N54)*100 -> 45.454545 | P54: ='UHV2'!BK57 -> 11 | Q54: ='UHV2'!BL57 -> 29 | R54: =(P54/Q54)*100 -> 37.931034 | S54: =EVS!BK57 -> 3 | T54: =EVS!BL57 -> 29 | U54: =(S54/T54)*100 -> 10.344828 | V54: =COAlab!BK57 -> 10 | W54: =COAlab!BL57 -> 28 | X54: =(V54/W54)*100 -> 35.714286 | Y54: =OSlab!BK57 -> 10 | Z54: =OSlab!BL57 -> 40 | AA54: =(Y54/Z54)*100 -> 25 | AB54: =DAAlab!BK57 -> 16 | AC54: =DAAlab!BL57 -> 42 | AD54: =(AB54/AC54)*100 -> 38.095238 | AE54: =AB54+Y54+V54+S54+P54+M54+J54+G54+D54 -> 105 | AF54: =AC54+Z54+W54+T54+Q54+N54+K54+H54+E54 -> 309 | AG54: =(AE54/AF54)*100 -> 33.980583
... A73: 70 | B73: 2322673 | C73: USMAN ALI | D73: =DM!BK76 -> 22 | E73: =DM!BL76 -> 45 | F73: =(D73/E73)*100 -> 48.888889 | G73: =COA!BK76 -> 17 | H73: =COA!BL76 -> 30 | I73: =(G73/H73)*100 -> 56.666667 | J73: =OS!BK76 -> 19 | K73: =OS!BL76 -> 33 | L73: =(J73/K73)*100 -> 57.575758 | M73: =DAA!BK76 -> 22 | N73: =DAA!BL76 -> 33 | O73: =(M73/N73)*100 -> 66.666667 | P73: ='UHV2'!BK76 -> 16 | Q73: ='UHV2'!BL76 -> 29 | R73: =(P73/Q73)*100 -> 55.172414 | S73: =EVS!BK76 -> 12 | T73: =EVS!BL76 -> 29 | U73: =(S73/T73)*100 -> 41.37931 | V73: =COAlab!BK76 -> 20 | W73: =COAlab!BL76 -> 28 | X73: =(V73/W73)*100 -> 71.428571 | Y73: =OSlab!BK76 -> 20 | Z73: =OSlab!BL76 -> 40 | AA73: =(Y73/Z73)*100 -> 50 | AB73: =DAAlab!BK76 -> 30 | AC73: =DAAlab!BL76 -> 42 | AD73: =(AB73/AC73)*100 -> 71.428571 | AE73: =AB73+Y73+V73+S73+P73+M73+J73+G73+D73 -> 178 | AF73: =AC73+Z73+W73+T73+Q73+N73+K73+H73+E73 -> 309 | AG73: =(AE73/AF73)*100 -> 57.605178

Sheet INTERNAL
A1: =OVERALL!A1 -> ATTENDANCE RECORD JAN-JUNE 2025 (B.Tech CSE 4B)
A2: S.No. | B2: Reg No. | C2: Name of Student | D2: DM | E2: COA | F2: OS | G2: DAA | H2: UHV2 | I2: EVS | J2: COA LAB | K2: OS LAB | L2: DAA LAB
A3: 1 | B3: =OVERALL!B4 -> 2301249 | C3: =OVERALL!C4 -> Rahul Sharma | D3: =DM!BW7 -> 16.666667 | E3: =COA!BW7 -> 25.5 | F3: =OS!BW7 -> 20.833333 | G3: =DAA!BW7 -> 26.166667 | H3: ='UHV2'!BW7 -> 21.166667 | I3: =EVS!BW7 -> 27.75 | J3: =COAlab!BS7 -> 16.3125 | K3: =OSlab!BS7 -> 17.5 | L3: =DAAlab!BS7 -> 20.2
A4: 2 | B4: =OVERALL!B5 -> 2301251 | C4: =OVERALL!C5 -> Raj Kumar | D4: =DM!BW8 -> 16 | E4: =COA!BW8 -> 20 | F4: =OS!BW8 -> 15.166667 | G4: =DAA!BW8 -> 18.833333 | H4: ='UHV2'!BW8 -> 13.333333 | I4: =EVS!BW8 -> 16.583333 | J4: =COAlab!BS8 -> 15.625 | K4: =OSlab!BS8 -> 21.833333 | L4: =DAAlab!BS8 -> 20.3
A5: 3 | B5: =OVERALL!B6 -> 2301252 | C5: =OVERALL!C6 -> Rajan Sharma | D5: =DM!BW9 -> 22.333333 | E5: =COA!BW9 -> 18.833333 | F5: =OS!BW9 -> 24.666667 | G5: =DAA!BW9 -> 17.833333 | H5: ='UHV2'!BW9 -> 20.166667 | I5: =EVS!BW9 -> 23.083333 | J5: =COAlab!BS9 -> 18.75 | K5: =OSlab!BS9 -> 21.333333 | L5: =DAAlab!BS9 -> 18.2
A6: 4 | B6: =OVERALL!B7 -> 2301253 | C6: =OVERALL!C7 -> Rajwinder Kaur | D6: =DM!BW10 -> 27.166667 | E6: =COA!BW10 -> 32.833333 | F6: =OS!BW10 -> 22.5 | G6: =DAA!BW10 -> 30.333333 | H6: ='UHV2'!BW10 -> 21.666667 | I6: =EVS!BW10 -> 33.666667 | J6: =COAlab!BS10 -> 22.833333 | K6: =OSlab!BS10 -> 20.666667 | L6: =DAAlab!BS10 -> 24.5
A7: 5 | B7: =OVERALL!B8 -> 2301255 | C7: =OVERALL!C8 -> Ravi Bhushan Kumar | D7: =DM!BW11 -> 30 | E7: =COA!BW11 -> 36.166667 | F7: =OS!BW11 -> 23.333333 | G7: =DAA!BW11 -> 34.833333 | H7: ='UHV2'!BW11 -> 24.666667 | I7: =EVS!BW11 -> 33.583333 | J7: =COAlab!BS11 -> 27.020833 | K7: =OSlab!BS11 -> 26.166667 | L7: =DAAlab!BS11 -> 26.7
A8: 6 | B8: =OVERALL!B9 -> 2301256 | C8: =OVERALL!C9 -> Reshma | D8: =DM!BW12 -> 26.666667 | E8: =COA!BW12 -> 32.5 | F8: =OS!BW12 -> 27 | G8: =DAA!BW12 -> 26.666667 | H8: ='UHV2'!BW12 -> 23.5 | I8: =EVS!BW12 -> 28.583333 | J8: =COAlab!BS12 -> 26.854167 | K8: =OSlab!BS12 -> 22.833333 | L8: =DAAlab!BS12 -> 20.9
A9: 7 | B9: =OVERALL!B10 -> 2301257 | C9: =OVERALL!C10 -> Ritesh Kumar Choudhary | D9: =DM!BW13 -> 23 | E9: =COA!BW13 -> 21.5 | F9: =OS!BW13 -> 26.333333 | G9: =DAA!BW13 -> 32.166667 | H9: ='UHV2'!BW13 -> 20.5 | I9: =EVS!BW13 -> 23.75 | J9: =COAlab!BS13 -> 14.020833 | K9: =OSlab!BS13 -> 18.833333 | L9: =DAAlab!BS13 -> 16.3
A10: 8 | B10: =OVERALL!B11 -> 2301258 | C10: =OVERALL!C11 -> Ritesh Thakur | D10: =DM!BW14 -> 11.5 | E10: =COA!BW14 -> 8.5 | F10: =OS!BW14 -> 13.166667 | G10: =DAA!BW14 -> 7.8333333 | H10: ='UHV2'!BW14 -> 10.333333 | I10: =EVS!BW14 -> 6.75 | J10: =COAlab!BS14 -> 0 | K10: =OSlab!BS14 -> 0 | L10: =DAAlab!BS14 -> 3.4
A11: 9 | B11: =OVERALL!B12 -> 2301259 | C11: =OVERALL!C12 -> Riya Thakur | D11: =DM!BW15 -> 24.5 | E11: =COA!BW15 -> 33.166667 | F11: =OS!BW15 -> 21.166667 | G11: =DAA!BW15 -> 25.833333 | H11: ='UHV2'!BW15 -> 19 | I11: =EVS!BW15 -> 26.666667 | J11: =COAlab!BS15 -> 26.6875 | K11: =OSlab!BS15 -> 19.166667 | L11: =DAAlab!BS15 -> 22.1
A12: 10 | B12: =OVERALL!B13 -> 2301260 | C12: =OVERALL!C13 -> Rounit Dhiman | D12: =DM!BW16 -> 28.166667 | E12: =COA!BW16 -> 29.5 | F12: =OS!BW16 -> 26.166667 | G12: =DAA!BW16 -> 21.333333 | H12: ='UHV2'!BW16 -> 20 | I12: =EVS!BW16 -> 28.083333 | J12: =COAlab!BS16 -> 23.125 | K12: =OSlab!BS16 -> 23 | L12: =DAAlab!BS16 -> 20.5
A13: 11 | B13: =OVERALL!B14 -> 2301261 | C13: =OVERALL!C14 -> Rubby Kumari | D13: =DM!BW17 -> 7.1666667 | E13: =COA!BW17 -> 17.333333 | F13: =OS!BW17 -> 18.166667 | G13: =DAA!BW17 -> 12.833333 | H13: ='UHV2'!BW17 -> 14.666667 | I13: =EVS!BW17 -> 18.583333 | J13: =COAlab!BS17 -> 15.5 | K13: =OSlab!BS17 -> 11 | L13: =DAAlab!BS17 -> 15.4
A14: 12 | B14: =OVERALL!B15 -> 2301262 | C14: =OVERALL!C15 -> Sakshi Devi | D14: =DM!BW18 -> 14.166667 | E14: =COA!BW18 -> 20.666667 | F14: =OS!BW18 -> 15.333333 | G14: =DAA!BW18 -> 17.166667 | H14: ='UHV2'!BW18 -> 17.666667 | I14: =EVS!BW18 -> 27.833333 | J14: =COAlab!BS18 -> 21.1875 | K14: =OSlab!BS18 -> 19 | L14: =DAAlab!BS18 -> 20.8
... A72: 70 | B72: =OVERALL!B73 -> 2322673 | C72: =OVERALL!C73 -> USMAN ALI | D72: =DM!BW76 -> 17.5 | E72: =COA!BW76 -> 18.5 | F72: =OS!BW76 -> 18.166667 | G72: =DAA!BW76 -> 15.5 | H72: ='UHV2'!BW76 -> 13.166667 | I72: =EVS!BW76 -> 24.5 | J72: =COAlab!BS76 -> 16.645833 | K72: =OSlab!BS76 -> 18 | L72: =DAAlab!BS76 -> 17.545455
A73: HIGHEST MARKS | D73: =MAX(D3:D72) -> 36.333333 | E73: =MAX(E3:E72) -> 36.333333 | F73: =MAX(F3:F72) -> 32.833333 | G73: =MAX(G3:G72) -> 36.333333 | H73: =MAX(H3:H72) -> 35.5 | I73: =MAX(I3:I72) -> 37.25 | J73: =MAX(J3:J72) -> 27.083333 | K73: =MAX(K3:K72) -> 26.833333 | L73: =MAX(L3:L72) -> 27.2
A74: LOWEST MARKS | D74: =MIN(D3:D72) -> 0 | E74: =MIN(E3:E72) -> 0 | F74: =MIN(F3:F72) -> 0 | G74: =MIN(G3:G72) -> 0 | H74: =MIN(H3:H72) -> 0 | I74: =MIN(I3:I72) -> 0 | J74: =MIN(J3:J72) -> 0 | K74: =MIN(K3:K72) -> 0 | L74: =MIN(L3:L72) -> 0
A75: AVG INTERNAL | D75: =AVERAGE(D3:D72) -> 19.140476 | E75: =AVERAGE(E3:E72) -> 25.507143 | F75: =AVERAGE(F3:F72) -> 20.195238 | G75: =AVERAGE(G3:G72) -> 22.683333 | H75: =AVERAGE(H3:H72) -> 20.77381 | I75: =AVERAGE(I3:I72) -> 24.94881 | J75: =AVERAGE(J3:J72) -> 19.577679 | K75: =AVERAGE(K3:K72) -> 18.764286 | L75: =AVERAGE(L3:L72) -> 19.470606
A76: NAME OF SUBJECT INCHARGE | D76: Ms. Ritika Agnihotri | E76: =COA!A4 -> Mr. Sukhdayal Dhanday | F76: =OS!A4 -> Dr. Sandeep Ranjan | G76: =DAA!A4 -> Ms. Monika Gharu | H76: ='UHV2'!A4 -> Ms. Simranjit | I76: =EVS!A4 -> Ms. Simranjit Kaur | J76: =COAlab!A4 -> Mr. Sukhdayal Dhanday | K76: =OSlab!A4 -> Ms. Shaveta, Ms. Ranjana | L76: =DAA!A4 -> Ms. Monika Gharu

Sheet DAA
A1: =OVERALL!A1 -> ATTENDANCE RECORD JAN-JUNE 2025 (B.Tech CSE 4B) | BH1: CTIEMT : Evaluation Sheet for Internal Awards (Theory)
BH2: Session: JAN TO JUNE 2025
BH3: Department: CSE | BP3: Semester: B.TECH 4B
A4: Ms. Monika Gharu | BH4: Subject Name: Design and Analysis of Algorithms | BP4: Subject Code: BTCS 403-18
A5: DATE | BB5: PRESENT | BC5: DL (IF ANY) | BD5: Total Attended | BE5: Total Delievered | BF5: PERCENTAGE | BH5: S.No. | BI5: Reg No. | BJ5: Name of Student | BK5: Total Lec Att | BL5: Total Lec Del | BM5: Att %age | BN5: Att Marks (6) | BO5: MST I (24) | BP5: MST II (24) | BQ5: Average MST I & II (24) | BR5: Assignments | BU5: Assignments AVG (10) | BV5: Marathon | BW5: Grand Total (40)
A6: S.No. | B6: Reg No. | C6: Name of Student | D6: 1 | E6: 2 | F6: 3 | G6: 4 | H6: 5 | I6: 6 | J6: 7 | K6: 8 | L6: 9 | M6: 10 | N6: 11 | O6: 12 | P6: 13 | Q6: 14 | R6: 15 | S6: 16 | T6: 17 | U6: 18 | V6: 19 | W6: 20 | X6: 21 | Y6: 22 | Z6: 23 | AA6: 24 | AB6: 25 | AC6: 26 | AD6: 27 | AE6: 28 | AF6: 29 | AG6: 30 | AH6: 31 | AI6: 32 | AJ6: 33 | AK6: 34 | AL6: 35 | AM6: 36 | AN6: 37 | AO6: 38 | AP6: 39 | AQ6: 40 | AR6: 41 | AS6: 42 | AT6: 43 | AU6: 44 | AV6: 45 | AW6: 46 | AX6: 47 | AY6: 48 | AZ6: 49 | BA6: 50 | BR6: 1 | BS6: 2 | BT6: 3
A7: 1 | B7: =OVERALL!B4 -> 2301249 | C7: =OVERALL!C4 -> Rahul Sharma | BB7: 29 | BC7: 1 | BD7: =BB7+BC7 -> 30 | BE7: 33 | BF7: =(BD7/BE7)*100 -> 90.909091 | BH7: 1 | BI7: =OVERALL!B4 -> 2301249 | BJ7: =OVERALL!C4 -> Rahul Sharma | BK7: =BD7 -> 30 | BL7: =BE7 -> 33 | BM7: =(BK7/BL7)*100 -> 90.909091 | BN7: =IF(BM7>=95.5,"6",IF(BM7>=90.5,"5", IF(BM7>=85.5,"4",IF(BM7>=80.5,"3",IF(BM7>=75.5,"2","0"))))) -> 5 | BO7: 6 | BP7: 11 | BQ7: =ROUND((BO7+BP7)/2, 2) -> 8.5 | BR7: 8 | BS7: 8 | BT7: 7 | BU7: =(BT7+BS7+BR7)/3 -> 7.6666667 | BV7: 5 | BW7: =BV7+BU7+BQ7+BN7 -> 26.166667
A8: 2 | B8: =OVERALL!B5 -> 2301251 | C8: =OVERALL!C5 -> Raj Kumar | BB8: 21 | BD8: =BB8+BC8 -> 21 | BE8: 33 | BF8: =(BD8/BE8)*100 -> 63.636364 | BH8: 2 | BI8: =OVERALL!B5 -> 2301251 | BJ8: =OVERALL!C5 -> Raj Kumar | BK8: =BD8 -> 21 | BL8: =BE8 -> 33 | BM8: =(BK8/BL8)*100 -> 63.636364 | BN8: =IF(BM8>=95.5,"6",IF(BM8>=90.5,"5", IF(BM8>=85.5,"4",IF(BM8>=80.5,"3",IF(BM8>=75.5,"2","0"))))) -> 0 | BO8: 11 | BP8: 10 | BQ8: =ROUND((BO8+BP8)/2, 2) -> 10.5 | BR8: 8 | BS8: 8 | BT8: 9 | BU8: =(BT8+BS8+BR8)/3 -> 8.3333333 | BW8: =BV8+BU8+BQ8+BN8 -> 18.833333
A9: 3 | B9: =OVERALL!B6 -> 2301252 | C9: =OVERALL!C6 -> Rajan Sharma | BB9: 22 | BD9: =BB9+BC9 -> 22 | BE9: 33 | BF9: =(BD9/BE9)*100 -> 66.666667 | BH9: 3 | BI9: =OVERALL!B6 -> 2301252 | BJ9: =OVERALL!C6 -> Rajan Sharma | BK9: =BD9 -> 22 | BL9: =BE9 -> 33 | BM9: =(BK9/BL9)*100 -> 66.666667 | BN9: =IF(BM9>=95.5,"6",IF(BM9>=90.5,"5", IF(BM9>=85.5,"4",IF(BM9>=80.5,"3",IF(BM9>=75.5,"2","0"))))) -> 0 | BO9: 3 | BP9: 16 | BQ9: =ROUND((BO9+BP9)/2, 2) -> 9.5 | BR9: 8 | BS9: 8 | BT9: 9 | BU9: =(BT9+BS9+BR9)/3 -> 8.3333333 | BW9: =BV9+BU9+BQ9+BN9 -> 17.833333
A10: 4 | B10: =OVERALL!B7 -> 2301253 | C10: =OVERALL!C7 -> Rajwinder Kaur | BB10: 25 | BC10: 1 | BD10: =BB10+BC10 -> 26 | BE10: 33 | BF10: =(BD10/BE10)*100 -> 78.787879 | BH10: 4 | BI10: =OVERALL!B7 -> 2301253 | BJ10: =OVERALL!C7 -> Rajwinder Kaur | BK10: =BD10 -> 26 | BL10: =BE10 -> 33 | BM10: =(BK10/BL10)*100 -> 78.787879 | BN10: =IF(BM10>=95.5,"6",IF(BM10>=90.5,"5", IF(BM10>=85.5,"4",IF(BM10>=80.5,"3",IF(BM10>=75.5,"2","0"))))) -> 2 | BO10: 18 | BP10: 22 | BQ10: =ROUND((BO10+BP10)/2, 2) -> 20 | BR10: 8 | BS10: 8 | BT10: 9 | BU10: =(BT10+BS10+BR10)/3 -> 8.3333333 | BW10: =BV10+BU10+BQ10+BN10 -> 30.333333
A11: 5 | B11: =OVERALL!B8 -> 2301255 | C11: =OVERALL!C8 -> Ravi Bhushan Kumar | BB11: 27 | BD11: =BB11+BC11 -> 27 | BE11: 33 | BF11: =(BD11/BE11)*100 -> 81.818182 | BH11: 5 | BI11: =OVERALL!B8 -> 2301255 | BJ11: =OVERALL!C8 -> Ravi Bhushan Kumar | BK11: =BD11 -> 27 | BL11: =BE11 -> 33 | BM11: =(BK11/BL11)*100 -> 81.818182 | BN11: =IF(BM11>=95.5,"6",IF(BM11>=90.5,"5", IF(BM11>=85.5,"4",IF(BM11>=80.5,"3",IF(BM11>=75.5,"2","0"))))) -> 3 | BO11: 18 | BP11: 17 | BQ11: =ROUND((BO11+BP11)/2, 2) -> 17.5 | BR11: 9 | BS11: 9 | BT11: 10 | BU11: =(BT11+BS11+BR11)/3 -> 9.3333333 | BV11: 5 | BW11: =BV11+BU11+BQ11+BN11 -> 34.833333
A12: 6 | B12: =OVERALL!B9 -> 2301256 | C12: =OVERALL!C9 -> Reshma | BB12: 31 | BD12: =BB12+BC12 -> 31 | BE12: 33 | BF12: =(BD12/BE12)*100 -> 93.939394 | BH12: 6 | BI12: =OVERALL!B9 -> 2301256 | BJ12: =OVERALL!C9 -> Reshma | BK12: =BD12 -> 31 | BL12: =BE12 -> 33 | BM12: =(BK12/BL12)*100 -> 93.939394 | BN12: =IF(BM12>=95.5,"6",IF(BM12>=90.5,"5", IF(BM12>=85.5,"4",IF(BM12>=80.5,"3",IF(BM12>=75.5,"2","0"))))) -> 5 | BO12: 11 | BP12: 17 | BQ12: =ROUND((BO12+BP12)/2, 2) -> 14 | BR12: 7 | BS12: 8 | BT12: 8 | BU12: =(BT12+BS12+BR12)/3 -> 7.6666667 | BW12: =BV12+BU12+BQ12+BN12 -> 26.666667
A13: 7 | B13: =OVERALL!B10 -> 2301257 | C13: =OVERALL!C10 -> Ritesh Kumar Choudhary | BB13: 25 | BC13: 5 | BD13: =BB13+BC13 -> 30 | BE13: 33 | BF13: =(BD13/BE13)*100 -> 90.909091 | BH13: 7 | BI13: =OVERALL!B10 -> 2301257 | BJ13: =OVERALL!C10 -> Ritesh Kumar Choudhary | BK13: =BD13 -> 30 | BL13: =BE13 -> 33 | BM13: =(BK13/BL13)*100 -> 90.909091 | BN13: =IF(BM13>=95.5,"6",IF(BM13>=90.5,"5", IF(BM13>=85.5,"4",IF(BM13>=80.5,"3",IF(BM13>=75.5,"2","0"))))) -> 5 | BO13: 10 | BP13: 17 | BQ13: =ROUND((BO13+BP13)/2, 2) -> 13.5 | BR13: 8 | BS13: 9 | BT13: 9 | BU13: =(BT13+BS13+BR13)/3 -> 8.6666667 | BV13: 5 | BW13: =BV13+BU13+BQ13+BN13 -> 32.166667
A14: 8 | B14: =OVERALL!B11 -> 2301258 | C14: =OVERALL!C11 -> Ritesh Thakur | BB14: 2 | BC14: 2 | BD14: =BB14+BC14 -> 4 | BE14: 33 | BF14: =(BD14/BE14)*100 -> 12.121212 | BH14: 8 | BI14: =OVERALL!B11 -> 2301258 | BJ14: =OVERALL!C11 -> Ritesh Thakur | BK14: =BD14 -> 4 | BL14: =BE14 -> 33 | BM14: =(BK14/BL14)*100 -> 12.121212 | BN14: =IF(BM14>=95.5,"6",IF(BM14>=90.5,"5", IF(BM14>=85.5,"4",IF(BM14>=80.5,"3",IF(BM14>=75.5,"2","0"))))) -> 0 | BO14: 0 | BP14: 11 | BQ14: =ROUND((BO14+BP14)/2, 2) -> 5.5 | BR14: 7 | BS14: 0 | BT14: 0 | BU14: =(BT14+BS14+BR14)/3 -> 2.3333333 | BW14: =BV14+BU14+BQ14+BN14 -> 7.8333333
A15: 9 | B15: =OVERALL!B12 -> 2301259 | C15: =OVERALL!C12 -> Riya Thakur | BB15: 26 | BD15: =BB15+BC15 -> 26 | BE15: 33 | BF15: =(BD15/BE15)*100 -> 78.787879 | BH15: 9 | BI15: =OVERALL!B12 -> 2301259 | BJ15: =OVERALL!C12 -> Riya Thakur | BK15: =BD15 -> 26 | BL15: =BE15 -> 33 | BM15: =(BK15/BL15)*100 -> 78.787879 | BN15: =IF(BM15>=95.5,"6",IF(BM15>=90.5,"5", IF(BM15>=85.5,"4",IF(BM15>=80.5,"3",IF(BM15>=75.5,"2","0"))))) -> 2 | BO15: 15 | BP15: 16 | BQ15: =ROUND((BO15+BP15)/2, 2) -> 15.5 | BR15: 8 | BS15: 8 | BT15: 9 | BU15: =(BT15+BS15+BR15)/3 -> 8.3333333 | BW15: =BV15+BU15+BQ15+BN15 -> 25.833333
A16: 10 | B16: =OVERALL!B13 -> 2301260 | C16: =OVERALL!C13 -> Rounit Dhiman | BB16: 25 | BD16: =BB16+BC16 -> 25 | BE16: 33 | BF16: =(BD16/BE16)*100 -> 75.757576 | BH16: 10 | BI16: =OVERALL!B13 -> 2301260 | BJ16: =OVERALL!C13 -> Rounit Dhiman | BK16: =BD16 -> 25 | BL16: =BE16 -> 33 | BM16: =(BK16/BL16)*100 -> 75.757576 | BN16: =IF(BM16>=95.5,"6",IF(BM16>=90.5,"5", IF(BM16>=85.5,"4",IF(BM16>=80.5,"3",IF(BM16>=75.5,"2","0"))))) -> 2 | BO16: 1 | BP16: 11 | BQ16: =ROUND((BO16+BP16)/2, 2) -> 6 | BR16: 8 | BS16: 8 | BT16: 9 | BU16: =(BT16+BS16+BR16)/3 -> 8.3333333 | BV16: 5 | BW16: =BV16+BU16+BQ16+BN16 -> 21.333333
A17: 11 | B17: =OVERALL!B14 -> 2301261 | C17: =OVERALL!C14 -> Rubby Kumari | BB17: 18 | BD17: =BB17+BC17 -> 18 | BE17: 33 | BF17: =(BD17/BE17)*100 -> 54.545455 | BH17: 11 | BI17: =OVERALL!B14 -> 2301261 | BJ17: =OVERALL!C14 -> Rubby Kumari | BK17: =BD17 -> 18 | BL17: =BE17 -> 33 | BM17: =(BK17/BL17)*100 -> 54.545455 | BN17: =IF(BM17>=95.5,"6",IF(BM17>=90.5,"5", IF(BM17>=85.5,"4",IF(BM17>=80.5,"3",IF(BM17>=75.5,"2","0"))))) -> 0 | BO17: 5 | BP17: 10 | BQ17: =ROUND((BO17+BP17)/2, 2) -> 7.5 | BR17: 9 | BS17: 7 | BT17: 0 | BU17: =(BT17+BS17+BR17)/3 -> 5.3333333 | BW17: =BV17+BU17+BQ17+BN17 -> 12.833333
A18: 12 | B18: =OVERALL!B15 -> 2301262 | C18: =OVERALL!C15 -> Sakshi Devi | BB18: 25 | BD18: =BB18+BC18 -> 25 | BE18: 33 | BF18: =(BD18/BE18)*100 -> 75.757576 | BH18: 12 | BI18: =OVERALL!B15 -> 2301262 | BJ18: =OVERALL!C15 -> Sakshi Devi | BK18: =BD18 -> 25 | BL18: =BE18 -> 33 | BM18: =(BK18/BL18)*100 -> 75.757576 | BN18: =IF(BM18>=95.5,"6",IF(BM18>=90.5,"5", IF(BM18>=85.5,"4",IF(BM18>=80.5,"3",IF(BM18>=75.5,"2","0"))))) -> 2 | BO18: 0 | BP18: 15 | BQ18: =ROUND((BO18+BP18)/2, 2) -> 7.5 | BR18: 7 | BS18: 7 | BT18: 9 | BU18: =(BT18+BS18+BR18)/3 -> 7.6666667 | BW18: =BV18+BU18+BQ18+BN18 -> 17.166667
A19: 13 | B19: =OVERALL!B16 -> 2301263 | C19: =OVERALL!C16 -> Sanchi Sharma | BB19: 32 | BD19: =BB19+BC19 -> 32 | BE19: 33 | BF19: =(BD19/BE19)*100 -> 96.969697 | BH19: 13 | BI19: =OVERALL!B16 -> 2301263 | BJ19: =OVERALL!C16 -> Sanchi Sharma | BK19: =BD19 -> 32 | BL19: =BE19 -> 33 | BM19: =(BK19/BL19)*100 -> 96.969697 | BN19: =IF(BM19>=95.5,"6",IF(BM19>=90.5,"5", IF(BM19>=85.5,"4",IF(BM19>=80.5,"3",IF(BM19>=75.5,"2","0"))))) -> 6 | BO19: 10 | BP19: 16 | BQ19: =ROUND((BO19+BP19)/2, 2) -> 13 | BR19: 8 | BS19: 8 | BT19: 9 | BU19: =(BT19+BS19+BR19)/3 -> 8.3333333 | BV19: 5 | BW19: =BV19+BU19+BQ19+BN19 -> 32.333333
A20: 14 | B20: =OVERALL!B17 -> 2301264 | C20: =OVERALL!C17 -> Sarbjit Singh | BB20: 20 | BD20: =BB20+BC20 -> 20 | BE20: 33 | BF20: =(BD20/BE20)*100 -> 60.606061 | BH20: 14 | BI20: =OVERALL!B17 -> 2301264 | BJ20: =OVERALL!C17 -> Sarbjit Singh | BK20: =BD20 -> 20 | BL20: =BE20 -> 33 | BM20: =(BK20/BL20)*100 -> 60.606061 | BN20: =IF(BM20>=95.5,"6",IF(BM20>=90.5,"5", IF(BM20>=85.5,"4",IF(BM20>=80.5,"3",IF(BM20>=75.5,"2","0"))))) -> 0 | BO20: 0 | BP20: 8 | BQ20: =ROUND((BO20+BP20)/2, 2) -> 4 | BR20: 8 | BS20: 8 | BT20: 9 | BU20: =(BT20+BS20+BR20)/3 -> 8.3333333 | BV20: 5 | BW20: =BV20+BU20+BQ20+BN20 -> 17.333333
A21: 15 | B21: =OVERALL!B18 -> 2301265 | C21: =OVERALL!C18 -> Sarif Mayangmayum | BB21: 26 | BD21: =BB21+BC21 -> 26 | BE21: 33 | BF21: =(BD21/BE21)*100 -> 78.787879 | BH21: 15 | BI21: =OVERALL!B18 -> 2301265 | BJ21: =OVERALL!C18 -> Sarif Mayangmayum | BK21: =BD21 -> 26 | BL21: =BE21 -> 33 | BM21: =(BK21/BL21)*100 -> 78.787879 | BN21: =IF(BM21>=95.5,"6",IF(BM21>=90.5,"5", IF(BM21>=85.5,"4",IF(BM21>=80.5,"3",IF(BM21>=75.5,"2","0"))))) -> 2 | BO21: 16 | BP21: 15 | BQ21: =ROUND((BO21+BP21)/2, 2) -> 15.5 | BR21: 8 | BS21: 8 | BT21: 9 | BU21: =(BT21+BS21+BR21)/3 -> 8.3333333 | BW21: =BV21+BU21+BQ21+BN21 -> 25.833333
A22: 16 | B22: =OVERALL!B19 -> 2301267 | C22: =OVERALL!C19 -> Shivam Kumar Chaubey | BB22: 28 | BD22: =BB22+BC22 -> 28 | BE22: 33 | BF22: =(BD22/BE22)*100 -> 84.848485 | BH22: 16 | BI22: =OVERALL!B19 -> 2301267 | BJ22: =OVERALL!C19 -> Shivam Kumar Chaubey | BK22: =BD22 -> 28 | BL22: =BE22 -> 33 | BM22: =(BK22/BL22)*100 -> 84.848485 | BN22: =IF(BM22>=95.5,"6",IF(BM22>=90.5,"5", IF(BM22>=85.5,"4",IF(BM22>=80.5,"3",IF(BM22>=75.5,"2","0"))))) -> 3 | BO22: 7 | BP22: 15 | BQ22: =ROUND((BO22+BP22)/2, 2) -> 11 | BR22: 9 | BS22: 8 | BT22: 9 | BU22: =(BT22+BS22+BR22)/3 -> 8.6666667 | BV22: 5 | BW22: =BV22+BU22+BQ22+BN22 -> 27.666667
A23: 17 | B23: =OVERALL!B20 -> 2301268 | C23: =OVERALL!C20 -> Simba Godfrey | BB23: 26 | BD23: =BB23+BC23 -> 26 | BE23: 33 | BF23: =(BD23/BE23)*100 -> 78.787879 | BH23: 17 | BI23: =OVERALL!B20 -> 2301268 | BJ23: =OVERALL!C20 -> Simba Godfrey | BK23: =BD23 -> 26 | BL23: =BE23 -> 33 | BM23: =(BK23/BL23)*100 -> 78.787879 | BN23: =IF(BM23>=95.5,"6",IF(BM23>=90.5,"5", IF(BM23>=85.5,"4",IF(BM23>=80.5,"3",IF(BM23>=75.5,"2","0"))))) -> 2 | BO23: 9 | BP23: 10 | BQ23: =ROUND((BO23+BP23)/2, 2) -> 9.5 | BR23: 8 | BS23: 9 | BT23: 9 | BU23: =(BT23+BS23+BR23)/3 -> 8.6666667 | BV23: 5 | BW23: =BV23+BU23+BQ23+BN23 -> 25.166667
A24: 18 | B24: =OVERALL!B21 -> 2301269 | C24: =OVERALL!C21 -> Simran Kaur | BB24: 27 | BD24: =BB24+BC24 -> 27 | BE24: 33 | BF24: =(BD24/BE24)*100 -> 81.818182 | BH24: 18 | BI24: =OVERALL!B21 -> 2301269 | BJ24: =OVERALL!C21 -> Simran Kaur | BK24: =BD24 -> 27 | BL24: =BE24 -> 33 | BM24: =(BK24/BL24)*100 -> 81.818182 | BN24: =IF(BM24>=95.5,"6",IF(BM24>=90.5,"5", IF(BM24>=85.5,"4",IF(BM24>=80.5,"3",IF(BM24>=75.5,"2","0"))))) -> 3 | BO24: 14 | BP24: 21 | BQ24: =ROUND((BO24+BP24)/2, 2) -> 17.5 | BR24: 9 | BS24: 9 | BT24: 9 | BU24: =(BT24+BS24+BR24)/3 -> 9 | BW24: =BV24+BU24+BQ24+BN24 -> 29.5
A25: 19 | B25: =OVERALL!B22 -> 2301270 | C25: =OVERALL!C22 -> Simranjit Singh | BB25: 25 | BC25: 2 | BD25: =BB25+BC25 -> 27 | BE25: 33 | BF25: =(BD25/BE25)*100 -> 81.818182 | BH25: 19 | BI25: =OVERALL!B22 -> 2301270 | BJ25: =OVERALL!C22 -> Simranjit Singh | BK25: =BD25 -> 27 | BL25: =BE25 -> 33 | BM25: =(BK25/BL25)*100 -> 81.818182 | BN25: =IF(BM25>=95.5,"6",IF(BM25>=90.5,"5", IF(BM25>=85.5,"4",IF(BM25>=80.5,"3",IF(BM25>=75.5,"2","0"))))) -> 3 | BO25: 6 | BP25: 19 | BQ25: =ROUND((BO25+BP25)/2, 2) -> 12.5 | BR25: 9 | BS25: 9 | BT25: 9 | BU25: =(BT25+BS25+BR25)/3 -> 9 | BV25: 5 | BW25: =BV25+BU25+BQ25+BN25 -> 29.5
A26: 20 | B26: =OVERALL!B23 -> 2301271 | C26: =OVERALL!C23 -> Sudip Sunar | BB26: 26 | BD26: =BB26+BC26 -> 26 | BE26: 33 | BF26: =(BD26/BE26)*100 -> 78.787879 | BH26: 20 | BI26: =OVERALL!B23 -> 2301271 | BJ26: =OVERALL!C23 -> Sudip Sunar | BK26: =BD26 -> 26 | BL26: =BE26 -> 33 | BM26: =(BK26/BL26)*100 -> 78.787879 | BN26: =IF(BM26>=95.5,"6",IF(BM26>=90.5,"5", IF(BM26>=85.5,"4",IF(BM26>=80.5,"3",IF(BM26>=75.5,"2","0"))))) -> 2 | BO26: 8 | BP26: 14 | BQ26: =ROUND((BO26+BP26)/2, 2) -> 11 | BR26: 8 | BS26: 8 | BT26: 7 | BU26: =(BT26+BS26+BR26)/3 -> 7.6666667 | BW26: =BV26+BU26+BQ26+BN26 -> 20.666667
A27: 21 | B27: =OVERALL!B24 -> 2301272 | C27: =OVERALL!C24 -> Sujal Sharma | BB27: 7 | BD27: =BB27+BC27 -> 7 | BE27: 33 | BF27: =(BD27/BE27)*100 -> 21.212121 | BH27: 21 | BI27: =OVERALL!B24 -> 2301272 | BJ27: =OVERALL!C24 -> Sujal Sharma | BK27: =BD27 -> 7 | BL27: =BE27 -> 33 | BM27: =(BK27/BL27)*100 -> 21.212121 | BN27: =IF(BM27>=95.5,"6",IF(BM27>=90.5,"5", IF(BM27>=85.5,"4",IF(BM27>=80.5,"3",IF(BM27>=75.5,"2","0"))))) -> 0 | BO27: 0 | BP27: 0 | BQ27: =ROUND((BO27+BP27)/2, 2) -> 0 | BR27: 0 | BS27: 0 | BT27: 0 | BU27: =(BT27+BS27+BR27)/3 -> 0 | BW27: =BV27+BU27+BQ27+BN27 -> 0
A28: 22 | B28: =OVERALL!B25 -> 2301273 | C28: =OVERALL!C25 -> Sukhraj Singh | BB28: 21 | BC28: 1 | BD28: =BB28+BC28 -> 22 | BE28: 33 | BF28: =(BD28/BE28)*100 -> 66.666667 | BH28: 22 | BI28: =OVERALL!B25 -> 2301273 | BJ28: =OVERALL!C25 -> Sukhraj Singh | BK28: =BD28 -> 22 | BL28: =BE28 -> 33 | BM28: =(BK28/BL28)*100 -> 66.666667 | BN28: =IF(BM28>=95.5,"6",IF(BM28>=90.5,"5", IF(BM28>=85.5,"4",IF(BM28>=80.5,"3",IF(BM28>=75.5,"2","0"))))) -> 0 | BO28: 0 | BP28: 0 | BQ28: =ROUND((BO28+BP28)/2, 2) -> 0 | BR28: 8 | BS28: 9 | BT28: 9 | BU28: =(BT28+BS28+BR28)/3 -> 8.6666667 | BV28: 5 | BW28: =BV28+BU28+BQ28+BN28 -> 13.666667
A29: 23 | B29: =OVERALL!B26 -> 2301274 | C29: =OVERALL!C26 -> Sukhreet Kaur | BB29: 24 | BC29: 1 | BD29: =BB29+BC29 -> 25 | BE29: 33 | BF29: =(BD29/BE29)*100 -> 75.757576 | BH29: 23 | BI29: =OVERALL!B26 -> 2301274 | BJ29: =OVERALL!C26 -> Sukhreet Kaur | BK29: =BD29 -> 25 | BL29: =BE29 -> 33 | BM29: =(BK29/BL29)*100 -> 75.757576 | BN29: =IF(BM29>=95.5,"6",IF(BM29>=90.5,"5", IF(BM29>=85.5,"4",IF(BM29>=80.5,"3",IF(BM29>=75.5,"2","0"))))) -> 2 | BO29: 12 | BP29: 19 | BQ29: =ROUND((BO29+BP29)/2, 2) -> 15.5 | BR29: 7 | BS29: 8 | BT29: 9 | BU29: =(BT29+BS29+BR29)/3 -> 8 | BW29: =BV29+BU29+BQ29+BN29 -> 25.5
A30: 24 | B30: =OVERALL!B27 -> 2301275 | C30: =OVERALL!C27 -> Suman Krishna | BB30: 21 | BC30: 2 | BD30: =BB30+BC30 -> 23 | BE30: 33 | BF30: =(BD30/BE30)*100 -> 69.69697 | BH30: 24 | BI30: =OVERALL!B27 -> 2301275 | BJ30: =OVERALL!C27 -> Suman Krishna | BK30: =BD30 -> 23 | BL30: =BE30 -> 33 | BM30: =(BK30/BL30)*100 -> 69.69697 | BN30: =IF(BM30>=95.5,"6",IF(BM30>=90.5,"5", IF(BM30>=85.5,"4",IF(BM30>=80.5,"3",IF(BM30>=75.5,"2","0"))))) -> 0 | BO30: 8 | BP30: 18 | BQ30: =ROUND((BO30+BP30)/2, 2) -> 13 | BR30: 9 | BS30: 9 | BT30: 9 | BU30: =(BT30+BS30+BR30)/3 -> 9 | BV30: 5 | BW30: =BV30+BU30+BQ30+BN30 -> 27
A31: 25 | B31: =OVERALL!B28 -> 2301277 | C31: =OVERALL!C28 -> Tamana | BB31: 24 | BD31: =BB31+BC31 -> 24 | BE31: 33 | BF31: =(BD31/BE31)*100 -> 72.727273 | BH31: 25 | BI31: =OVERALL!B28 -> 2301277 | BJ31: =OVERALL!C28 -> Tamana | BK31: =BD31 -> 24 | BL31: =BE31 -> 33 | BM31: =(BK31/BL31)*100 -> 72.727273 | BN31: =IF(BM31>=95.5,"6",IF(BM31>=90.5,"5", IF(BM31>=85.5,"4",IF(BM31>=80.5,"3",IF(BM31>=75.5,"2","0"))))) -> 0 | BO31: 10 | BP31: 16 | BQ31: =ROUND((BO31+BP31)/2, 2) -> 13 | BR31: 8 | BS31: 9 | BT31: 8 | BU31: =(BT31+BS31+BR31)/3 -> 8.3333333 | BV31: 5 | BW31: =BV31+BU31+BQ31+BN31 -> 26.333333
A32: 26 | B32: =OVERALL!B29 -> 2301278 | C32: =OVERALL!C29 -> Tamana Farooq Khanday | BB32: 9 | BD32: =BB32+BC32 -> 9 | BE32: 33 | BF32: =(BD32/BE32)*100 -> 27.272727 | BH32: 26 | BI32: =OVERALL!B29 -> 2301278 | BJ32: =OVERALL!C29 -> Tamana Farooq Khanday | BK32: =BD32 -> 9 | BL32: =BE32 -> 33 | BM32: =(BK32/BL32)*100 -> 27.272727 | BN32: =IF(BM32>=95.5,"6",IF(BM32>=90.5,"5", IF(BM32>=85.5,"4",IF(BM32>=80.5,"3",IF(BM32>=75.5,"2","0"))))) -> 0 | BO32: 0 | BP32: 14 | BQ32: =ROUND((BO32+BP32)/2, 2) -> 7 | BR32: 8 | BS32: 9 | BT32: 9 | BU32: =(BT32+BS32+BR32)/3 -> 8.6666667 | BW32: =BV32+BU32+BQ32+BN32 -> 15.666667
A33: 27 | B33: =OVERALL!B30 -> 2301279 | C33: =OVERALL!C30 -> Tania | BB33: 29 | BD33: =BB33+BC33 -> 29 | BE33: 33 | BF33: =(BD33/BE33)*100 -> 87.878788 | BH33: 27 | BI33: =OVERALL!B30 -> 2301279 | BJ33: =OVERALL!C30 -> Tania | BK33: =BD33 -> 29 | BL33: =BE33 -> 33 | BM33: =(BK33/BL33)*100 -> 87.878788 | BN33: =IF(BM33>=95.5,"6",IF(BM33>=90.5,"5", IF(BM33>=85.5,"4",IF(BM33>=80.5,"3",IF(BM33>=75.5,"2","0"))))) -> 4 | BO33: 10 | BP33: 17 | BQ33: =ROUND((BO33+BP33)/2, 2) -> 13.5 | BR33: 7 | BS33: 8 | BT33: 9 | BU33: =(BT33+BS33+BR33)/3 -> 8 | BW33: =BV33+BU33+BQ33+BN33 -> 25.5
A34: 28 | B34: =OVERALL!B31 -> 2301280 | C34: =OVERALL!C31 -> Taniya | BB34: 23 | BD34: =BB34+BC34 -> 23 | BE34: 33 | BF34: =(BD34/BE34)*100 -> 69.69697 | BH34: 28 | BI34: =OVERALL!B31 -> 2301280 | BJ34: =OVERALL!C31 -> Taniya | BK34: =BD34 -> 23 | BL34: =BE34 -> 33 | BM34: =(BK34/BL34)*100 -> 69.69697 | BN34: =IF(BM34>=95.5,"6",IF(BM34>=90.5,"5", IF(BM34>=85.5,"4",IF(BM34>=80.5,"3",IF(BM34>=75.5,"2","0"))))) -> 0 | BO34: 6 | BP34: 15 | BQ34: =ROUND((BO34+BP34)/2, 2) -> 10.5 | BR34: 8 | BS34: 9 | BT34: 9 | BU34: =(BT34+BS34+BR34)/3 -> 8.6666667 | BW34: =BV34+BU34+BQ34+BN34 -> 19.166667
A35: 29 | B35: =OVERALL!B32 -> 2301281 | C35: =OVERALL!C32 -> Taziko Trakha | BB35: 24 | BD35: =BB35+BC35 -> 24 | BE35: 33 | BF35: =(BD35/BE35)*100 -> 72.727273 | BH35: 29 | BI35: =OVERALL!B32 -> 2301281 | BJ35: =OVERALL!C32 -> Taziko Trakha | BK35: =BD35 -> 24 | BL35: =BE35 -> 33 | BM35: =(BK35/BL35)*100 -> 72.727273 | BN35: =IF(BM35>=95.5,"6",IF(BM35>=90.5,"5", IF(BM35>=85.5,"4",IF(BM35>=80.5,"3",IF(BM35>=75.5,"2","0"))))) -> 0 | BO35: 10 | BP35: 12 | BQ35: =ROUND((BO35+BP35)/2, 2) -> 11 | BR35: 7 | BS35: 7 | BT35: 9 | BU35: =(BT35+BS35+BR35)/3 -> 7.6666667 | BW35: =BV35+BU35+BQ35+BN35 -> 18.666667
A36: 30 | B36: =OVERALL!B33 -> 2301283 | C36: =OVERALL!C33 -> Vaibhav Shahi | BB36: 22 | BC36: 2 | BD36: =BB36+BC36 -> 24 | BE36: 33 | BF36: =(BD36/BE36)*100 -> 72.727273 | BH36: 30 | BI36: =OVERALL!B33 -> 2301283 | BJ36: =OVERALL!C33 -> Vaibhav Shahi | BK36: =BD36 -> 24 | BL36: =BE36 -> 33 | BM36: =(BK36/BL36)*100 -> 72.727273 | BN36: =IF(BM36>=95.5,"6",IF(BM36>=90.5,"5", IF(BM36>=85.5,"4",IF(BM36>=80.5,"3",IF(BM36>=75.5,"2","0"))))) -> 0 | BO36: 0 | BP36: 0 | BQ36: =ROUND((BO36+BP36)/2, 2) -> 0 | BR36: 8 | BS36: 8 | BT36: 9 | BU36: =(BT36+BS36+BR36)/3 -> 8.3333333 | BW36: =BV36+BU36+BQ36+BN36 -> 8.3333333
A37: 31 | B37: =OVERALL!B34 -> 2301285 | C37: =OVERALL!C34 -> Vansh Sharma | BB37: 9 | BD37: =BB37+BC37 -> 9 | BE37: 33 | BF37: =(BD37/BE37)*100 -> 27.272727 | BH37: 31 | BI37: =OVERALL!B34 -> 2301285 | BJ37: =OVERALL!C34 -> Vansh Sharma | BK37: =BD37 -> 9 | BL37: =BE37 -> 33 | BM37: =(BK37/BL37)*100 -> 27.272727 | BN37: =IF(BM37>=95.5,"6",IF(BM37>=90.5,"5", IF(BM37>=85.5,"4",IF(BM37>=80.5,"3",IF(BM37>=75.5,"2","0"))))) -> 0 | BO37: 0 | BP37: 0 | BQ37: =ROUND((BO37+BP37)/2, 2) -> 0 | BR37: 8 | BS37: 0 | BT37: 0 | BU37: =(BT37+BS37+BR37)/3 -> 2.6666667 | BW37: =BV37+BU37+BQ37+BN37 -> 2.6666667
A38: 32 | B38: =OVERALL!B35 -> 2301286 | C38: =OVERALL!C35 -> Vikramjit Singh | BB38: =COUNTIF(D38:BA38,"P") -> 0 | BD38: =BB38+BC38 -> 0 | BE38: 33 | BF38: =(BD38/BE38)*100 -> 0 | BH38: 32 | BI38: =OVERALL!B35 -> 2301286 | BJ38: =OVERALL!C35 -> Vikramjit Singh | BK38: =BD38 -> 0 | BL38: =BE38 -> 33 | BM38: =(BK38/BL38)*100 -> 0 | BN38: =IF(BM38>=95.5,"6",IF(BM38>=90.5,"5", IF(BM38>=85.5,"4",IF(BM38>=80.5,"3",IF(BM38>=75.5,"2","0"))))) -> 0 | BO38: 0 | BP38: 0 | BQ38: =ROUND((BO38+BP38)/2, 2) -> 0 | BR38: 0 | BS38: 0 | BT38: 0 | BU38: =(BT38+BS38+BR38)/3 -> 0 | BW38: =BV38+BU38+BQ38+BN38 -> 0
A39: 33 | B39: =OVERALL!B36 -> 2339508 | C39: =OVERALL!C36 -> TANISHA | BB39: 25 | BD39: =BB39+BC39 -> 25 | BE39: 33 | BF39: =(BD39/BE39)*100 -> 75.757576 | BH39: 33 | BI39: =OVERALL!B36 -> 2339508 | BJ39: =OVERALL!C36 -> TANISHA | BK39: =BD39 -> 25 | BL39: =BE39 -> 33 | BM39: =(BK39/BL39)*100 -> 75.757576 | BN39: =IF(BM39>=95.5,"6",IF(BM39>=90.5,"5", IF(BM39>=85.5,"4",IF(BM39>=80.5,"3",IF(BM39>=75.5,"2","0"))))) -> 2 | BO39: 8 | BP39: 17 | BQ39: =ROUND((BO39+BP39)/2, 2) -> 12.5 | BR39: 8 | BS39: 8 | BT39: 9 | BU39: =(BT39+BS39+BR39)/3 -> 8.3333333 | BV39: 5 | BW39: =BV39+BU39+BQ39+BN39 -> 27.833333
A40: 34 | B40: =OVERALL!B37 -> 2339509 | C40: =OVERALL!C37 -> TOHIED AHMED | BB40: 3 | BD40: =BB40+BC40 -> 3 | BE40: 33 | BF40: =(BD40/BE40)*100 -> 9.0909091 | BH40: 34 | BI40: =OVERALL!B37 -> 2339509 | BJ40: =OVERALL!C37 -> TOHIED AHMED | BK40: =BD40 -> 3 | BL40: =BE40 -> 33 | BM40: =(BK40/BL40)*100 -> 9.0909091 | BN40: =IF(BM40>=95.5,"6",IF(BM40>=90.5,"5", IF(BM40>=85.5,"4",IF(BM40>=80.5,"3",IF(BM40>=75.5,"2","0"))))) -> 0 | BO40: 0 | BP40: 0 | BQ40: =ROUND((BO40+BP40)/2, 2) -> 0 | BR40: 0 | BS40: 0 | BT40: 0 | BU40: =(BT40+BS40+BR40)/3 -> 0 | BW40: =BV40+BU40+BQ40+BN40 -> 0
...

Sheet DM
D1: ATTENDANCE RECORD JAN-JUNE2025 (B.Tech CSE 4B) | BH1: CTIEMT : Evaluation Sheet for Internal Awards (Theory)
BH2: Session: JAN TO JUNE 2025
BH3: Department: CSE | BP3: Semester: B.TECH 4B
D4: Ms. Ritika Agnihotri | BH4: Subject Name: Discrete Mathematics | BP4: Subject Code: BTCS 401-18
A5: DATE | BB5: PRESENT | BC5: DL (IF ANY) | BD5: Total Attended | BE5: Total Delievered | BF5: PERCENTAGE | BH5: S.No. | BI5: Reg No. | BJ5: Name of Student | BK5: Total Lec Att | BL5: Total Lec Del | BM5: Att %age | BN5: Att Marks (6) | BO5: MST I (24) | BP5: MST II (24) | BQ5: Average MST I & II (24) | BR5: Assignments | BU5: Assignments AVG (10) | BV5: Grace | BW5: Grand Total (40)
A6: S.No. | B6: Reg No. | C6: Name of Student | D6: 1 | E6: 2 | F6: 3 | G6: 4 | H6: 5 | I6: 6 | J6: 7 | K6: 8 | L6: 9 | M6: 10 | N6: 11 | O6: 12 | P6: 13 | Q6: 14 | R6: 15 | S6: 16 | T6: 17 | U6: 18 | V6: 19 | W6: 20 | X6: 21 | Y6: 22 | Z6: 23 | AA6: 24 | AB6: 25 | AC6: 26 | AD6: 27 | AE6: 28 | AF6: 29 | AG6: 30 | AH6: 31 | AI6: 32 | AJ6: 33 | AK6: 34 | AL6: 35 | AM6: 36 | AN6: 37 | AO6: 38 | AP6: 39 | AQ6: 40 | AR6: 41 | AS6: 42 | AT6: 43 | AU6: 44 | AV6: 45 | AW6: 46 | AX6: 47 | AY6: 48 | AZ6: 49 | BA6: 50 | BR6: 1 | BS6: 2 | BT6: 3
A7: 1 | B7: =OVERALL!B4 -> 2301249 | C7: =OVERALL!C4 -> Rahul Sharma | BB7: 19 | BD7: =BB7+BC7 -> 19 | BE7: 45 | BF7: =(BD7/BE7)*100 -> 42.222222 | BH7: 1 | BI7: =OVERALL!B4 -> 2301249 | BJ7: =OVERALL!C4 -> Rahul Sharma | BK7: =BD7 -> 19 | BL7: =BE7 -> 45 | BM7: =(BK7/BL7)*100 -> 42.222222 | BN7: =IF(BM7>=95.5,"6",IF(BM7>=90.5,"5", IF(BM7>=85.5,"4",IF(BM7>=80.5,"3",IF(BM7>=75.5,"2","0"))))) -> 0 | BO7: 5 | BP7: 13 | BQ7: =(BO7+BP7)/2 -> 9 | BR7: 8 | BS7: 0 | BT7: 0 | BU7: =(BR7+BS7+BT7)/3 -> 2.6666667 | BV7: 5 | BW7: =BV7+BU7+BQ7+BN7 -> 16.666667
A8: 2 | B8: =OVERALL!B5 -> 2301251 | C8: =OVERALL!C5 -> Raj Kumar | BB8: 29 | BD8: =BB8+BC8 -> 29 | BE8: 45 | BF8: =(BD8/BE8)*100 -> 64.444444 | BH8: 2 | BI8: =OVERALL!B5 -> 2301251 | BJ8: =OVERALL!C5 -> Raj Kumar | BK8: =BD8 -> 29 | BL8: =BE8 -> 45 | BM8: =(BK8/BL8)*100 -> 64.444444 | BN8: =IF(BM8>=95.5,"6",IF(BM8>=90.5,"5", IF(BM8>=85.5,"4",IF(BM8>=80.5,"3",IF(BM8>=75.5,"2","0"))))) -> 0 | BO8: 12 | BP8: 10 | BQ8: =(BO8+BP8)/2 -> 11 | BR8: 0 | BS8: 7 | BT8: 8 | BU8: =(BR8+BS8+BT8)/3 -> 5 | BW8: =BV8+BU8+BQ8+BN8 -> 16
A9: 3 | B9: =OVERALL!B6 -> 2301252 | C9: =OVERALL!C6 -> Rajan Sharma | BB9: 34 | BD9: =BB9+BC9 -> 34 | BE9: 45 | BF9: =(BD9/BE9)*100 -> 75.555556 | BH9: 3 | BI9: =OVERALL!B6 -> 2301252 | BJ9: =OVERALL!C6 -> Rajan Sharma | BK9: =BD9 -> 34 | BL9: =BE9 -> 45 | BM9: =(BK9/BL9)*100 -> 75.555556 | BN9: =IF(BM9>=95.5,"6",IF(BM9>=90.5,"5", IF(BM9>=85.5,"4",IF(BM9>=80.5,"3",IF(BM9>=75.5,"2","0"))))) -> 2 | BO9: 14 | BP9: 12 | BQ9: =(BO9+BP9)/2 -> 13 | BR9: 8 | BS9: 6 | BT9: 8 | BU9: =(BR9+BS9+BT9)/3 -> 7.3333333 | BW9: =BV9+BU9+BQ9+BN9 -> 22.333333
A10: 4 | B10: =OVERALL!B7 -> 2301253 | C10: =OVERALL!C7 -> Rajwinder Kaur | BB10: 30 | BD10: =BB10+BC10 -> 30 | BE10: 45 | BF10: =(BD10/BE10)*100 -> 66.666667 | BH10: 4 | BI10: =OVERALL!B7 -> 2301253 | BJ10: =OVERALL!C7 -> Rajwinder Kaur | BK10: =BD10 -> 30 | BL10: =BE10 -> 45 | BM10: =(BK10/BL10)*100 -> 66.666667 | BN10: =IF(BM10>=95.5,"6",IF(BM10>=90.5,"5", IF(BM10>=85.5,"4",IF(BM10>=80.5,"3",IF(BM10>=75.5,"2","0"))))) -> 0 | BO10: 22 | BP10: 15 | BQ10: =(BO10+BP10)/2 -> 18.5 | BR10: 8 | BS10: 9 | BT10: 9 | BU10: =(BR10+BS10+BT10)/3 -> 8.6666667 | BW10: =BV10+BU10+BQ10+BN10 -> 27.166667
